<?xml version="1.0"?>
<robot xmlns:xacro="http://www.ros.org/wiki/xacro">

  <!-- ================================================================== -->
  <!-- Right Arm                                                         -->
  <!-- ================================================================== -->
  <joint name="right_shoulder_pitch_joint_X6" type="revolute">
    <origin xyz="4.00839e-06 -0.181502 0.427" rpy="0 0 0"/>
    <parent link="urdf_simplified_torso_sub_assembly"/>
    <child link="urdf_r_shoulder_assembly"/>
    <axis xyz="0 1 0"/>
    <limit effort="10" velocity="10" lower="-3.14159" upper="1.5708"/>
    <dynamics damping="0.5" friction="0.1"/>
  </joint>

  <joint name="right_shoulder_roll_joint_X6" type="revolute">
    <origin xyz="0.041 -0.07 -1.08797e-07" rpy="0 0 0"/>
    <parent link="urdf_r_shoulder_assembly"/>
    <child link="urdf_r_upper_arm_assembly"/>
    <axis xyz="1 0 0"/>
    <limit effort="10" velocity="10" lower="-3.14159" upper="-0"/>
    <dynamics damping="0.5" friction="0.1"/>
  </joint>

  <joint name="right_shoulder_yaw_joint_X4" type="revolute">
    <origin xyz="-0.041 6.24445e-07 -0.17" rpy="0 0 0"/>
    <parent link="urdf_r_upper_arm_assembly"/>
    <child link="urdf_r_elbow_assembly"/>
    <axis xyz="0 0 1"/>
    <limit effort="10" velocity="10" lower="-2.35619" upper="2.35619"/>
    <dynamics damping="0.5" friction="0.1"/>
  </joint>

  <joint name="right_elbow_pitch_joint_X6" type="revolute">
    <origin xyz="0 -0.04 -0.065" rpy="0 0 0"/>
    <parent link="urdf_r_elbow_assembly"/>
    <child link="urdf_r_upper_forearm_assembly"/>
    <axis xyz="0 1 0"/>
    <limit effort="10" velocity="10" lower="-1.5708" upper="1.5708"/>
    <dynamics damping="0.5" friction="0.1"/>
  </joint>

  <joint name="right_wrist_yaw_joint_X4" type="revolute">
    <origin xyz="-6.17098e-07 0.04 -0.168" rpy="0 0 0"/>
    <parent link="urdf_r_upper_forearm_assembly"/>
    <child link="urdf_r_lower_forearm_assembly"/>
    <axis xyz="0 0 1"/>
    <limit effort="10" velocity="10" lower="-2.35619" upper="2.35619"/>
    <dynamics damping="0.5" friction="0.1"/>
  </joint>

  <joint name="right_wrist_roll_joint_X4" type="revolute">
    <origin xyz="0.033 0 -0.0565" rpy="0 0 0"/>
    <parent link="urdf_r_lower_forearm_assembly"/>
    <child link="urdf_r_wrist_assembly"/>
    <axis xyz="1 0 0"/>
    <limit effort="10" velocity="10" lower="-1.5708" upper="1.5708"/>
    <dynamics damping="0.5" friction="0.1"/>
  </joint>

</robot>
