<?xml version="1.0"?>
<robot xmlns:xacro="http://www.ros.org/wiki/xacro">

  <!-- ================================================================== -->
  <!-- Left Arm                                                          -->
  <!-- ================================================================== -->
  <joint name="left_shoulder_pitch_joint_X6" type="revolute">
    <origin xyz="0 0.1755 0.423977" rpy="0 0 0"/>
    <parent link="urdf_simplified_torso"/>
    <child link="urdf_l_shoulder_assembly"/>
    <axis xyz="0 1 0"/>
    <limit effort="100" velocity="100" lower="-3.02" upper="1.69"/>
    <dynamics damping="0.5" friction="0.1"/>
  </joint>

  <joint name="left_shoulder_roll_joint_X6" type="revolute">
    <origin xyz="0.0456571 0.07 0.00560599" rpy="0 -0.122173 0"/>
    <parent link="urdf_l_shoulder_assembly"/>
    <child link="urdf_l_upper_arm_assembly"/>
    <axis xyz="1 0 0"/>
    <limit effort="100" velocity="100" lower="-0.21" upper="2.93"/>
    <dynamics damping="0.5" friction="0.1"/>
  </joint>

  <joint name="left_shoulder_yaw_joint_X4" type="revolute">
    <origin xyz="-0.046 0.0343048 -0.161394" rpy="0.209376 0.00530409 -0.0249664"/>
    <parent link="urdf_l_upper_arm_assembly"/>
    <child link="urdf_l_elbow_assembly"/>
    <axis xyz="0 0 1"/>
    <limit effort="100" velocity="100" lower="-1.75" upper="2.97"/>
    <dynamics damping="0.5" friction="0.1"/>
  </joint>

  <joint name="left_elbow_pitch_joint_X6" type="revolute">
    <origin xyz="0.019337 0.0291733 -0.075" rpy="0 -0.0190902 -0.585348"/>
    <parent link="urdf_l_elbow_assembly"/>
    <child link="urdf_l_upper_forearm_assembly"/>
    <axis xyz="0 1 0"/>
    <limit effort="100" velocity="100" lower="-1.31" upper="1.83"/>
    <dynamics damping="0.5" friction="0.1"/>
  </joint>

  <joint name="left_wrist_yaw_joint_X4" type="revolute">
    <origin xyz="0.0391738 -0.035 -0.158223" rpy="-0.142861 -0.19688 0.634041"/>
    <parent link="urdf_l_upper_forearm_assembly"/>
    <child link="urdf_l_lower_forearm_assembly"/>
    <axis xyz="0 0 1"/>
    <limit effort="100" velocity="100" lower="-2.36" upper="2.36"/>
    <dynamics damping="0.5" friction="0.1"/>
  </joint>

  <joint name="left_wrist_roll_joint_X4" type="revolute">
    <origin xyz="0.0219762 -0.0156859 -0.0615" rpy="-0.248271 0 -0.619909"/>
    <parent link="urdf_l_lower_forearm_assembly"/>
    <child link="urdf_l_wrist_assembly"/>
    <axis xyz="1 0 0"/>
    <limit effort="100" velocity="100" lower="-1.57" upper="1.57"/>
    <dynamics damping="0.5" friction="0.1"/>
  </joint>

</robot>
