<?xml version="1.0"?>
<robot xmlns:xacro="http://www.ros.org/wiki/xacro">

  <!-- ================================================================== -->
  <!-- Right Arm                                                         -->
  <!-- ================================================================== -->
  <joint name="right_shoulder_pitch_joint_X6" type="revolute">
    <origin xyz="0 -0.1755 0.423977" rpy="0 0 0"/>
    <parent link="urdf_simplified_torso"/>
    <child link="urdf_r_shoulder_assembly"/>
    <axis xyz="0 1 0"/>
    <limit effort="100" velocity="100" lower="-3.02" upper="1.69"/>
    <dynamics damping="0.5" friction="0.1"/>
  </joint>

  <joint name="right_shoulder_roll_joint_X6" type="revolute">
    <origin xyz="0.0456571 -0.07 0.00560599" rpy="0 -0.122173 0"/>
    <parent link="urdf_r_shoulder_assembly"/>
    <child link="urdf_r_upper_arm_assembly"/>
    <axis xyz="1 0 0"/>
    <limit effort="100" velocity="100" lower="-2.93" upper="0.21"/>
    <dynamics damping="0.5" friction="0.1"/>
  </joint>

  <joint name="right_shoulder_yaw_joint_X4" type="revolute">
    <origin xyz="-0.046 -0.0353456 -0.166285" rpy="-0.209378 0.00530246 0.0249661"/>
    <parent link="urdf_r_upper_arm_assembly"/>
    <child link="urdf_r_elbow_assembly"/>
    <axis xyz="0 0 1"/>
    <limit effort="100" velocity="100" lower="-2.97" upper="1.75"/>
    <dynamics damping="0.5" friction="0.1"/>
  </joint>

  <joint name="right_elbow_pitch_joint_X6" type="revolute">
    <origin xyz="0.0220994 -0.0333409 -0.065" rpy="0 -0.019088 0.585341"/>
    <parent link="urdf_r_elbow_assembly"/>
    <child link="urdf_r_upper_forearm_assembly"/>
    <axis xyz="0 1 0"/>
    <limit effort="100" velocity="100" lower="-1.31" upper="1.83"/>
    <dynamics damping="0.5" friction="0.1"/>
  </joint>

  <joint name="right_wrist_yaw_joint_X4" type="revolute">
    <origin xyz="0.0403763 0.04 -0.163076" rpy="0.142857 -0.196885 -0.634033"/>
    <parent link="urdf_r_upper_forearm_assembly"/>
    <child link="urdf_r_lower_forearm_assembly"/>
    <axis xyz="0 0 1"/>
    <limit effort="100" velocity="100" lower="-2.36" upper="2.36"/>
    <dynamics damping="0.5" friction="0.1"/>
  </joint>

  <joint name="right_wrist_roll_joint_X4" type="revolute">
    <origin xyz="0.0219763 0.0156857 -0.0565" rpy="0.248281 0 0.619897"/>
    <parent link="urdf_r_lower_forearm_assembly"/>
    <child link="urdf_r_wrist_assembly"/>
    <axis xyz="1 0 0"/>
    <limit effort="100" velocity="100" lower="-1.57" upper="1.57"/>
    <dynamics damping="0.5" friction="0.1"/>
  </joint>

</robot>
