<?xml version="1.0" ?>
<!-- Generated using onshape-to-robot -->
<!-- Onshape document_id: a1654a8c4d07fc15a88455e3 -->
<robot name="robot_harambe_v0.3">
  <!-- Link urdf_base -->
  <link name="urdf_base">
    <inertial>
      <origin xyz="0.000699269 0.0334604 -0.431702" rpy="0 0 0"/>
      <mass value="5.132"/>
      <inertia ixx="0.0213139" ixy="-2.35276e-07" ixz="6.5838e-06" iyy="0.0288848" iyz="-2.88595e-05" izz="0.0155352"/>
    </inertial>
    <!-- Part stator_x8_p20_120_unified -->
    <visual>
      <origin xyz="-0.0103011 0.0333787 -0.467748" rpy="-1.5708 0.785398 1.5708"/>
      <geometry>
        <mesh filename="package://assets/stator_x8_p20_120_unified.stl"/>
      </geometry>
      <material name="stator_x8_p20_120_unified_material">
        <color rgba="0.882353 0.572549 0.478431 1"/>
      </material>
    </visual>
    <collision>
      <origin xyz="-0.0103011 0.0333787 -0.467748" rpy="-1.5708 0.785398 1.5708"/>
      <geometry>
        <mesh filename="package://assets/stator_x8_p20_120_unified.stl"/>
      </geometry>
    </collision>
    <!-- Part b_base -->
    <visual>
      <origin xyz="0.000697952 -0.00271429 -0.432504" rpy="0 -0 0"/>
      <geometry>
        <mesh filename="package://assets/b_base.stl"/>
      </geometry>
      <material name="b_base_material">
        <color rgba="0.368627 0.25098 0.643137 1"/>
      </material>
    </visual>
    <collision>
      <origin xyz="0.000697952 -0.00271429 -0.432504" rpy="0 -0 0"/>
      <geometry>
        <mesh filename="package://assets/b_base.stl"/>
      </geometry>
    </collision>
    <!-- Part stator_x8_p20_120_unified_2 -->
    <visual>
      <origin xyz="0.0116989 0.0333787 -0.467748" rpy="1.5708 -0.785398 1.5708"/>
      <geometry>
        <mesh filename="package://assets/stator_x8_p20_120_unified.stl"/>
      </geometry>
      <material name="stator_x8_p20_120_unified_2_material">
        <color rgba="0.882353 0.572549 0.478431 1"/>
      </material>
    </visual>
    <collision>
      <origin xyz="0.0116989 0.0333787 -0.467748" rpy="1.5708 -0.785398 1.5708"/>
      <geometry>
        <mesh filename="package://assets/stator_x8_p20_120_unified.stl"/>
      </geometry>
    </collision>
    <!-- Part stator_x8_p20_120_unified_3 -->
    <visual>
      <origin xyz="0.000698852 0.0333787 -0.396748" rpy="0 -0 0"/>
      <geometry>
        <mesh filename="package://assets/stator_x8_p20_120_unified.stl"/>
      </geometry>
      <material name="stator_x8_p20_120_unified_3_material">
        <color rgba="0.882353 0.572549 0.478431 1"/>
      </material>
    </visual>
    <collision>
      <origin xyz="0.000698852 0.0333787 -0.396748" rpy="0 -0 0"/>
      <geometry>
        <mesh filename="package://assets/stator_x8_p20_120_unified.stl"/>
      </geometry>
    </collision>
    <!-- Part f_base -->
    <visual>
      <origin xyz="0.000705351 0.070373 -0.431099" rpy="0 -0 0"/>
      <geometry>
        <mesh filename="package://assets/f_base.stl"/>
      </geometry>
      <material name="f_base_material">
        <color rgba="0.909804 0.572549 0.164706 1"/>
      </material>
    </visual>
    <collision>
      <origin xyz="0.000705351 0.070373 -0.431099" rpy="0 -0 0"/>
      <geometry>
        <mesh filename="package://assets/f_base.stl"/>
      </geometry>
    </collision>
  </link>
  <!-- Link urdf_simplified_torso -->
  <link name="urdf_simplified_torso">
    <inertial>
      <origin xyz="4.1776e-05 0.00199118 0.327574" rpy="0 0 0"/>
      <mass value="5.9"/>
      <inertia ixx="0.294153" ixy="-5.08517e-07" ixz="-9.68158e-05" iyy="0.320832" iyz="-0.00443482" izz="0.076931"/>
    </inertial>
    <!-- Part urdf_simplified_torso -->
    <visual>
      <origin xyz="0 5.1e-11 0.26095" rpy="-0 -0 -0"/>
      <geometry>
        <mesh filename="package://assets/urdf_simplified_torso.stl"/>
      </geometry>
      <material name="urdf_simplified_torso_material">
        <color rgba="0.647059 0.647059 0.647059 1"/>
      </material>
    </visual>
    <collision>
      <origin xyz="0 5.1e-11 0.26095" rpy="-0 -0 -0"/>
      <geometry>
        <mesh filename="package://assets/urdf_simplified_torso.stl"/>
      </geometry>
    </collision>
    <!-- Part head -->
    <visual>
      <origin xyz="0.000382221 4.03711e-05 0.67095" rpy="0 0 0"/>
      <geometry>
        <mesh filename="package://assets/head.stl"/>
      </geometry>
      <material name="head_material">
        <color rgba="0.737255 0.937255 0.917647 1"/>
      </material>
    </visual>
    <collision>
      <origin xyz="0.000382221 4.03711e-05 0.67095" rpy="0 0 0"/>
      <geometry>
        <mesh filename="package://assets/head.stl"/>
      </geometry>
    </collision>
    <!-- Part back_access -->
    <visual>
      <origin xyz="0.000382221 4.03711e-05 0.672878" rpy="0 0 0"/>
      <geometry>
        <mesh filename="package://assets/back_access.stl"/>
      </geometry>
      <material name="back_access_material">
        <color rgba="0.231373 0.380392 0.705882 1"/>
      </material>
    </visual>
    <collision>
      <origin xyz="0.000382221 4.03711e-05 0.672878" rpy="0 0 0"/>
      <geometry>
        <mesh filename="package://assets/back_access.stl"/>
      </geometry>
    </collision>
  </link>
  <!-- Link urdf_l_shoulder_assembly -->
  <link name="urdf_l_shoulder_assembly">
    <inertial>
      <origin xyz="-0.00409836 0.000544496 0.0631966" rpy="0 0 0"/>
      <mass value="1.246"/>
      <inertia ixx="0.00205876" ixy="-4.11941e-05" ixz="-3.48871e-05" iyy="0.00171602" iyz="7.63836e-06" izz="0.00152408"/>
    </inertial>
    <!-- Part l_shoulder -->
    <visual>
      <origin xyz="-0.00129022 0.000165436 0.0502746" rpy="1.69297 1.5708 0"/>
      <geometry>
        <mesh filename="package://assets/l_shoulder.stl"/>
      </geometry>
      <material name="l_shoulder_material">
        <color rgba="0.615686 0.811765 0.929412 1"/>
      </material>
    </visual>
    <collision>
      <origin xyz="-0.00129022 0.000165436 0.0502746" rpy="1.69297 1.5708 0"/>
      <geometry>
        <mesh filename="package://assets/l_shoulder.stl"/>
      </geometry>
    </collision>
    <!-- Part stator_x6_p20_60_unified -->
    <visual>
      <origin xyz="-0.038213 0.00469197 0.07" rpy="0.122173 1.5708 0"/>
      <geometry>
        <mesh filename="package://assets/stator_x6_p20_60_unified.stl"/>
      </geometry>
      <material name="stator_x6_p20_60_unified_material">
        <color rgba="0.960784 0.835294 0.470588 1"/>
      </material>
    </visual>
    <collision>
      <origin xyz="-0.038213 0.00469197 0.07" rpy="0.122173 1.5708 0"/>
      <geometry>
        <mesh filename="package://assets/stator_x6_p20_60_unified.stl"/>
      </geometry>
    </collision>
  </link>
  <!-- Link urdf_l_upper_arm_assembly -->
  <link name="urdf_l_upper_arm_assembly">
    <inertial>
      <origin xyz="-0.0213183 0.103332 -0.0354438" rpy="0 0 0"/>
      <mass value="0.802"/>
      <inertia ixx="0.00203106" ixy="0.000183112" ixz="-8.88411e-05" iyy="0.00107639" iyz="0.000467525" izz="0.00190836"/>
    </inertial>
    <!-- Part urdf_l_upper_arm_simplified -->
    <visual>
      <origin xyz="-0.0182149 0.0914676 -0.0268697" rpy="1.5708 -0.785398 0.20944"/>
      <geometry>
        <mesh filename="package://assets/urdf_l_upper_arm_simplified.stl"/>
      </geometry>
      <material name="urdf_l_upper_arm_simplified_material">
        <color rgba="0.917647 0.917647 0.917647 1"/>
      </material>
    </visual>
    <collision>
      <origin xyz="-0.0182149 0.0914676 -0.0268697" rpy="1.5708 -0.785398 0.20944"/>
      <geometry>
        <mesh filename="package://assets/urdf_l_upper_arm_simplified.stl"/>
      </geometry>
    </collision>
    <!-- Part stator_x4_p36_36_unified -->
    <visual>
      <origin xyz="-0.01892 0.0890114 -0.046" rpy="-1.5708 0.785398 0.20944"/>
      <geometry>
        <mesh filename="package://assets/stator_x4_p36_36_unified.stl"/>
      </geometry>
      <material name="stator_x4_p36_36_unified_material">
        <color rgba="0.764706 0.545098 0.803922 1"/>
      </material>
    </visual>
    <collision>
      <origin xyz="-0.01892 0.0890114 -0.046" rpy="-1.5708 0.785398 0.20944"/>
      <geometry>
        <mesh filename="package://assets/stator_x4_p36_36_unified.stl"/>
      </geometry>
    </collision>
  </link>
  <!-- Link urdf_l_elbow_assembly -->
  <link name="urdf_l_elbow_assembly">
    <inertial>
      <origin xyz="0.000297133 0.00777593 -0.0710681" rpy="0 0 0"/>
      <mass value="1.109"/>
      <inertia ixx="0.00140529" ixy="1.03356e-05" ixz="-1.68171e-05" iyy="0.00151899" iyz="7.83699e-05" izz="0.00113761"/>
    </inertial>
    <!-- Part stator_x6_p20_60_unified_2 -->
    <visual>
      <origin xyz="0 0.044 -0.075" rpy="1.5708 1.5708 0"/>
      <geometry>
        <mesh filename="package://assets/stator_x6_p20_60_unified.stl"/>
      </geometry>
      <material name="stator_x6_p20_60_unified_2_material">
        <color rgba="0.960784 0.835294 0.470588 1"/>
      </material>
    </visual>
    <collision>
      <origin xyz="0 0.044 -0.075" rpy="1.5708 1.5708 0"/>
      <geometry>
        <mesh filename="package://assets/stator_x6_p20_60_unified.stl"/>
      </geometry>
    </collision>
    <!-- Part urdf_l_elbow_simplified -->
    <visual>
      <origin xyz="0 0.01225 -0.075" rpy="-1.5708 1.5708 0"/>
      <geometry>
        <mesh filename="package://assets/urdf_l_elbow_simplified.stl"/>
      </geometry>
      <material name="urdf_l_elbow_simplified_material">
        <color rgba="0.231373 0.380392 0.705882 1"/>
      </material>
    </visual>
    <collision>
      <origin xyz="0 0.01225 -0.075" rpy="-1.5708 1.5708 0"/>
      <geometry>
        <mesh filename="package://assets/urdf_l_elbow_simplified.stl"/>
      </geometry>
    </collision>
  </link>
  <!-- Link urdf_l_upper_forearm_assembly -->
  <link name="urdf_l_upper_forearm_assembly">
    <inertial>
      <origin xyz="0.10341 0.00191699 0.0286559" rpy="0 0 0"/>
      <mass value="0.707"/>
      <inertia ixx="0.000720041" ixy="-2.79231e-06" ixz="-0.000365631" iyy="0.00168211" iyz="-5.21195e-06" izz="0.00146156"/>
    </inertial>
    <!-- Part urdf_l_upper_forearm_simplified -->
    <visual>
      <origin xyz="0.119 0 0.035" rpy="0 -1.5708 0"/>
      <geometry>
        <mesh filename="package://assets/urdf_l_upper_forearm_simplified.stl"/>
      </geometry>
      <material name="urdf_l_upper_forearm_simplified_material">
        <color rgba="0.498039 0.498039 0.498039 1"/>
      </material>
    </visual>
    <collision>
      <origin xyz="0.119 0 0.035" rpy="0 -1.5708 0"/>
      <geometry>
        <mesh filename="package://assets/urdf_l_upper_forearm_simplified.stl"/>
      </geometry>
    </collision>
    <!-- Part stator_x4_p36_36_unified_2 -->
    <visual>
      <origin xyz="0.09 0 0.035" rpy="-3.14159 -1.5708 0"/>
      <geometry>
        <mesh filename="package://assets/stator_x4_p36_36_unified.stl"/>
      </geometry>
      <material name="stator_x4_p36_36_unified_2_material">
        <color rgba="0.764706 0.545098 0.803922 1"/>
      </material>
    </visual>
    <collision>
      <origin xyz="0.09 0 0.035" rpy="-3.14159 -1.5708 0"/>
      <geometry>
        <mesh filename="package://assets/stator_x4_p36_36_unified.stl"/>
      </geometry>
    </collision>
  </link>
  <!-- Link urdf_l_lower_forearm_assembly -->
  <link name="urdf_l_lower_forearm_assembly">
    <inertial>
      <origin xyz="-0.000687732 -0.00432126 -0.0515634" rpy="0 0 0"/>
      <mass value="0.618"/>
      <inertia ixx="0.000619445" ixy="-4.69813e-06" ixz="1.66447e-05" iyy="0.000626234" iyz="-2.276e-05" izz="0.000448744"/>
    </inertial>
    <!-- Part urdf_l_lower_forearm_simplified -->
    <visual>
      <origin xyz="0 -0.009 -0.0615" rpy="-1.5708 -0 -3.14159"/>
      <geometry>
        <mesh filename="package://assets/urdf_l_lower_forearm_simplified.stl"/>
      </geometry>
      <material name="urdf_l_lower_forearm_simplified_material">
        <color rgba="0.980392 0.713725 0.00392157 1"/>
      </material>
    </visual>
    <collision>
      <origin xyz="0 -0.009 -0.0615" rpy="-1.5708 -0 -3.14159"/>
      <geometry>
        <mesh filename="package://assets/urdf_l_lower_forearm_simplified.stl"/>
      </geometry>
    </collision>
    <!-- Part stator_x4_p36_36_unified_3 -->
    <visual>
      <origin xyz="0 -0.0375 -0.0615" rpy="1.5708 -0 -3.14159"/>
      <geometry>
        <mesh filename="package://assets/stator_x4_p36_36_unified.stl"/>
      </geometry>
      <material name="stator_x4_p36_36_unified_3_material">
        <color rgba="0.764706 0.545098 0.803922 1"/>
      </material>
    </visual>
    <collision>
      <origin xyz="0 -0.0375 -0.0615" rpy="1.5708 -0 -3.14159"/>
      <geometry>
        <mesh filename="package://assets/stator_x4_p36_36_unified.stl"/>
      </geometry>
    </collision>
  </link>
  <!-- Link urdf_l_wrist_assembly -->
  <link name="urdf_l_wrist_assembly">
    <inertial>
      <origin xyz="-4.30487e-06 0.0434653 -0.0219307" rpy="0 0 0"/>
      <mass value="0.098"/>
      <inertia ixx="0.000123151" ixy="5.685e-09" ixz="4.662e-09" iyy="9.46279e-05" iyz="3.33959e-05" izz="0.000100785"/>
    </inertial>
    <!-- Part l_wrist -->
    <visual>
      <origin xyz="-4.31502e-06 0.0434653 -0.0219314" rpy="1.5708 0 -0"/>
      <geometry>
        <mesh filename="package://assets/l_wrist.stl"/>
      </geometry>
      <material name="l_wrist_material">
        <color rgba="0.8 0.74902 0.913725 1"/>
      </material>
    </visual>
    <collision>
      <origin xyz="-4.31502e-06 0.0434653 -0.0219314" rpy="1.5708 0 -0"/>
      <geometry>
        <mesh filename="package://assets/l_wrist.stl"/>
      </geometry>
    </collision>
  </link>
  <!-- Joint from urdf_l_lower_forearm_assembly to urdf_l_wrist_assembly -->
  <joint name="left_wrist_roll_joint_X4" type="revolute">
    <origin xyz="0 0.027 -0.0615" rpy="-1.5708 0 0"/>
    <parent link="urdf_l_lower_forearm_assembly"/>
    <child link="urdf_l_wrist_assembly"/>
    <axis xyz="0 0 1"/>
    <limit effort="10" velocity="10" lower="-1.5708" upper="1.5708"/>
  </joint>
  <!-- Joint from urdf_l_upper_forearm_assembly to urdf_l_lower_forearm_assembly -->
  <joint name="left_wrist_yaw_joint_X4" type="revolute">
    <origin xyz="0.163 0 0.035" rpy="0 -1.5708 0"/>
    <parent link="urdf_l_upper_forearm_assembly"/>
    <child link="urdf_l_lower_forearm_assembly"/>
    <axis xyz="0 0 1"/>
    <limit effort="10" velocity="10" lower="-2.35619" upper="2.35619"/>
  </joint>
  <!-- Joint from urdf_l_elbow_assembly to urdf_l_upper_forearm_assembly -->
  <joint name="left_elbow_pitch_joint_X6" type="revolute">
    <origin xyz="0 -0.035 -0.075" rpy="1.5708 1.309 3.14159"/>
    <parent link="urdf_l_elbow_assembly"/>
    <child link="urdf_l_upper_forearm_assembly"/>
    <axis xyz="0 0 1"/>
    <limit effort="10" velocity="10" lower="-1.8326" upper="1.309"/>
  </joint>
  <!-- Joint from urdf_l_upper_arm_assembly to urdf_l_elbow_assembly -->
  <joint name="left_shoulder_yaw_joint_X4" type="revolute">
    <origin xyz="-0.0343054 0.161394 -0.046" rpy="-1.5708 0.959931 -2.93215"/>
    <parent link="urdf_l_upper_arm_assembly"/>
    <child link="urdf_l_elbow_assembly"/>
    <axis xyz="0 0 1"/>
    <limit effort="10" velocity="10" lower="-1.74533" upper="2.96706"/>
  </joint>
  <!-- Joint from urdf_l_shoulder_assembly to urdf_l_upper_arm_assembly -->
  <joint name="left_shoulder_roll_joint_X6" type="revolute">
    <origin xyz="0.0456571 -0.00560599 0.07" rpy="0.122173 1.5708 0"/>
    <parent link="urdf_l_shoulder_assembly"/>
    <child link="urdf_l_upper_arm_assembly"/>
    <axis xyz="0 0 1"/>
    <limit effort="10" velocity="10" lower="-0.20944" upper="2.93215"/>
  </joint>
  <!-- Joint from urdf_simplified_torso to urdf_l_shoulder_assembly -->
  <joint name="left_shoulder_pitch_joint_X6" type="revolute">
    <origin xyz="-0.1755 -5.1e-11 0.423977" rpy="-1.5708 -0 1.5708"/>
    <parent link="urdf_simplified_torso"/>
    <child link="urdf_l_shoulder_assembly"/>
    <axis xyz="0 0 1"/>
    <limit effort="10" velocity="10" lower="-3.01942" upper="1.69297"/>
  </joint>
  <!-- Link urdf_r_shoulder_assembly -->
  <link name="urdf_r_shoulder_assembly">
    <inertial>
      <origin xyz="-0.0047018 0.000602814 -0.0660727" rpy="0 0 0"/>
      <mass value="1.02"/>
      <inertia ixx="0.0013257" ixy="-2.16639e-05" ixz="1.37507e-05" iyy="0.0011458" iyz="-3.46307e-06" izz="0.00104972"/>
    </inertial>
    <!-- Part stator_x6_p20_60_unified_3 -->
    <visual>
      <origin xyz="-0.038213 0.00469197 -0.07" rpy="0.122173 1.5708 0"/>
      <geometry>
        <mesh filename="package://assets/stator_x6_p20_60_unified.stl"/>
      </geometry>
      <material name="stator_x6_p20_60_unified_3_material">
        <color rgba="0.960784 0.835294 0.470588 1"/>
      </material>
    </visual>
    <collision>
      <origin xyz="-0.038213 0.00469197 -0.07" rpy="0.122173 1.5708 0"/>
      <geometry>
        <mesh filename="package://assets/stator_x6_p20_60_unified.stl"/>
      </geometry>
    </collision>
    <!-- Part r_shoulder -->
    <visual>
      <origin xyz="-0.00128021 0.000164153 -0.0501448" rpy="1.69297 1.5708 0"/>
      <geometry>
        <mesh filename="package://assets/r_shoulder.stl"/>
      </geometry>
      <material name="r_shoulder_material">
        <color rgba="0.615686 0.811765 0.929412 1"/>
      </material>
    </visual>
    <collision>
      <origin xyz="-0.00128021 0.000164153 -0.0501448" rpy="1.69297 1.5708 0"/>
      <geometry>
        <mesh filename="package://assets/r_shoulder.stl"/>
      </geometry>
    </collision>
  </link>
  <!-- Link urdf_r_upper_arm_assembly -->
  <link name="urdf_r_upper_arm_assembly">
    <inertial>
      <origin xyz="0.0216402 0.101809 -0.0347331" rpy="0 0 0"/>
      <mass value="0.802"/>
      <inertia ixx="0.00200295" ixy="-0.000209825" ixz="9.73944e-05" iyy="0.00106039" iyz="0.00045821" izz="0.00188605"/>
    </inertial>
    <!-- Part stator_x4_p36_36_unified_4 -->
    <visual>
      <origin xyz="0.01892 0.0890114 -0.046" rpy="-1.5708 0 -0.20944"/>
      <geometry>
        <mesh filename="package://assets/stator_x4_p36_36_unified.stl"/>
      </geometry>
      <material name="stator_x4_p36_36_unified_4_material">
        <color rgba="0.764706 0.545098 0.803922 1"/>
      </material>
    </visual>
    <collision>
      <origin xyz="0.01892 0.0890114 -0.046" rpy="-1.5708 0 -0.20944"/>
      <geometry>
        <mesh filename="package://assets/stator_x4_p36_36_unified.stl"/>
      </geometry>
    </collision>
    <!-- Part r_upper_arm -->
    <visual>
      <origin xyz="0.0188225 0.0885531 -0.025543" rpy="1.5708 0 -0.20944"/>
      <geometry>
        <mesh filename="package://assets/r_upper_arm.stl"/>
      </geometry>
      <material name="r_upper_arm_material">
        <color rgba="0.231373 0.380392 0.705882 1"/>
      </material>
    </visual>
    <collision>
      <origin xyz="0.0188225 0.0885531 -0.025543" rpy="1.5708 0 -0.20944"/>
      <geometry>
        <mesh filename="package://assets/r_upper_arm.stl"/>
      </geometry>
    </collision>
  </link>
  <!-- Link urdf_r_elbow_assembly -->
  <link name="urdf_r_elbow_assembly">
    <inertial>
      <origin xyz="-0.006946 -0.00482512 -0.0612736" rpy="0 0 0"/>
      <mass value="1.109"/>
      <inertia ixx="0.00147254" ixy="5.71903e-05" ixz="-4.8341e-05" iyy="0.00143026" iyz="-3.66028e-05" izz="0.00111817"/>
    </inertial>
    <!-- Part r_elbow -->
    <visual>
      <origin xyz="0.000264961 0.000199692 -0.0512953" rpy="0 0 0.610865"/>
      <geometry>
        <mesh filename="package://assets/r_elbow.stl"/>
      </geometry>
      <material name="r_elbow_material">
        <color rgba="0.796078 0.905882 0.745098 1"/>
      </material>
    </visual>
    <collision>
      <origin xyz="0.000264961 0.000199692 -0.0512953" rpy="0 0 0.610865"/>
      <geometry>
        <mesh filename="package://assets/r_elbow.stl"/>
      </geometry>
    </collision>
    <!-- Part stator_x6_p20_60_unified_4 -->
    <visual>
      <origin xyz="-0.0364523 -0.0255242 -0.065" rpy="-2.53073 -1.5708 0"/>
      <geometry>
        <mesh filename="package://assets/stator_x6_p20_60_unified.stl"/>
      </geometry>
      <material name="stator_x6_p20_60_unified_4_material">
        <color rgba="0.960784 0.835294 0.470588 1"/>
      </material>
    </visual>
    <collision>
      <origin xyz="-0.0364523 -0.0255242 -0.065" rpy="-2.53073 -1.5708 0"/>
      <geometry>
        <mesh filename="package://assets/stator_x6_p20_60_unified.stl"/>
      </geometry>
    </collision>
  </link>
  <!-- Link urdf_r_upper_forearm_assembly -->
  <link name="urdf_r_upper_forearm_assembly">
    <inertial>
      <origin xyz="0.0285486 0.0977333 0.0327896" rpy="0 0 0"/>
      <mass value="0.707"/>
      <inertia ixx="0.00159667" ixy="-0.000254664" ixz="-0.000102417" iyy="0.000776009" iyz="-0.000337457" izz="0.0014499"/>
    </inertial>
    <!-- Part stator_x4_p36_36_unified_5 -->
    <visual>
      <origin xyz="0.0232937 0.0869333 0.04" rpy="-1.309 1.5708 0"/>
      <geometry>
        <mesh filename="package://assets/stator_x4_p36_36_unified.stl"/>
      </geometry>
      <material name="stator_x4_p36_36_unified_5_material">
        <color rgba="0.764706 0.545098 0.803922 1"/>
      </material>
    </visual>
    <collision>
      <origin xyz="0.0232937 0.0869333 0.04" rpy="-1.309 1.5708 0"/>
      <geometry>
        <mesh filename="package://assets/stator_x4_p36_36_unified.stl"/>
      </geometry>
    </collision>
    <!-- Part r_upper_forearm -->
    <visual>
      <origin xyz="0.0263061 0.0801326 0.0254856" rpy="1.8326 1.5708 0"/>
      <geometry>
        <mesh filename="package://assets/r_upper_forearm.stl"/>
      </geometry>
      <material name="r_upper_forearm_material">
        <color rgba="0.890196 0.698039 0.639216 1"/>
      </material>
    </visual>
    <collision>
      <origin xyz="0.0263061 0.0801326 0.0254856" rpy="1.8326 1.5708 0"/>
      <geometry>
        <mesh filename="package://assets/r_upper_forearm.stl"/>
      </geometry>
    </collision>
  </link>
  <!-- Link urdf_r_lower_forearm_assembly -->
  <link name="urdf_r_lower_forearm_assembly">
    <inertial>
      <origin xyz="-2.4334e-08 0.00399848 0.046852" rpy="0 0 0"/>
      <mass value="0.618"/>
      <inertia ixx="0.000618602" ixy="-1.76e-10" ixz="5.34e-10" iyy="0.000617307" iyz="-3.83228e-05" izz="0.000437775"/>
    </inertial>
    <!-- Part r_lower_forearm -->
    <visual>
      <origin xyz="4.2712e-08 -0.00205797 0.0333447" rpy="3.14159 0 -0"/>
      <geometry>
        <mesh filename="package://assets/r_lower_forearm.stl"/>
      </geometry>
      <material name="r_lower_forearm_material">
        <color rgba="0.941176 0.87451 0.678431 1"/>
      </material>
    </visual>
    <collision>
      <origin xyz="4.2712e-08 -0.00205797 0.0333447" rpy="3.14159 0 -0"/>
      <geometry>
        <mesh filename="package://assets/r_lower_forearm.stl"/>
      </geometry>
    </collision>
    <!-- Part stator_x4_p36_36_unified_6 -->
    <visual>
      <origin xyz="0 0.038 0.0565" rpy="-1.5708 -1e-12 -3.14159"/>
      <geometry>
        <mesh filename="package://assets/stator_x4_p36_36_unified.stl"/>
      </geometry>
      <material name="stator_x4_p36_36_unified_6_material">
        <color rgba="0.764706 0.545098 0.803922 1"/>
      </material>
    </visual>
    <collision>
      <origin xyz="0 0.038 0.0565" rpy="-1.5708 -1e-12 -3.14159"/>
      <geometry>
        <mesh filename="package://assets/stator_x4_p36_36_unified.stl"/>
      </geometry>
    </collision>
  </link>
  <!-- Link urdf_r_wrist_assembly -->
  <link name="urdf_r_wrist_assembly">
    <inertial>
      <origin xyz="4.59046e-06 0.043439 -0.0219123" rpy="0 0 0"/>
      <mass value="0.15"/>
      <inertia ixx="0.000188543" ixy="-9.002e-09" ixz="-6.565e-09" iyy="0.000144985" iyz="5.11126e-05" izz="0.000154293"/>
    </inertial>
    <!-- Part r_wrist -->
    <visual>
      <origin xyz="4.44584e-06 0.0434653 -0.0219316" rpy="1.5708 -0 -0"/>
      <geometry>
        <mesh filename="package://assets/r_wrist.stl"/>
      </geometry>
      <material name="r_wrist_material">
        <color rgba="0.8 0.74902 0.913725 1"/>
      </material>
    </visual>
    <collision>
      <origin xyz="4.44584e-06 0.0434653 -0.0219316" rpy="1.5708 -0 -0"/>
      <geometry>
        <mesh filename="package://assets/r_wrist.stl"/>
      </geometry>
    </collision>
  </link>
  <!-- Joint from urdf_r_lower_forearm_assembly to urdf_r_wrist_assembly -->
  <joint name="right_wrist_roll_joint_X4" type="revolute">
    <origin xyz="-0 -0.027 0.0565" rpy="1.5708 0 -0"/>
    <parent link="urdf_r_lower_forearm_assembly"/>
    <child link="urdf_r_wrist_assembly"/>
    <axis xyz="0 0 1"/>
    <limit effort="10" velocity="10" lower="-1.5708" upper="1.5708"/>
  </joint>
  <!-- Joint from urdf_r_upper_forearm_assembly to urdf_r_lower_forearm_assembly -->
  <joint name="right_wrist_yaw_joint_X4" type="revolute">
    <origin xyz="0.0434816 0.162276 0.04" rpy="-1.309 1.5708 0"/>
    <parent link="urdf_r_upper_forearm_assembly"/>
    <child link="urdf_r_lower_forearm_assembly"/>
    <axis xyz="0 0 1"/>
    <limit effort="10" velocity="10" lower="-2.35619" upper="2.35619"/>
  </joint>
  <!-- Joint from urdf_r_elbow_assembly to urdf_r_upper_forearm_assembly -->
  <joint name="right_elbow_pitch_joint_X6" type="revolute">
    <origin xyz="0.0327661 0.0229431 -0.065" rpy="-1.5708 -0 2.18166"/>
    <parent link="urdf_r_elbow_assembly"/>
    <child link="urdf_r_upper_forearm_assembly"/>
    <axis xyz="0 0 1"/>
    <limit effort="10" velocity="10" lower="-1.309" upper="1.8326"/>
  </joint>
  <!-- Joint from urdf_r_upper_arm_assembly to urdf_r_elbow_assembly -->
  <joint name="right_shoulder_yaw_joint_X4" type="revolute">
    <origin xyz="0.035345 0.166285 -0.046" rpy="1.5708 -0 -0.20944"/>
    <parent link="urdf_r_upper_arm_assembly"/>
    <child link="urdf_r_elbow_assembly"/>
    <axis xyz="0 0 1"/>
    <limit effort="10" velocity="10" lower="-2.96706" upper="1.74533"/>
  </joint>
  <!-- Joint from urdf_r_shoulder_assembly to urdf_r_upper_arm_assembly -->
  <joint name="right_shoulder_roll_joint_X6" type="revolute">
    <origin xyz="0.0456571 -0.00560599 -0.07" rpy="0.122173 1.5708 0"/>
    <parent link="urdf_r_shoulder_assembly"/>
    <child link="urdf_r_upper_arm_assembly"/>
    <axis xyz="0 0 1"/>
    <limit effort="10" velocity="10" lower="-2.93215" upper="0.20944"/>
  </joint>
  <!-- Joint from urdf_simplified_torso to urdf_r_shoulder_assembly -->
  <joint name="right_shoulder_pitch_joint_X6" type="revolute">
    <origin xyz="0.1755 -5.1e-11 0.423977" rpy="-1.5708 -0 1.5708"/>
    <parent link="urdf_simplified_torso"/>
    <child link="urdf_r_shoulder_assembly"/>
    <axis xyz="0 0 1"/>
    <limit effort="10" velocity="10" lower="-3.01942" upper="1.69297"/>
  </joint>
  <!-- Joint from urdf_base to urdf_simplified_torso -->
  <joint name="waist_yaw_joint" type="revolute">
    <origin xyz="0.000698852 0.0333787 -0.300748" rpy="0 -0 0"/>
    <parent link="urdf_base"/>
    <child link="urdf_simplified_torso"/>
    <axis xyz="0 0 1"/>
    <limit effort="10" velocity="10" lower="-1.5708" upper="1.5708"/>
  </joint>
  <!-- Link urdf_hip_assembly -->
  <link name="urdf_hip_assembly">
    <inertial>
      <origin xyz="-0.00420762 6.23945e-06 0.0689982" rpy="0 0 0"/>
      <mass value="1.73"/>
      <inertia ixx="0.00302301" ixy="-4.5747e-08" ixz="2.30858e-05" iyy="0.00263533" iyz="8.49179e-07" izz="0.00228746"/>
    </inertial>
    <!-- Part hip -->
    <visual>
      <origin xyz="0.00253653 3.27638e-05 0.0520203" rpy="1.5708 1.5708 0"/>
      <geometry>
        <mesh filename="package://assets/hip.stl"/>
      </geometry>
      <material name="hip_material">
        <color rgba="0.0627451 0.266667 0.490196 1"/>
      </material>
    </visual>
    <collision>
      <origin xyz="0.00253653 3.27638e-05 0.0520203" rpy="1.5708 1.5708 0"/>
      <geometry>
        <mesh filename="package://assets/hip.stl"/>
      </geometry>
    </collision>
    <!-- Part stator_x8_p20_120_unified_4 -->
    <visual>
      <origin xyz="-0.043 -0 0.073" rpy="-3.14159 -1.5708 0"/>
      <geometry>
        <mesh filename="package://assets/stator_x8_p20_120_unified.stl"/>
      </geometry>
      <material name="stator_x8_p20_120_unified_4_material">
        <color rgba="0.882353 0.572549 0.478431 1"/>
      </material>
    </visual>
    <collision>
      <origin xyz="-0.043 -0 0.073" rpy="-3.14159 -1.5708 0"/>
      <geometry>
        <mesh filename="package://assets/stator_x8_p20_120_unified.stl"/>
      </geometry>
    </collision>
  </link>
  <!-- Link urdf_l_upper_femur_assembly -->
  <link name="urdf_l_upper_femur_assembly">
    <inertial>
      <origin xyz="-0.000406021 0.147969 -0.0457109" rpy="0 0 0"/>
      <mass value="1.912"/>
      <inertia ixx="0.00557257" ixy="-5.1876e-05" ixz="-1.18834e-06" iyy="0.00336728" iyz="0.000930002" izz="0.00512969"/>
    </inertial>
    <!-- Part l_upper_femur -->
    <visual>
      <origin xyz="-0.00151622 0.111785 -0.0257799" rpy="1.5708 0 0"/>
      <geometry>
        <mesh filename="package://assets/l_upper_femur.stl"/>
      </geometry>
      <material name="l_upper_femur_material">
        <color rgba="0.141176 0.694118 0.65098 1"/>
      </material>
    </visual>
    <collision>
      <origin xyz="-0.00151622 0.111785 -0.0257799" rpy="1.5708 0 0"/>
      <geometry>
        <mesh filename="package://assets/l_upper_femur.stl"/>
      </geometry>
    </collision>
    <!-- Part stator_x8_p20_120_unified_5 -->
    <visual>
      <origin xyz="0 0.124 -0.053" rpy="-1.5708 0 0"/>
      <geometry>
        <mesh filename="package://assets/stator_x8_p20_120_unified.stl"/>
      </geometry>
      <material name="stator_x8_p20_120_unified_5_material">
        <color rgba="0.882353 0.572549 0.478431 1"/>
      </material>
    </visual>
    <collision>
      <origin xyz="0 0.124 -0.053" rpy="-1.5708 0 0"/>
      <geometry>
        <mesh filename="package://assets/stator_x8_p20_120_unified.stl"/>
      </geometry>
    </collision>
  </link>
  <!-- Link urdf_lower_femur_assembly -->
  <link name="urdf_lower_femur_assembly">
    <inertial>
      <origin xyz="0.00357383 1.0389e-08 0.103307" rpy="0 0 0"/>
      <mass value="1.817"/>
      <inertia ixx="0.00421827" ixy="-2.5e-11" ixz="-0.00019709" iyy="0.00383469" iyz="-2.1291e-08" izz="0.00258541"/>
    </inertial>
    <!-- Part lower_femur -->
    <visual>
      <origin xyz="-0.00389134 -5.752e-09 0.070766" rpy="-3.14159 0 0"/>
      <geometry>
        <mesh filename="package://assets/lower_femur.stl"/>
      </geometry>
      <material name="lower_femur_material">
        <color rgba="0.380392 0.0470588 0.435294 1"/>
      </material>
    </visual>
    <collision>
      <origin xyz="-0.00389134 -5.752e-09 0.070766" rpy="-3.14159 0 0"/>
      <geometry>
        <mesh filename="package://assets/lower_femur.stl"/>
      </geometry>
    </collision>
    <!-- Part stator_x8_p20_120_unified_6 -->
    <visual>
      <origin xyz="0.043 -0 0.113" rpy="3.14159 1.5708 0"/>
      <geometry>
        <mesh filename="package://assets/stator_x8_p20_120_unified.stl"/>
      </geometry>
      <material name="stator_x8_p20_120_unified_6_material">
        <color rgba="0.882353 0.572549 0.478431 1"/>
      </material>
    </visual>
    <collision>
      <origin xyz="0.043 -0 0.113" rpy="3.14159 1.5708 0"/>
      <geometry>
        <mesh filename="package://assets/stator_x8_p20_120_unified.stl"/>
      </geometry>
    </collision>
  </link>
  <!-- Link urdf_l_tibia_assembly -->
  <link name="urdf_l_tibia_assembly">
    <inertial>
      <origin xyz="0.00463967 0.190721 -0.0449177" rpy="0 0 0"/>
      <mass value="6.45981"/>
      <inertia ixx="0.0785879" ixy="-0.00174734" ixz="0.000322174" iyy="0.0153456" iyz="0.00887502" izz="0.0762229"/>
    </inertial>
    <!-- Part stator_x4_p36_36_unified_7 -->
    <visual>
      <origin xyz="-0.018 0.16 -0.055" rpy="-0 1.5708 0"/>
      <geometry>
        <mesh filename="package://assets/stator_x4_p36_36_unified.stl"/>
      </geometry>
      <material name="stator_x4_p36_36_unified_7_material">
        <color rgba="0.764706 0.545098 0.803922 1"/>
      </material>
    </visual>
    <collision>
      <origin xyz="-0.018 0.16 -0.055" rpy="-0 1.5708 0"/>
      <geometry>
        <mesh filename="package://assets/stator_x4_p36_36_unified.stl"/>
      </geometry>
    </collision>
    <!-- Part stator_x4_p36_36_unified_8 -->
    <visual>
      <origin xyz="-0.018 0.235 -0.055" rpy="3.14159 -1.5708 0"/>
      <geometry>
        <mesh filename="package://assets/stator_x4_p36_36_unified.stl"/>
      </geometry>
      <material name="stator_x4_p36_36_unified_8_material">
        <color rgba="0.764706 0.545098 0.803922 1"/>
      </material>
    </visual>
    <collision>
      <origin xyz="-0.018 0.235 -0.055" rpy="3.14159 -1.5708 0"/>
      <geometry>
        <mesh filename="package://assets/stator_x4_p36_36_unified.stl"/>
      </geometry>
    </collision>
    <!-- Part m6_threaded_bar_300mm -->
    <visual>
      <origin xyz="0.0845 0.288554 -0.0732971" rpy="-3.14159 1.51844 1.5708"/>
      <geometry>
        <mesh filename="package://assets/m6_threaded_bar_300mm.stl"/>
      </geometry>
      <material name="m6_threaded_bar_300mm_material">
        <color rgba="0.141176 0.0352941 0.396078 1"/>
      </material>
    </visual>
    <collision>
      <origin xyz="0.0845 0.288554 -0.0732971" rpy="-3.14159 1.51844 1.5708"/>
      <geometry>
        <mesh filename="package://assets/m6_threaded_bar_300mm.stl"/>
      </geometry>
    </collision>
    <!-- Part urdf_spacer_x4 -->
    <visual>
      <origin xyz="0.05375 0.235 -0.055" rpy="-3.14159 1.50098 -1.5708"/>
      <geometry>
        <mesh filename="package://assets/urdf_spacer_x4.stl"/>
      </geometry>
      <material name="urdf_spacer_x4_material">
        <color rgba="0.615686 0.811765 0.929412 1"/>
      </material>
    </visual>
    <collision>
      <origin xyz="0.05375 0.235 -0.055" rpy="-3.14159 1.50098 -1.5708"/>
      <geometry>
        <mesh filename="package://assets/urdf_spacer_x4.stl"/>
      </geometry>
    </collision>
    <!-- Part urdf_l_tibia_assembly -->
    <visual>
      <origin xyz="0.000678721 0.186264 -0.0431371" rpy="1.5708 1.5708 0"/>
      <geometry>
        <mesh filename="package://assets/urdf_l_tibia_assembly.stl"/>
      </geometry>
      <material name="urdf_l_tibia_assembly_material">
        <color rgba="0.615686 0.811765 0.929412 1"/>
      </material>
    </visual>
    <collision>
      <origin xyz="0.000678721 0.186264 -0.0431371" rpy="1.5708 1.5708 0"/>
      <geometry>
        <mesh filename="package://assets/urdf_l_tibia_assembly.stl"/>
      </geometry>
    </collision>
    <!-- Part m6_threaded_bar_225mm -->
    <visual>
      <origin xyz="0.0845 0.326445 -0.0363334" rpy="-0 1.50098 -1.5708"/>
      <geometry>
        <mesh filename="package://assets/m6_threaded_bar_225mm.stl"/>
      </geometry>
      <material name="m6_threaded_bar_225mm_material">
        <color rgba="0.27451 0.0117647 0.317647 1"/>
      </material>
    </visual>
    <collision>
      <origin xyz="0.0845 0.326445 -0.0363334" rpy="-0 1.50098 -1.5708"/>
      <geometry>
        <mesh filename="package://assets/m6_threaded_bar_225mm.stl"/>
      </geometry>
    </collision>
    <!-- Part urdf_spacer_x4_2 -->
    <visual>
      <origin xyz="0.05375 0.16 -0.055" rpy="3.14159 -1.51844 -1.5708"/>
      <geometry>
        <mesh filename="package://assets/urdf_spacer_x4.stl"/>
      </geometry>
      <material name="urdf_spacer_x4_2_material">
        <color rgba="0.615686 0.811765 0.929412 1"/>
      </material>
    </visual>
    <collision>
      <origin xyz="0.05375 0.16 -0.055" rpy="3.14159 -1.51844 -1.5708"/>
      <geometry>
        <mesh filename="package://assets/urdf_spacer_x4.stl"/>
      </geometry>
    </collision>
  </link>
  <!-- Link urdf_ankle_assembly -->
  <link name="urdf_ankle_assembly">
    <inertial>
      <origin xyz="-0 0.0125426 -0.004" rpy="0 0 0"/>
      <mass value="0.0818219"/>
      <inertia ixx="1.69449e-05" ixy="0" ixz="0" iyy="1.25404e-05" iyz="0" izz="2.15245e-05"/>
    </inertial>
    <!-- Part urdf_ankle_assembly -->
    <visual>
      <origin xyz="-0 0.0125426 -0.004" rpy="1.5708 1.5708 0"/>
      <geometry>
        <mesh filename="package://assets/urdf_ankle_assembly.stl"/>
      </geometry>
      <material name="urdf_ankle_assembly_material">
        <color rgba="0.615686 0.811765 0.929412 1"/>
      </material>
    </visual>
    <collision>
      <origin xyz="-0 0.0125426 -0.004" rpy="1.5708 1.5708 0"/>
      <geometry>
        <mesh filename="package://assets/urdf_ankle_assembly.stl"/>
      </geometry>
    </collision>
  </link>
  <!-- Link urdf_foot_assembly -->
  <link name="urdf_foot_assembly">
    <inertial>
      <origin xyz="-9.73e-10 0.0209668 0.0427639" rpy="0 0 0"/>
      <mass value="0.504"/>
      <inertia ixx="0.00202397" ixy="-1.6e-11" ixz="1.2e-11" iyy="0.00229243" iyz="5.90887e-06" izz="0.000361698"/>
    </inertial>
    <!-- Part urdf_foot_assembly -->
    <visual>
      <origin xyz="5.6e-11 0.0209668 0.0427639" rpy="1.5708 0 -0"/>
      <geometry>
        <mesh filename="package://assets/urdf_foot_assembly.stl"/>
      </geometry>
      <material name="urdf_foot_assembly_material">
        <color rgba="0.615686 0.811765 0.929412 1"/>
      </material>
    </visual>
    <collision>
      <origin xyz="5.6e-11 0.0209668 0.0427639" rpy="1.5708 0 -0"/>
      <geometry>
        <mesh filename="package://assets/urdf_foot_assembly.stl"/>
      </geometry>
    </collision>
  </link>
  <!-- Joint from urdf_ankle_assembly to urdf_foot_assembly -->
  <joint name="left_ankle_roll_joint" type="revolute">
    <origin xyz="-0.012 0.028 -0.004" rpy="0 1.5708 0"/>
    <parent link="urdf_ankle_assembly"/>
    <child link="urdf_foot_assembly"/>
    <axis xyz="0 0 1"/>
    <limit effort="10" velocity="10" lower="-0.785398" upper="0.785398"/>
  </joint>
  <!-- Joint from urdf_l_tibia_assembly to urdf_ankle_assembly -->
  <joint name="left_ankle_pitch_joint" type="revolute">
    <origin xyz="0 0.395 -0.051" rpy="0 -0 0"/>
    <parent link="urdf_l_tibia_assembly"/>
    <child link="urdf_ankle_assembly"/>
    <axis xyz="0 0 1"/>
    <limit effort="10" velocity="10" lower="-0.785398" upper="0.785398"/>
  </joint>
  <!-- Joint from urdf_lower_femur_assembly to urdf_l_tibia_assembly -->
  <joint name="left_knee_joint" type="revolute">
    <origin xyz="-0.055 0 0.113" rpy="1.5708 0 -1.5708"/>
    <parent link="urdf_lower_femur_assembly"/>
    <child link="urdf_l_tibia_assembly"/>
    <axis xyz="0 0 1"/>
    <limit effort="10" velocity="10" lower="-0.174533" upper="1.5708"/>
  </joint>
  <!-- Joint from urdf_l_upper_femur_assembly to urdf_lower_femur_assembly -->
  <joint name="left_hip_yaw_joint" type="revolute">
    <origin xyz="-0 0.217 -0.053" rpy="-1.5708 0 0"/>
    <parent link="urdf_l_upper_femur_assembly"/>
    <child link="urdf_lower_femur_assembly"/>
    <axis xyz="0 0 1"/>
    <limit effort="10" velocity="10" lower="-1.5708" upper="1.5708"/>
  </joint>
  <!-- Joint from urdf_hip_assembly to urdf_l_upper_femur_assembly -->
  <joint name="left_hip_roll_joint" type="revolute">
    <origin xyz="0.055 0 0.073" rpy="-0 1.5708 0"/>
    <parent link="urdf_hip_assembly"/>
    <child link="urdf_l_upper_femur_assembly"/>
    <axis xyz="0 0 1"/>
    <limit effort="10" velocity="10" lower="-0.349066" upper="3.14159"/>
  </joint>
  <!-- Joint from urdf_base to urdf_hip_assembly -->
  <joint name="left_hip_pitch_joint" type="revolute">
    <origin xyz="-0.111301 0.0333787 -0.467748" rpy="-1.5708 -0 1.5708"/>
    <parent link="urdf_base"/>
    <child link="urdf_hip_assembly"/>
    <axis xyz="0 0 1"/>
    <limit effort="10" velocity="10" lower="-2.53073" upper="1.5708"/>
  </joint>
  <!-- Link urdf_hip_assembly_2 -->
  <link name="urdf_hip_assembly_2">
    <inertial>
      <origin xyz="-0.00420762 6.23945e-06 0.0739982" rpy="0 0 0"/>
      <mass value="1.73"/>
      <inertia ixx="0.00302301" ixy="-4.5747e-08" ixz="2.30858e-05" iyy="0.00263533" iyz="8.49179e-07" izz="0.00228746"/>
    </inertial>
    <!-- Part hip_2 -->
    <visual>
      <origin xyz="0.00253653 3.27638e-05 0.0570203" rpy="1.5708 1.5708 0"/>
      <geometry>
        <mesh filename="package://assets/hip.stl"/>
      </geometry>
      <material name="hip_2_material">
        <color rgba="0.0627451 0.266667 0.490196 1"/>
      </material>
    </visual>
    <collision>
      <origin xyz="0.00253653 3.27638e-05 0.0570203" rpy="1.5708 1.5708 0"/>
      <geometry>
        <mesh filename="package://assets/hip.stl"/>
      </geometry>
    </collision>
    <!-- Part stator_x8_p20_120_unified_7 -->
    <visual>
      <origin xyz="-0.043 0 0.078" rpy="-3.14159 -1.5708 0"/>
      <geometry>
        <mesh filename="package://assets/stator_x8_p20_120_unified.stl"/>
      </geometry>
      <material name="stator_x8_p20_120_unified_7_material">
        <color rgba="0.882353 0.572549 0.478431 1"/>
      </material>
    </visual>
    <collision>
      <origin xyz="-0.043 0 0.078" rpy="-3.14159 -1.5708 0"/>
      <geometry>
        <mesh filename="package://assets/stator_x8_p20_120_unified.stl"/>
      </geometry>
    </collision>
  </link>
  <!-- Link urdf_r_upper_femur_assemby -->
  <link name="urdf_r_upper_femur_assemby">
    <inertial>
      <origin xyz="0.000405705 0.147963 -0.0457092" rpy="0 0 0"/>
      <mass value="1.912"/>
      <inertia ixx="0.00557422" ixy="5.18237e-05" ixz="1.24938e-06" iyy="0.00336736" iyz="0.000930579" izz="0.00513139"/>
    </inertial>
    <!-- Part r_upper_femur -->
    <visual>
      <origin xyz="0.00151505 0.111761 -0.0257733" rpy="1.5708 0 -0"/>
      <geometry>
        <mesh filename="package://assets/r_upper_femur.stl"/>
      </geometry>
      <material name="r_upper_femur_material">
        <color rgba="0.941176 0.87451 0.678431 1"/>
      </material>
    </visual>
    <collision>
      <origin xyz="0.00151505 0.111761 -0.0257733" rpy="1.5708 0 -0"/>
      <geometry>
        <mesh filename="package://assets/r_upper_femur.stl"/>
      </geometry>
    </collision>
    <!-- Part stator_x8_p20_120_unified_8 -->
    <visual>
      <origin xyz="-0 0.124 -0.053" rpy="-1.5708 -0 0"/>
      <geometry>
        <mesh filename="package://assets/stator_x8_p20_120_unified.stl"/>
      </geometry>
      <material name="stator_x8_p20_120_unified_8_material">
        <color rgba="0.882353 0.572549 0.478431 1"/>
      </material>
    </visual>
    <collision>
      <origin xyz="-0 0.124 -0.053" rpy="-1.5708 -0 0"/>
      <geometry>
        <mesh filename="package://assets/stator_x8_p20_120_unified.stl"/>
      </geometry>
    </collision>
  </link>
  <!-- Link urdf_lower_femur_assembly_2 -->
  <link name="urdf_lower_femur_assembly_2">
    <inertial>
      <origin xyz="-0.00357383 -1.0389e-08 0.103307" rpy="0 0 0"/>
      <mass value="1.817"/>
      <inertia ixx="0.00421827" ixy="-2.5e-11" ixz="0.00019709" iyy="0.00383469" iyz="2.1291e-08" izz="0.00258541"/>
    </inertial>
    <!-- Part lower_femur_2 -->
    <visual>
      <origin xyz="0.00389134 5.752e-09 0.070766" rpy="-3.14159 0 3.14159"/>
      <geometry>
        <mesh filename="package://assets/lower_femur.stl"/>
      </geometry>
      <material name="lower_femur_2_material">
        <color rgba="0.380392 0.0470588 0.435294 1"/>
      </material>
    </visual>
    <collision>
      <origin xyz="0.00389134 5.752e-09 0.070766" rpy="-3.14159 0 3.14159"/>
      <geometry>
        <mesh filename="package://assets/lower_femur.stl"/>
      </geometry>
    </collision>
    <!-- Part stator_x8_p20_120_unified_9 -->
    <visual>
      <origin xyz="-0.043 0 0.113" rpy="0 1.5708 0"/>
      <geometry>
        <mesh filename="package://assets/stator_x8_p20_120_unified.stl"/>
      </geometry>
      <material name="stator_x8_p20_120_unified_9_material">
        <color rgba="0.882353 0.572549 0.478431 1"/>
      </material>
    </visual>
    <collision>
      <origin xyz="-0.043 0 0.113" rpy="0 1.5708 0"/>
      <geometry>
        <mesh filename="package://assets/stator_x8_p20_120_unified.stl"/>
      </geometry>
    </collision>
  </link>
  <!-- Link urdf_r_tibia_assembly -->
  <link name="urdf_r_tibia_assembly">
    <inertial>
      <origin xyz="0.00463921 0.190727 0.0449175" rpy="0 0 0"/>
      <mass value="6.45984"/>
      <inertia ixx="0.0785959" ixy="-0.00175015" ixz="-0.000322094" iyy="0.0153456" iyz="-0.0088755" izz="0.0762312"/>
    </inertial>
    <!-- Part urdf_spacer_x4_3 -->
    <visual>
      <origin xyz="0.05375 0.16 0.055" rpy="-3.14159 1.51844 -1.5708"/>
      <geometry>
        <mesh filename="package://assets/urdf_spacer_x4.stl"/>
      </geometry>
      <material name="urdf_spacer_x4_3_material">
        <color rgba="0.615686 0.811765 0.929412 1"/>
      </material>
    </visual>
    <collision>
      <origin xyz="0.05375 0.16 0.055" rpy="-3.14159 1.51844 -1.5708"/>
      <geometry>
        <mesh filename="package://assets/urdf_spacer_x4.stl"/>
      </geometry>
    </collision>
    <!-- Part m6_threaded_bar_225mm_2 -->
    <visual>
      <origin xyz="0.0845 0.326658 0.0363483" rpy="3.14159 1.50098 1.5708"/>
      <geometry>
        <mesh filename="package://assets/m6_threaded_bar_225mm.stl"/>
      </geometry>
      <material name="m6_threaded_bar_225mm_2_material">
        <color rgba="0.27451 0.0117647 0.317647 1"/>
      </material>
    </visual>
    <collision>
      <origin xyz="0.0845 0.326658 0.0363483" rpy="3.14159 1.50098 1.5708"/>
      <geometry>
        <mesh filename="package://assets/m6_threaded_bar_225mm.stl"/>
      </geometry>
    </collision>
    <!-- Part urdf_spacer_x4_4 -->
    <visual>
      <origin xyz="0.05375 0.235 0.055" rpy="-3.14159 -1.50098 -1.5708"/>
      <geometry>
        <mesh filename="package://assets/urdf_spacer_x4.stl"/>
      </geometry>
      <material name="urdf_spacer_x4_4_material">
        <color rgba="0.615686 0.811765 0.929412 1"/>
      </material>
    </visual>
    <collision>
      <origin xyz="0.05375 0.235 0.055" rpy="-3.14159 -1.50098 -1.5708"/>
      <geometry>
        <mesh filename="package://assets/urdf_spacer_x4.stl"/>
      </geometry>
    </collision>
    <!-- Part urdf_r_tibia_assembly -->
    <visual>
      <origin xyz="0.000678806 0.186264 0.0431372" rpy="1.5708 1.5708 0"/>
      <geometry>
        <mesh filename="package://assets/urdf_r_tibia_assembly.stl"/>
      </geometry>
      <material name="urdf_r_tibia_assembly_material">
        <color rgba="0.615686 0.811765 0.929412 1"/>
      </material>
    </visual>
    <collision>
      <origin xyz="0.000678806 0.186264 0.0431372" rpy="1.5708 1.5708 0"/>
      <geometry>
        <mesh filename="package://assets/urdf_r_tibia_assembly.stl"/>
      </geometry>
    </collision>
    <!-- Part stator_x4_p36_36_unified_9 -->
    <visual>
      <origin xyz="-0.018 0.16 0.055" rpy="-0 1.5708 0"/>
      <geometry>
        <mesh filename="package://assets/stator_x4_p36_36_unified.stl"/>
      </geometry>
      <material name="stator_x4_p36_36_unified_9_material">
        <color rgba="0.764706 0.545098 0.803922 1"/>
      </material>
    </visual>
    <collision>
      <origin xyz="-0.018 0.16 0.055" rpy="-0 1.5708 0"/>
      <geometry>
        <mesh filename="package://assets/stator_x4_p36_36_unified.stl"/>
      </geometry>
    </collision>
    <!-- Part m6_threaded_bar_300mm_2 -->
    <visual>
      <origin xyz="0.0845 0.288767 0.0732859" rpy="0 1.51844 -1.5708"/>
      <geometry>
        <mesh filename="package://assets/m6_threaded_bar_300mm.stl"/>
      </geometry>
      <material name="m6_threaded_bar_300mm_2_material">
        <color rgba="0.141176 0.0352941 0.396078 1"/>
      </material>
    </visual>
    <collision>
      <origin xyz="0.0845 0.288767 0.0732859" rpy="0 1.51844 -1.5708"/>
      <geometry>
        <mesh filename="package://assets/m6_threaded_bar_300mm.stl"/>
      </geometry>
    </collision>
    <!-- Part stator_x4_p36_36_unified_10 -->
    <visual>
      <origin xyz="-0.018 0.235 0.055" rpy="-3.14159 -1.5708 0"/>
      <geometry>
        <mesh filename="package://assets/stator_x4_p36_36_unified.stl"/>
      </geometry>
      <material name="stator_x4_p36_36_unified_10_material">
        <color rgba="0.764706 0.545098 0.803922 1"/>
      </material>
    </visual>
    <collision>
      <origin xyz="-0.018 0.235 0.055" rpy="-3.14159 -1.5708 0"/>
      <geometry>
        <mesh filename="package://assets/stator_x4_p36_36_unified.stl"/>
      </geometry>
    </collision>
  </link>
  <!-- Link urdf_ankle_assembly_2 -->
  <link name="urdf_ankle_assembly_2">
    <inertial>
      <origin xyz="-0 0.0125426 -0.004" rpy="0 0 0"/>
      <mass value="0.0818219"/>
      <inertia ixx="1.69449e-05" ixy="0" ixz="0" iyy="1.25404e-05" iyz="0" izz="2.15245e-05"/>
    </inertial>
    <!-- Part urdf_ankle_assembly_2 -->
    <visual>
      <origin xyz="-0 0.0125426 -0.004" rpy="1.5708 1.5708 0"/>
      <geometry>
        <mesh filename="package://assets/urdf_ankle_assembly.stl"/>
      </geometry>
      <material name="urdf_ankle_assembly_2_material">
        <color rgba="0.615686 0.811765 0.929412 1"/>
      </material>
    </visual>
    <collision>
      <origin xyz="-0 0.0125426 -0.004" rpy="1.5708 1.5708 0"/>
      <geometry>
        <mesh filename="package://assets/urdf_ankle_assembly.stl"/>
      </geometry>
    </collision>
  </link>
  <!-- Link urdf_foot_assembly_2 -->
  <link name="urdf_foot_assembly_2">
    <inertial>
      <origin xyz="-9.73e-10 0.0209668 0.0427639" rpy="0 0 0"/>
      <mass value="0.504"/>
      <inertia ixx="0.00202397" ixy="-1.6e-11" ixz="1.2e-11" iyy="0.00229243" iyz="5.90887e-06" izz="0.000361698"/>
    </inertial>
    <!-- Part urdf_foot_assembly_2 -->
    <visual>
      <origin xyz="5.6e-11 0.0209668 0.0427639" rpy="1.5708 0 0"/>
      <geometry>
        <mesh filename="package://assets/urdf_foot_assembly.stl"/>
      </geometry>
      <material name="urdf_foot_assembly_2_material">
        <color rgba="0.615686 0.811765 0.929412 1"/>
      </material>
    </visual>
    <collision>
      <origin xyz="5.6e-11 0.0209668 0.0427639" rpy="1.5708 0 0"/>
      <geometry>
        <mesh filename="package://assets/urdf_foot_assembly.stl"/>
      </geometry>
    </collision>
  </link>
  <!-- Joint from urdf_ankle_assembly_2 to urdf_foot_assembly_2 -->
  <joint name="right_ankle_pitch_joint" type="revolute">
    <origin xyz="-0.012 0.028 -0.004" rpy="0 1.5708 0"/>
    <parent link="urdf_ankle_assembly_2"/>
    <child link="urdf_foot_assembly_2"/>
    <axis xyz="0 0 1"/>
    <limit effort="10" velocity="10" lower="-0.785398" upper="0.785398"/>
  </joint>
  <!-- Joint from urdf_r_tibia_assembly to urdf_ankle_assembly_2 -->
  <joint name="right_ankle_roll_joint" type="revolute">
    <origin xyz="-0 0.395 0.059" rpy="0 -0 0"/>
    <parent link="urdf_r_tibia_assembly"/>
    <child link="urdf_ankle_assembly_2"/>
    <axis xyz="0 0 1"/>
    <limit effort="10" velocity="10" lower="-0.785398" upper="0.785398"/>
  </joint>
  <!-- Joint from urdf_lower_femur_assembly_2 to urdf_r_tibia_assembly -->
  <joint name="right_knee_joint" type="revolute">
    <origin xyz="0.055 -0 0.113" rpy="1.5708 0 -1.5708"/>
    <parent link="urdf_lower_femur_assembly_2"/>
    <child link="urdf_r_tibia_assembly"/>
    <axis xyz="0 0 1"/>
    <limit effort="10" velocity="10" lower="-0.174533" upper="1.5708"/>
  </joint>
  <!-- Joint from urdf_r_upper_femur_assemby to urdf_lower_femur_assembly_2 -->
  <joint name="right_hip_yaw_joint" type="revolute">
    <origin xyz="0 0.217 -0.053" rpy="-1.5708 0 -0"/>
    <parent link="urdf_r_upper_femur_assemby"/>
    <child link="urdf_lower_femur_assembly_2"/>
    <axis xyz="0 0 1"/>
    <limit effort="10" velocity="10" lower="-1.5708" upper="1.5708"/>
  </joint>
  <!-- Joint from urdf_hip_assembly_2 to urdf_r_upper_femur_assemby -->
  <joint name="right_hip_roll_joint" type="revolute">
    <origin xyz="0.055 0 0.078" rpy="-3.14159 -1.5708 0"/>
    <parent link="urdf_hip_assembly_2"/>
    <child link="urdf_r_upper_femur_assemby"/>
    <axis xyz="0 0 1"/>
    <limit effort="10" velocity="10" lower="-3.14159" upper="0.349066"/>
  </joint>
  <!-- Joint from urdf_base to urdf_hip_assembly_2 -->
  <joint name="right_hip_pitch_joint" type="revolute">
    <origin xyz="0.107699 0.0333787 -0.467748" rpy="1.5708 -0 1.5708"/>
    <parent link="urdf_base"/>
    <child link="urdf_hip_assembly_2"/>
    <axis xyz="0 0 1"/>
    <limit effort="10" velocity="10" lower="-1.5708" upper="2.53073"/>
  </joint>
</robot>
