<?xml version='1.0' encoding='utf-8'?>
<robot name="robot_harambe">
  <link name="urdf_base">
    <inertial>
      <origin xyz="0.0334604 -0.000699269 -0.431702" rpy="0 0 0" />
      <mass value="5.132" />
      <inertia ixx="0.0288848" ixy="2.35276e-07" ixz="-2.88595e-05" iyy="0.0213139" iyz="-6.5838e-06" izz="0.0155352" />
    </inertial>
    <visual>
      <origin xyz="0.0333787 0.0103011 -0.467748" rpy="-1.5708 0.785398 0" />
      <geometry>
        <mesh filename="package://assets/stator_x8_p20_120_unified.stl" />
      </geometry>
      <material name="stator_x8_p20_120_unified_material">
        <color rgba="0.882353 0.572549 0.478431 1" />
      </material>
    </visual>
    <collision>
      <origin xyz="0.0333787 0.0103011 -0.467748" rpy="-1.5708 0.785398 0" />
      <geometry>
        <mesh filename="package://assets/stator_x8_p20_120_unified.stl" />
      </geometry>
    </collision>
    <visual>
      <origin xyz="-0.00271429 -0.000697952 -0.432504" rpy="0 0 -1.5708" />
      <geometry>
        <mesh filename="package://assets/b_base.stl" />
      </geometry>
      <material name="b_base_material">
        <color rgba="0.368627 0.25098 0.643137 1" />
      </material>
    </visual>
    <collision>
      <origin xyz="-0.00271429 -0.000697952 -0.432504" rpy="0 0 -1.5708" />
      <geometry>
        <mesh filename="package://assets/b_base.stl" />
      </geometry>
    </collision>
    <visual>
      <origin xyz="0.0333787 -0.0116989 -0.467748" rpy="1.5708 -0.785398 0" />
      <geometry>
        <mesh filename="package://assets/stator_x8_p20_120_unified.stl" />
      </geometry>
      <material name="stator_x8_p20_120_unified_2_material">
        <color rgba="0.882353 0.572549 0.478431 1" />
      </material>
    </visual>
    <collision>
      <origin xyz="0.0333787 -0.0116989 -0.467748" rpy="1.5708 -0.785398 0" />
      <geometry>
        <mesh filename="package://assets/stator_x8_p20_120_unified.stl" />
      </geometry>
    </collision>
    <visual>
      <origin xyz="0.0333787 -0.000698852 -0.396748" rpy="0 0 -1.5708" />
      <geometry>
        <mesh filename="package://assets/stator_x8_p20_120_unified.stl" />
      </geometry>
      <material name="stator_x8_p20_120_unified_3_material">
        <color rgba="0.882353 0.572549 0.478431 1" />
      </material>
    </visual>
    <collision>
      <origin xyz="0.0333787 -0.000698852 -0.396748" rpy="0 0 -1.5708" />
      <geometry>
        <mesh filename="package://assets/stator_x8_p20_120_unified.stl" />
      </geometry>
    </collision>
    <visual>
      <origin xyz="0.070373 -0.000705351 -0.431099" rpy="0 0 -1.5708" />
      <geometry>
        <mesh filename="package://assets/f_base.stl" />
      </geometry>
      <material name="f_base_material">
        <color rgba="0.909804 0.572549 0.164706 1" />
      </material>
    </visual>
    <collision>
      <origin xyz="0.070373 -0.000705351 -0.431099" rpy="0 0 -1.5708" />
      <geometry>
        <mesh filename="package://assets/f_base.stl" />
      </geometry>
    </collision>
  </link>
  <link name="urdf_simplified_torso_sub_assembly">
    <inertial>
      <origin xyz="0.00084485 -0.00587549 0.417851" rpy="0 0 0" />
      <mass value="9.22071" />
      <inertia ixx="0.324451" ixy="2.3692e-08" ixz="-0.00208618" iyy="0.220452" iyz="-0.000110066" izz="0.138166" />
    </inertial>
    <visual>
      <origin xyz="4.00834e-06 -0.168755 0.427883" rpy="0 0 -1.5708" />
      <geometry>
        <mesh filename="package://assets/urdf_r_plate_shoulder_with_limiter_pla.stl" />
      </geometry>
      <material name="urdf_r_plate_shoulder_with_limiter_pla_material">
        <color rgba="0.647059 0.647059 0.647059 1" />
      </material>
    </visual>
    <collision>
      <origin xyz="4.00834e-06 -0.168755 0.427883" rpy="0 0 -1.5708" />
      <geometry>
        <mesh filename="package://assets/urdf_r_plate_shoulder_with_limiter_pla.stl" />
      </geometry>
    </collision>
    <visual>
      <origin xyz="4.00839e-06 0.156752 0.427883" rpy="0 0 -1.5708" />
      <geometry>
        <mesh filename="package://assets/urdf_l_plate_shoulder_with_limiter_pla.stl" />
      </geometry>
      <material name="urdf_l_plate_shoulder_with_limiter_pla_material">
        <color rgba="0.615686 0.811765 0.929412 1" />
      </material>
    </visual>
    <collision>
      <origin xyz="4.00839e-06 0.156752 0.427883" rpy="0 0 -1.5708" />
      <geometry>
        <mesh filename="package://assets/urdf_l_plate_shoulder_with_limiter_pla.stl" />
      </geometry>
    </collision>
    <visual>
      <origin xyz="4.00839e-06 -0.0990017 0.427" rpy="-3.14159 1.57079 1.5708" />
      <geometry>
        <mesh filename="package://assets/stator_x6_p20_60_unified.stl" />
      </geometry>
      <material name="stator_x6_p20_60_unified_material">
        <color rgba="0.960784 0.835294 0.470588 1" />
      </material>
    </visual>
    <collision>
      <origin xyz="4.00839e-06 -0.0990017 0.427" rpy="-3.14159 1.57079 1.5708" />
      <geometry>
        <mesh filename="package://assets/stator_x6_p20_60_unified.stl" />
      </geometry>
    </collision>
    <visual>
      <origin xyz="4.00839e-06 0.0869983 0.427" rpy="0 1.57079 1.5708" />
      <geometry>
        <mesh filename="package://assets/stator_x6_p20_60_unified.stl" />
      </geometry>
      <material name="stator_x6_p20_60_unified_2_material">
        <color rgba="0.960784 0.835294 0.470588 1" />
      </material>
    </visual>
    <collision>
      <origin xyz="4.00839e-06 0.0869983 0.427" rpy="0 1.57079 1.5708" />
      <geometry>
        <mesh filename="package://assets/stator_x6_p20_60_unified.stl" />
      </geometry>
    </collision>
    <visual>
      <origin xyz="4.00844e-06 -0.00600172 0.2625" rpy="0 0 -1.5708" />
      <geometry>
        <mesh filename="package://assets/urdf_simplified_torso.stl" />
      </geometry>
      <material name="urdf_simplified_torso_material">
        <color rgba="0.647059 0.647059 0.647059 1" />
      </material>
    </visual>
    <collision>
      <origin xyz="4.00844e-06 -0.00600172 0.2625" rpy="0 0 -1.5708" />
      <geometry>
        <mesh filename="package://assets/urdf_simplified_torso.stl" />
      </geometry>
    </collision>
    <visual>
      <origin xyz="0 0 0.005" rpy="0 0 -1.5708" />
      <geometry>
        <mesh filename="package://assets/urdf_torso_pelvis_plate_pla.stl" />
      </geometry>
      <material name="urdf_torso_pelvis_plate_pla_material">
        <color rgba="0.231373 0.380392 0.705882 1" />
      </material>
    </visual>
    <collision>
      <origin xyz="0 0 0.005" rpy="0 0 -1.5708" />
      <geometry>
        <mesh filename="package://assets/urdf_torso_pelvis_plate_pla.stl" />
      </geometry>
    </collision>
    <visual>
      <origin xyz="4.18304e-05 -0.00635981 0.6725" rpy="0 0 -1.5708" />
      <geometry>
        <mesh filename="package://assets/head.stl" />
      </geometry>
      <material name="head_material">
        <color rgba="0.737255 0.937255 0.917647 1" />
      </material>
    </visual>
    <collision>
      <origin xyz="4.18304e-05 -0.00635981 0.6725" rpy="0 0 -1.5708" />
      <geometry>
        <mesh filename="package://assets/head.stl" />
      </geometry>
    </collision>
    <visual>
      <origin xyz="4.18304e-05 -0.00635981 0.674429" rpy="0 0 -1.5708" />
      <geometry>
        <mesh filename="package://assets/back_access.stl" />
      </geometry>
      <material name="back_access_material">
        <color rgba="0.231373 0.380392 0.705882 1" />
      </material>
    </visual>
    <collision>
      <origin xyz="4.18304e-05 -0.00635981 0.674429" rpy="0 0 -1.5708" />
      <geometry>
        <mesh filename="package://assets/back_access.stl" />
      </geometry>
    </collision>
  </link>
  <link name="urdf_l_shoulder_assembly">
    <inertial>
      <origin xyz="-0.00497539 0.06724 -1.66088e-05" rpy="0 0 0" />
      <mass value="3.07135" />
      <inertia ixx="0.0035417" ixy="-2.84269e-05" ixz="-1.44615e-06" iyy="0.00290943" iyz="-3.53609e-06" izz="0.00313077" />
    </inertial>
    <visual>
      <origin xyz="-0.00130076 0.0502746 -6.96176e-06" rpy="0 0 -1.5708" />
      <geometry>
        <mesh filename="package://assets/l_shoulder.stl" />
      </geometry>
      <material name="l_shoulder_material">
        <color rgba="0.615686 0.811765 0.929412 1" />
      </material>
    </visual>
    <collision>
      <origin xyz="-0.00130076 0.0502746 -6.96176e-06" rpy="0 0 -1.5708" />
      <geometry>
        <mesh filename="package://assets/l_shoulder.stl" />
      </geometry>
    </collision>
    <visual>
      <origin xyz="-0.0385 0.07 1.02163e-07" rpy="-1.5708 0 -1.5708" />
      <geometry>
        <mesh filename="package://assets/stator_x6_p20_60_unified.stl" />
      </geometry>
      <material name="stator_x6_p20_60_unified_3_material">
        <color rgba="0.960784 0.835294 0.470588 1" />
      </material>
    </visual>
    <collision>
      <origin xyz="-0.0385 0.07 1.02163e-07" rpy="-1.5708 0 -1.5708" />
      <geometry>
        <mesh filename="package://assets/stator_x6_p20_60_unified.stl" />
      </geometry>
    </collision>
  </link>
  <link name="urdf_l_upper_arm_assembly">
    <inertial>
      <origin xyz="-0.0355919 -0.00100166 -0.105781" rpy="0 0 0" />
      <mass value="0.822" />
      <inertia ixx="0.0019913" ixy="-1.65839e-05" ixz="-0.00049977" iyy="0.00215042" iyz="-4.34174e-05" izz="0.00109808" />
    </inertial>
    <visual>
      <origin xyz="-0.0675144 -0.0411513 -0.158216" rpy="0 0 -1.5708" />
      <geometry>
        <mesh filename="package://assets/arm_limiter.stl" />
      </geometry>
      <material name="arm_limiter_material">
        <color rgba="1 0.756863 0.054902 1" />
      </material>
    </visual>
    <collision>
      <origin xyz="-0.0675144 -0.0411513 -0.158216" rpy="0 0 -1.5708" />
      <geometry>
        <mesh filename="package://assets/arm_limiter.stl" />
      </geometry>
    </collision>
    <visual>
      <origin xyz="-0.0256703 -3.97868e-07 -0.0912885" rpy="0 0 -1.5708" />
      <geometry>
        <mesh filename="package://assets/l_upper_arm.stl" />
      </geometry>
      <material name="l_upper_arm_material">
        <color rgba="0.231373 0.380392 0.705882 1" />
      </material>
    </visual>
    <collision>
      <origin xyz="-0.0256703 -3.97868e-07 -0.0912885" rpy="0 0 -1.5708" />
      <geometry>
        <mesh filename="package://assets/l_upper_arm.stl" />
      </geometry>
    </collision>
    <visual>
      <origin xyz="-0.046 -3.34262e-07 -0.091" rpy="3.14159 0 -1.5708" />
      <geometry>
        <mesh filename="package://assets/stator_x4_p36_36_unified.stl" />
      </geometry>
      <material name="stator_x4_p36_36_unified_material">
        <color rgba="0.764706 0.545098 0.803922 1" />
      </material>
    </visual>
    <collision>
      <origin xyz="-0.046 -3.34262e-07 -0.091" rpy="3.14159 0 -1.5708" />
      <geometry>
        <mesh filename="package://assets/stator_x4_p36_36_unified.stl" />
      </geometry>
    </collision>
  </link>
  <link name="urdf_l_elbow_assembly">
    <inertial>
      <origin xyz="-0.000233513 -0.00994774 -0.0631484" rpy="0 0 0" />
      <mass value="2.98735" />
      <inertia ixx="0.00298255" ixy="2.33726e-05" ixz="3.70633e-05" iyy="0.00314902" iyz="-0.000124999" izz="0.00265174" />
    </inertial>
    <visual>
      <origin xyz="-0.0350673 0.0364319 -0.00907087" rpy="0 0 -1.5708" />
      <geometry>
        <mesh filename="package://assets/elbow_limiter.stl" />
      </geometry>
      <material name="elbow_limiter_material">
        <color rgba="1 0.756863 0.054902 1" />
      </material>
    </visual>
    <collision>
      <origin xyz="-0.0350673 0.0364319 -0.00907087" rpy="0 0 -1.5708" />
      <geometry>
        <mesh filename="package://assets/elbow_limiter.stl" />
      </geometry>
    </collision>
    <visual>
      <origin xyz="0 -0.0445 -0.065" rpy="0 1.57079 1.5708" />
      <geometry>
        <mesh filename="package://assets/stator_x6_p20_60_unified.stl" />
      </geometry>
      <material name="stator_x6_p20_60_unified_4_material">
        <color rgba="0.960784 0.835294 0.470588 1" />
      </material>
    </visual>
    <collision>
      <origin xyz="0 -0.0445 -0.065" rpy="0 1.57079 1.5708" />
      <geometry>
        <mesh filename="package://assets/stator_x6_p20_60_unified.stl" />
      </geometry>
    </collision>
    <visual>
      <origin xyz="1.15447e-05 0.000331628 -0.0512953" rpy="0 0 -1.5708" />
      <geometry>
        <mesh filename="package://assets/l_elbow.stl" />
      </geometry>
      <material name="l_elbow_material">
        <color rgba="0.796078 0.905882 0.745098 1" />
      </material>
    </visual>
    <collision>
      <origin xyz="1.15447e-05 0.000331628 -0.0512953" rpy="0 0 -1.5708" />
      <geometry>
        <mesh filename="package://assets/l_elbow.stl" />
      </geometry>
    </collision>
  </link>
  <link name="urdf_l_upper_forearm_assembly">
    <inertial>
      <origin xyz="0.00170809 -0.0340287 -0.103744" rpy="0 0 0" />
      <mass value="0.727" />
      <inertia ixx="0.00176929" ixy="1.34904e-06" ixz="-5.81831e-06" iyy="0.0015348" iyz="-0.000394864" izz="0.000766079" />
    </inertial>
    <visual>
      <origin xyz="-0.0189086 -0.0747704 -0.156122" rpy="0 0 -1.5708" />
      <geometry>
        <mesh filename="package://assets/forearm_limiter.stl" />
      </geometry>
      <material name="forearm_limiter_material">
        <color rgba="1 0.756863 0.054902 1" />
      </material>
    </visual>
    <collision>
      <origin xyz="-0.0189086 -0.0747704 -0.156122" rpy="0 0 -1.5708" />
      <geometry>
        <mesh filename="package://assets/forearm_limiter.stl" />
      </geometry>
    </collision>
    <visual>
      <origin xyz="0.00467041 -0.0254855 -0.0842108" rpy="0 0 -1.5708" />
      <geometry>
        <mesh filename="package://assets/l_upper_forearm.stl" />
      </geometry>
      <material name="l_upper_forearm_material">
        <color rgba="0.890196 0.698039 0.639216 1" />
      </material>
    </visual>
    <collision>
      <origin xyz="0.00467041 -0.0254855 -0.0842108" rpy="0 0 -1.5708" />
      <geometry>
        <mesh filename="package://assets/l_upper_forearm.stl" />
      </geometry>
    </collision>
    <visual>
      <origin xyz="3.30588e-07 -0.04 -0.09" rpy="-3.14159 0 -1.5708" />
      <geometry>
        <mesh filename="package://assets/stator_x4_p36_36_unified.stl" />
      </geometry>
      <material name="stator_x4_p36_36_unified_2_material">
        <color rgba="0.764706 0.545098 0.803922 1" />
      </material>
    </visual>
    <collision>
      <origin xyz="3.30588e-07 -0.04 -0.09" rpy="-3.14159 0 -1.5708" />
      <geometry>
        <mesh filename="package://assets/stator_x4_p36_36_unified.stl" />
      </geometry>
    </collision>
  </link>
  <link name="urdf_l_lower_forearm_assembly">
    <inertial>
      <origin xyz="-0.00570813 0.00114678 -0.0477193" rpy="0 0 0" />
      <mass value="0.553" />
      <inertia ixx="0.000521453" ixy="6.12847e-06" ixz="-1.24836e-05" iyy="0.000524359" iyz="-2.55712e-05" izz="0.000391379" />
    </inertial>
    <visual>
      <origin xyz="-0.0248862 0.0317086 -0.00779106" rpy="0 0 -1.5708" />
      <geometry>
        <mesh filename="package://assets/hand_limiter.stl" />
      </geometry>
      <material name="hand_limiter_material">
        <color rgba="1 0.756863 0.054902 1" />
      </material>
    </visual>
    <collision>
      <origin xyz="-0.0248862 0.0317086 -0.00779106" rpy="0 0 -1.5708" />
      <geometry>
        <mesh filename="package://assets/hand_limiter.stl" />
      </geometry>
    </collision>
    <visual>
      <origin xyz="0.00198299 3.7846e-08 -0.0340631" rpy="0 0 -1.5708" />
      <geometry>
        <mesh filename="package://assets/l_lower_forearm.stl" />
      </geometry>
      <material name="l_lower_forearm_material">
        <color rgba="0.941176 0.87451 0.678431 1" />
      </material>
    </visual>
    <collision>
      <origin xyz="0.00198299 3.7846e-08 -0.0340631" rpy="0 0 -1.5708" />
      <geometry>
        <mesh filename="package://assets/l_lower_forearm.stl" />
      </geometry>
    </collision>
    <visual>
      <origin xyz="-0.038 0 -0.0565" rpy="1.5708 0 1.57079" />
      <geometry>
        <mesh filename="package://assets/stator_x4_p36_36_unified.stl" />
      </geometry>
      <material name="stator_x4_p36_36_unified_3_material">
        <color rgba="0.764706 0.545098 0.803922 1" />
      </material>
    </visual>
    <collision>
      <origin xyz="-0.038 0 -0.0565" rpy="1.5708 0 1.57079" />
      <geometry>
        <mesh filename="package://assets/stator_x4_p36_36_unified.stl" />
      </geometry>
    </collision>
  </link>
  <link name="urdf_l_wrist_assembly">
    <inertial>
      <origin xyz="-0.0282716 1.08315e-06 -0.112614" rpy="0 0 0" />
      <mass value="0.398" />
      <inertia ixx="0.00146537" ixy="-7.037e-09" ixz="-5.58167e-05" iyy="0.00160501" iyz="-2.3164e-08" izz="0.000274862" />
    </inertial>
    <visual>
      <origin xyz="-0.0219314 4.31502e-06 -0.0434653" rpy="0 0 -1.5708" />
      <geometry>
        <mesh filename="package://assets/l_wrist.stl" />
      </geometry>
      <material name="l_wrist_material">
        <color rgba="0.8 0.74902 0.913725 1" />
      </material>
    </visual>
    <collision>
      <origin xyz="-0.0219314 4.31502e-06 -0.0434653" rpy="0 0 -1.5708" />
      <geometry>
        <mesh filename="package://assets/l_wrist.stl" />
      </geometry>
    </collision>
    <visual>
      <origin xyz="-0.0303429 2.67e-09 -0.135203" rpy="0 0 0" />
      <geometry>
        <mesh filename="package://assets/l_hand.stl" />
      </geometry>
      <material name="l_hand_material">
        <color rgba="1 1 1 1" />
      </material>
    </visual>
    <collision>
      <origin xyz="-0.0303429 2.67e-09 -0.135203" rpy="0 0 0" />
      <geometry>
        <mesh filename="package://assets/l_hand.stl" />
      </geometry>
    </collision>
  </link>
  <joint name="left_wrist_roll_joint_X4" type="revolute">
    <origin xyz="0.033 0 -0.0565" rpy="0 0 0" />
    <parent link="urdf_l_lower_forearm_assembly" />
    <child link="urdf_l_wrist_assembly" />
    <axis xyz="1 0 0" />
    <limit effort="10" velocity="10" lower="-1.5708" upper="1.5708" />
  </joint>
  <joint name="left_wrist_yaw_joint_X4" type="revolute">
    <origin xyz="6.17098e-07 -0.04 -0.168" rpy="0 0 0" />
    <parent link="urdf_l_upper_forearm_assembly" />
    <child link="urdf_l_lower_forearm_assembly" />
    <axis xyz="0 0 1" />
    <limit effort="10" velocity="10" lower="-2.35619" upper="2.35619" />
  </joint>
  <joint name="left_elbow_pitch_joint_X6" type="revolute">
    <origin xyz="0 0.04 -0.065" rpy="0 0 0" />
    <parent link="urdf_l_elbow_assembly" />
    <child link="urdf_l_upper_forearm_assembly" />
    <axis xyz="0 1 0" />
    <limit effort="10" velocity="10" lower="-1.5708" upper="1.5708" />
  </joint>
  <joint name="left_shoulder_yaw_joint_X4" type="revolute">
    <origin xyz="-0.046 -6.24445e-07 -0.17" rpy="0 0 0" />
    <parent link="urdf_l_upper_arm_assembly" />
    <child link="urdf_l_elbow_assembly" />
    <axis xyz="0 0 1" />
    <limit effort="10" velocity="10" lower="-2.35619" upper="2.35619" />
  </joint>
  <joint name="left_shoulder_roll_joint_X6" type="revolute">
    <origin xyz="0.036 0.07 -9.55292e-08" rpy="0 0 0" />
    <parent link="urdf_l_shoulder_assembly" />
    <child link="urdf_l_upper_arm_assembly" />
    <axis xyz="1 0 0" />
    <limit effort="10" velocity="10" lower="0" upper="3.14159" />
  </joint>
  <joint name="left_shoulder_pitch_joint_X6" type="revolute">
    <origin xyz="4.00839e-06 0.169498 0.427" rpy="0 0 0" />
    <parent link="urdf_simplified_torso_sub_assembly" />
    <child link="urdf_l_shoulder_assembly" />
    <axis xyz="0 1 0" />
    <limit effort="10" velocity="10" lower="-3.14159" upper="1.5708" />
  </joint>
  <link name="urdf_r_shoulder_assembly">
    <inertial>
      <origin xyz="-0.00525946 -0.0685921 -9.06105e-06" rpy="0 0 0" />
      <mass value="2.84535" />
      <inertia ixx="0.00278215" ixy="1.19902e-05" ixz="-7.27684e-07" iyy="0.00243401" iyz="1.8265e-06" izz="0.00253762" />
    </inertial>
    <visual>
      <origin xyz="-0.0385 -0.07 1.02163e-07" rpy="-1.5708 0 -1.5708" />
      <geometry>
        <mesh filename="package://assets/stator_x6_p20_60_unified.stl" />
      </geometry>
      <material name="stator_x6_p20_60_unified_5_material">
        <color rgba="0.960784 0.835294 0.470588 1" />
      </material>
    </visual>
    <collision>
      <origin xyz="-0.0385 -0.07 1.02163e-07" rpy="-1.5708 0 -1.5708" />
      <geometry>
        <mesh filename="package://assets/stator_x6_p20_60_unified.stl" />
      </geometry>
    </collision>
    <visual>
      <origin xyz="-0.00129067 -0.0501448 -6.90836e-06" rpy="0 0 -1.5708" />
      <geometry>
        <mesh filename="package://assets/r_shoulder.stl" />
      </geometry>
      <material name="r_shoulder_material">
        <color rgba="0.615686 0.811765 0.929412 1" />
      </material>
    </visual>
    <collision>
      <origin xyz="-0.00129067 -0.0501448 -6.90836e-06" rpy="0 0 -1.5708" />
      <geometry>
        <mesh filename="package://assets/r_shoulder.stl" />
      </geometry>
    </collision>
  </link>
  <link name="urdf_r_upper_arm_assembly">
    <inertial>
      <origin xyz="-0.0297331 3.91738e-07 -0.104084" rpy="0 0 0" />
      <mass value="0.802" />
      <inertia ixx="0.00188605" ixy="2.8797e-09" ixz="-0.000468447" iyy="0.00204755" iyz="4.48483e-09" izz="0.0010158" />
    </inertial>
    <visual>
      <origin xyz="-0.041 3.34262e-07 -0.091" rpy="-3.14159 0 -1.5708" />
      <geometry>
        <mesh filename="package://assets/stator_x4_p36_36_unified.stl" />
      </geometry>
      <material name="stator_x4_p36_36_unified_4_material">
        <color rgba="0.764706 0.545098 0.803922 1" />
      </material>
    </visual>
    <collision>
      <origin xyz="-0.041 3.34262e-07 -0.091" rpy="-3.14159 0 -1.5708" />
      <geometry>
        <mesh filename="package://assets/stator_x4_p36_36_unified.stl" />
      </geometry>
    </collision>
    <visual>
      <origin xyz="-0.020543 3.79398e-07 -0.0905315" rpy="0 0 -1.5708" />
      <geometry>
        <mesh filename="package://assets/r_upper_arm.stl" />
      </geometry>
      <material name="r_upper_arm_material">
        <color rgba="0.231373 0.380392 0.705882 1" />
      </material>
    </visual>
    <collision>
      <origin xyz="-0.020543 3.79398e-07 -0.0905315" rpy="0 0 -1.5708" />
      <geometry>
        <mesh filename="package://assets/r_upper_arm.stl" />
      </geometry>
    </collision>
  </link>
  <link name="urdf_r_elbow_assembly">
    <inertial>
      <origin xyz="1.19265e-05 0.010381 -0.0635916" rpy="0 0 0" />
      <mass value="2.93435" />
      <inertia ixx="0.00279047" ixy="3.7473e-07" ixz="-2.33715e-06" iyy="0.00296574" iyz="6.85424e-05" izz="0.00250864" />
    </inertial>
    <visual>
      <origin xyz="1.16025e-05 -0.000331582 -0.0512953" rpy="0 0 -1.5708" />
      <geometry>
        <mesh filename="package://assets/r_elbow.stl" />
      </geometry>
      <material name="r_elbow_material">
        <color rgba="0.796078 0.905882 0.745098 1" />
      </material>
    </visual>
    <collision>
      <origin xyz="1.16025e-05 -0.000331582 -0.0512953" rpy="0 0 -1.5708" />
      <geometry>
        <mesh filename="package://assets/r_elbow.stl" />
      </geometry>
    </collision>
    <visual>
      <origin xyz="0 0.0445 -0.065" rpy="0 -1.57079 1.5708" />
      <geometry>
        <mesh filename="package://assets/stator_x6_p20_60_unified.stl" />
      </geometry>
      <material name="stator_x6_p20_60_unified_6_material">
        <color rgba="0.960784 0.835294 0.470588 1" />
      </material>
    </visual>
    <collision>
      <origin xyz="0 0.0445 -0.065" rpy="0 -1.57079 1.5708" />
      <geometry>
        <mesh filename="package://assets/stator_x6_p20_60_unified.stl" />
      </geometry>
    </collision>
  </link>
  <link name="urdf_r_upper_forearm_assembly">
    <inertial>
      <origin xyz="0.00228027 0.0327896 -0.101792" rpy="0 0 0" />
      <mass value="0.707" />
      <inertia ixx="0.00166903" ixy="-1.15859e-05" ixz="1.53763e-05" iyy="0.0014499" iyz="0.000352466" izz="0.000703651" />
    </inertial>
    <visual>
      <origin xyz="-3.30588e-07 0.04 -0.09" rpy="3.14159 0 -1.5708" />
      <geometry>
        <mesh filename="package://assets/stator_x4_p36_36_unified.stl" />
      </geometry>
      <material name="stator_x4_p36_36_unified_5_material">
        <color rgba="0.764706 0.545098 0.803922 1" />
      </material>
    </visual>
    <collision>
      <origin xyz="-3.30588e-07 0.04 -0.09" rpy="3.14159 0 -1.5708" />
      <geometry>
        <mesh filename="package://assets/stator_x4_p36_36_unified.stl" />
      </geometry>
    </collision>
    <visual>
      <origin xyz="0.00466955 0.0254856 -0.0842107" rpy="0 0 -1.5708" />
      <geometry>
        <mesh filename="package://assets/r_upper_forearm.stl" />
      </geometry>
      <material name="r_upper_forearm_material">
        <color rgba="0.890196 0.698039 0.639216 1" />
      </material>
    </visual>
    <collision>
      <origin xyz="0.00466955 0.0254856 -0.0842107" rpy="0 0 -1.5708" />
      <geometry>
        <mesh filename="package://assets/r_upper_forearm.stl" />
      </geometry>
    </collision>
  </link>
  <link name="urdf_r_lower_forearm_assembly">
    <inertial>
      <origin xyz="-0.00399848 2.4334e-08 -0.046852" rpy="0 0 0" />
      <mass value="0.618" />
      <inertia ixx="0.000617307" ixy="-1.76e-10" ixz="-3.83228e-05" iyy="0.000618602" iyz="5.34e-10" izz="0.000437775" />
    </inertial>
    <visual>
      <origin xyz="0.00205797 -4.2712e-08 -0.0333447" rpy="0 0 -1.5708" />
      <geometry>
        <mesh filename="package://assets/r_lower_forearm.stl" />
      </geometry>
      <material name="r_lower_forearm_material">
        <color rgba="0.941176 0.87451 0.678431 1" />
      </material>
    </visual>
    <collision>
      <origin xyz="0.00205797 -4.2712e-08 -0.0333447" rpy="0 0 -1.5708" />
      <geometry>
        <mesh filename="package://assets/r_lower_forearm.stl" />
      </geometry>
    </collision>
    <visual>
      <origin xyz="-0.038 0 -0.0565" rpy="1.5708 0 1.57079" />
      <geometry>
        <mesh filename="package://assets/stator_x4_p36_36_unified.stl" />
      </geometry>
      <material name="stator_x4_p36_36_unified_6_material">
        <color rgba="0.764706 0.545098 0.803922 1" />
      </material>
    </visual>
    <collision>
      <origin xyz="-0.038 0 -0.0565" rpy="1.5708 0 1.57079" />
      <geometry>
        <mesh filename="package://assets/stator_x4_p36_36_unified.stl" />
      </geometry>
    </collision>
  </link>
  <link name="urdf_r_wrist_assembly">
    <inertial>
      <origin xyz="-0.0275327 -1.54616e-06 -0.104482" rpy="0 0 0" />
      <mass value="0.45" />
      <inertia ixx="0.0017356" ixy="1.0208e-08" ixz="-9.3721e-05" iyy="0.001889" iyz="3.2626e-08" izz="0.000327099" />
    </inertial>
    <visual>
      <origin xyz="-0.0303429 -2.67e-09 -0.135003" rpy="0 0 3.14159" />
      <geometry>
        <mesh filename="package://assets/r_hand.stl" />
      </geometry>
      <material name="r_hand_material">
        <color rgba="1 1 1 1" />
      </material>
    </visual>
    <collision>
      <origin xyz="-0.0303429 -2.67e-09 -0.135003" rpy="0 0 3.14159" />
      <geometry>
        <mesh filename="package://assets/r_hand.stl" />
      </geometry>
    </collision>
    <visual>
      <origin xyz="-0.0219316 -4.44584e-06 -0.0434653" rpy="0 0 -1.5708" />
      <geometry>
        <mesh filename="package://assets/r_wrist.stl" />
      </geometry>
      <material name="r_wrist_material">
        <color rgba="0.8 0.74902 0.913725 1" />
      </material>
    </visual>
    <collision>
      <origin xyz="-0.0219316 -4.44584e-06 -0.0434653" rpy="0 0 -1.5708" />
      <geometry>
        <mesh filename="package://assets/r_wrist.stl" />
      </geometry>
    </collision>
  </link>
  <joint name="right_wrist_roll_joint_X4" type="revolute">
    <origin xyz="0.033 0 -0.0565" rpy="0 0 0" />
    <parent link="urdf_r_lower_forearm_assembly" />
    <child link="urdf_r_wrist_assembly" />
    <axis xyz="1 0 0" />
    <limit effort="10" velocity="10" lower="-1.5708" upper="1.5708" />
  </joint>
  <joint name="right_wrist_yaw_joint_X4" type="revolute">
    <origin xyz="-6.17098e-07 0.04 -0.168" rpy="0 0 0" />
    <parent link="urdf_r_upper_forearm_assembly" />
    <child link="urdf_r_lower_forearm_assembly" />
    <axis xyz="0 0 1" />
    <limit effort="10" velocity="10" lower="-2.35619" upper="2.35619" />
  </joint>
  <joint name="right_elbow_pitch_joint_X6" type="revolute">
    <origin xyz="0 -0.04 -0.065" rpy="0 0 0" />
    <parent link="urdf_r_elbow_assembly" />
    <child link="urdf_r_upper_forearm_assembly" />
    <axis xyz="0 1 0" />
    <limit effort="10" velocity="10" lower="-1.5708" upper="1.5708" />
  </joint>
  <joint name="right_shoulder_yaw_joint_X4" type="revolute">
    <origin xyz="-0.041 6.24445e-07 -0.17" rpy="0 0 0" />
    <parent link="urdf_r_upper_arm_assembly" />
    <child link="urdf_r_elbow_assembly" />
    <axis xyz="0 0 1" />
    <limit effort="10" velocity="10" lower="-2.35619" upper="2.35619" />
  </joint>
  <joint name="right_shoulder_roll_joint_X6" type="revolute">
    <origin xyz="0.041 -0.07 -1.08797e-07" rpy="0 0 0" />
    <parent link="urdf_r_shoulder_assembly" />
    <child link="urdf_r_upper_arm_assembly" />
    <axis xyz="1 0 0" />
    <limit effort="10" velocity="10" lower="-3.14159" upper="-0" />
  </joint>
  <joint name="right_shoulder_pitch_joint_X6" type="revolute">
    <origin xyz="4.00839e-06 -0.181502 0.427" rpy="0 0 0" />
    <parent link="urdf_simplified_torso_sub_assembly" />
    <child link="urdf_r_shoulder_assembly" />
    <axis xyz="0 1 0" />
    <limit effort="10" velocity="10" lower="-3.14159" upper="1.5708" />
  </joint>
  <joint name="waist_yaw_joint" type="revolute">
    <origin xyz="0.0333787 -0.000698852 -0.300748" rpy="0 0 0" />
    <parent link="urdf_base" />
    <child link="urdf_simplified_torso_sub_assembly" />
    <axis xyz="0 0 1" />
    <limit effort="10" velocity="10" lower="-1.5708" upper="1.5708" />
  </joint>
  <link name="urdf_hip_assembly">
    <inertial>
      <origin xyz="-0.00420762 0.0689982 -6.23945e-06" rpy="0 0 0" />
      <mass value="1.73" />
      <inertia ixx="0.00302301" ixy="2.30858e-05" ixz="4.5747e-08" iyy="0.00228746" iyz="-8.49179e-07" izz="0.00263533" />
    </inertial>
    <visual>
      <origin xyz="0.00253653 0.0520203 -3.27638e-05" rpy="0 0 -1.5708" />
      <geometry>
        <mesh filename="package://assets/hip.stl" />
      </geometry>
      <material name="hip_material">
        <color rgba="0.0627451 0.266667 0.490196 1" />
      </material>
    </visual>
    <collision>
      <origin xyz="0.00253653 0.0520203 -3.27638e-05" rpy="0 0 -1.5708" />
      <geometry>
        <mesh filename="package://assets/hip.stl" />
      </geometry>
    </collision>
    <visual>
      <origin xyz="-0.043 0.073 0" rpy="1.5708 0 1.5708" />
      <geometry>
        <mesh filename="package://assets/stator_x8_p20_120_unified.stl" />
      </geometry>
      <material name="stator_x8_p20_120_unified_4_material">
        <color rgba="0.882353 0.572549 0.478431 1" />
      </material>
    </visual>
    <collision>
      <origin xyz="-0.043 0.073 0" rpy="1.5708 0 1.5708" />
      <geometry>
        <mesh filename="package://assets/stator_x8_p20_120_unified.stl" />
      </geometry>
    </collision>
  </link>
  <link name="urdf_l_upper_femur_assembly">
    <inertial>
      <origin xyz="-0.0457109 0.000406567 -0.148741" rpy="0 0 0" />
      <mass value="1.912" />
      <inertia ixx="0.0051989" ixy="1.15719e-06" ixz="-0.000940749" iyy="0.0056213" iyz="-5.24664e-05" izz="0.00336495" />
    </inertial>
    <visual>
      <origin xyz="-0.0257799 0.00151663 -0.111785" rpy="0 0 -1.5708" />
      <geometry>
        <mesh filename="package://assets/l_upper_femur.stl" />
      </geometry>
      <material name="l_upper_femur_material">
        <color rgba="0.141176 0.694118 0.65098 1" />
      </material>
    </visual>
    <collision>
      <origin xyz="-0.0257799 0.00151663 -0.111785" rpy="0 0 -1.5708" />
      <geometry>
        <mesh filename="package://assets/l_upper_femur.stl" />
      </geometry>
    </collision>
    <visual>
      <origin xyz="-0.053 4.55477e-07 -0.124" rpy="3.14159 0 1.99137" />
      <geometry>
        <mesh filename="package://assets/rotor_x8_p20_120.stl" />
      </geometry>
      <material name="rotor_x8_p20_120_material">
        <color rgba="0.596078 0.176471 0.0509804 1" />
      </material>
    </visual>
    <collision>
      <origin xyz="-0.053 4.55477e-07 -0.124" rpy="3.14159 0 1.99137" />
      <geometry>
        <mesh filename="package://assets/rotor_x8_p20_120.stl" />
      </geometry>
    </collision>
    <visual>
      <origin xyz="-0.053 4.55477e-07 -0.124" rpy="-3.14159 0 -1.5708" />
      <geometry>
        <mesh filename="package://assets/stator_x8_p20_120.stl" />
      </geometry>
      <material name="stator_x8_p20_120_material">
        <color rgba="0.882353 0.572549 0.478431 1" />
      </material>
    </visual>
    <collision>
      <origin xyz="-0.053 4.55477e-07 -0.124" rpy="-3.14159 0 -1.5708" />
      <geometry>
        <mesh filename="package://assets/stator_x8_p20_120.stl" />
      </geometry>
    </collision>
  </link>
  <link name="urdf_lower_femur_assembly">
    <inertial>
      <origin xyz="-1.0389e-08 -0.00357383 -0.103307" rpy="0 0 0" />
      <mass value="1.817" />
      <inertia ixx="0.00383469" ixy="-2.5e-11" ixz="-2.1291e-08" iyy="0.00421827" iyz="-0.00019709" izz="0.00258541" />
    </inertial>
    <visual>
      <origin xyz="5.752e-09 0.00389134 -0.070766" rpy="0 0 -1.5708" />
      <geometry>
        <mesh filename="package://assets/lower_femur.stl" />
      </geometry>
      <material name="lower_femur_material">
        <color rgba="0.380392 0.0470588 0.435294 1" />
      </material>
    </visual>
    <collision>
      <origin xyz="5.752e-09 0.00389134 -0.070766" rpy="0 0 -1.5708" />
      <geometry>
        <mesh filename="package://assets/lower_femur.stl" />
      </geometry>
    </collision>
    <visual>
      <origin xyz="0 -0.043 -0.113" rpy="-3.14159 -1.57079 1.5708" />
      <geometry>
        <mesh filename="package://assets/stator_x8_p20_120_unified.stl" />
      </geometry>
      <material name="stator_x8_p20_120_unified_5_material">
        <color rgba="0.882353 0.572549 0.478431 1" />
      </material>
    </visual>
    <collision>
      <origin xyz="0 -0.043 -0.113" rpy="-3.14159 -1.57079 1.5708" />
      <geometry>
        <mesh filename="package://assets/stator_x8_p20_120_unified.stl" />
      </geometry>
    </collision>
  </link>
  <link name="urdf_l_tibia_assembly">
    <inertial>
      <origin xyz="0.015131 -0.0519322 -0.253045" rpy="0 0 0" />
      <mass value="4.89318" />
      <inertia ixx="0.070962" ixy="0.000216167" ixz="0.00320045" iyy="0.0742001" iyz="-0.00255494" izz="0.00924192" />
    </inertial>
    <visual>
      <origin xyz="0.0808489 -0.0729994 -0.287625" rpy="0.0610936 0.0269221 0.191443" />
      <geometry>
        <mesh filename="package://assets/m6_threaded_bar_300mm.stl" />
      </geometry>
      <material name="m6_threaded_bar_300mm_material">
        <color rgba="0.141176 0.0352941 0.396078 1" />
      </material>
    </visual>
    <collision>
      <origin xyz="0.0808489 -0.0729994 -0.287625" rpy="0.0610936 0.0269221 0.191443" />
      <geometry>
        <mesh filename="package://assets/m6_threaded_bar_300mm.stl" />
      </geometry>
    </collision>
    <visual>
      <origin xyz="0.0808488 -0.0360012 -0.325171" rpy="0.0566165 -0.0643278 -2.97336" />
      <geometry>
        <mesh filename="package://assets/m6_threaded_bar_225mm.stl" />
      </geometry>
      <material name="m6_threaded_bar_225mm_material">
        <color rgba="0.27451 0.0117647 0.317647 1" />
      </material>
    </visual>
    <collision>
      <origin xyz="0.0808488 -0.0360012 -0.325171" rpy="0.0566165 -0.0643278 -2.97336" />
      <geometry>
        <mesh filename="package://assets/m6_threaded_bar_225mm.stl" />
      </geometry>
    </collision>
    <visual>
      <origin xyz="0.0303226 -0.054 -0.449431" rpy="0 0 -1.5708" />
      <geometry>
        <mesh filename="package://assets/shoe.stl" />
      </geometry>
      <material name="shoe_material">
        <color rgba="0.0862745 0.321569 0.580392 1" />
      </material>
    </visual>
    <collision>
      <origin xyz="0.0303226 -0.054 -0.449431" rpy="0 0 -1.5708" />
      <geometry>
        <mesh filename="package://assets/shoe.stl" />
      </geometry>
    </collision>
    <visual>
      <origin xyz="0.0564984 -0.054 -0.424448" rpy="0 0 -1.5708" />
      <geometry>
        <mesh filename="package://assets/lower_fixation_leg_lontrol.stl" />
      </geometry>
      <material name="lower_fixation_leg_lontrol_material">
        <color rgba="0.615686 0.811765 0.929412 1" />
      </material>
    </visual>
    <collision>
      <origin xyz="0.0564984 -0.054 -0.424448" rpy="0 0 -1.5708" />
      <geometry>
        <mesh filename="package://assets/lower_fixation_leg_lontrol.stl" />
      </geometry>
    </collision>
    <visual>
      <origin xyz="0.0301364 -0.054 -0.444982" rpy="0 0 -1.5708" />
      <geometry>
        <mesh filename="package://assets/foot.stl" />
      </geometry>
      <material name="foot_material">
        <color rgba="0.615686 0.811765 0.929412 1" />
      </material>
    </visual>
    <collision>
      <origin xyz="0.0301364 -0.054 -0.444982" rpy="0 0 -1.5708" />
      <geometry>
        <mesh filename="package://assets/foot.stl" />
      </geometry>
    </collision>
    <visual>
      <origin xyz="-1.37929e-06 -0.055 -0.3755" rpy="0 0 -1.5708" />
      <geometry>
        <mesh filename="package://assets/spacer_bottom_tibia.stl" />
      </geometry>
      <material name="spacer_bottom_tibia_material">
        <color rgba="0.615686 0.811765 0.929412 1" />
      </material>
    </visual>
    <collision>
      <origin xyz="-1.37929e-06 -0.055 -0.3755" rpy="0 0 -1.5708" />
      <geometry>
        <mesh filename="package://assets/spacer_bottom_tibia.stl" />
      </geometry>
    </collision>
    <visual>
      <origin xyz="0.000690997 -0.0429128 -0.182574" rpy="0 0 -1.5708" />
      <geometry>
        <mesh filename="package://assets/l_tibia.stl" />
      </geometry>
      <material name="l_tibia_material">
        <color rgba="0.513725 0.415686 0.733333 1" />
      </material>
    </visual>
    <collision>
      <origin xyz="0.000690997 -0.0429128 -0.182574" rpy="0 0 -1.5708" />
      <geometry>
        <mesh filename="package://assets/l_tibia.stl" />
      </geometry>
    </collision>
    <visual>
      <origin xyz="0.0759985 -0.042 -0.415" rpy="-1.5708 0 -1.5708" />
      <geometry>
        <mesh filename="package://assets/m6_threaded_eye.stl" />
      </geometry>
      <material name="m6_threaded_eye_material">
        <color rgba="0.615686 0.811765 0.929412 1" />
      </material>
    </visual>
    <collision>
      <origin xyz="0.0759985 -0.042 -0.415" rpy="-1.5708 0 -1.5708" />
      <geometry>
        <mesh filename="package://assets/m6_threaded_eye.stl" />
      </geometry>
    </collision>
    <visual>
      <origin xyz="0.0759985 -0.042 -0.415" rpy="-1.63522 -0.0565022 -1.39892" />
      <geometry>
        <mesh filename="package://assets/12_7mm_ball_with_6mm_hole.stl" />
      </geometry>
      <material name="12_7mm_ball_with_6mm_hole_material">
        <color rgba="0.647059 0.647059 0.647059 1" />
      </material>
    </visual>
    <collision>
      <origin xyz="0.0759985 -0.042 -0.415" rpy="-1.63522 -0.0565022 -1.39892" />
      <geometry>
        <mesh filename="package://assets/12_7mm_ball_with_6mm_hole.stl" />
      </geometry>
    </collision>
    <visual>
      <origin xyz="0.0164984 -0.054 -0.423" rpy="3.14159 0 -1.5708" />
      <geometry>
        <mesh filename="package://assets/rulment_d22_x_d8_x_t7.stl" />
      </geometry>
      <material name="rulment_d22_x_d8_x_t7_material">
        <color rgba="0.901961 0.901961 0.901961 1" />
      </material>
    </visual>
    <collision>
      <origin xyz="0.0164984 -0.054 -0.423" rpy="3.14159 0 -1.5708" />
      <geometry>
        <mesh filename="package://assets/rulment_d22_x_d8_x_t7.stl" />
      </geometry>
    </collision>
    <visual>
      <origin xyz="0.0191783 -0.054 -0.428357" rpy="0 0 -1.5708" />
      <geometry>
        <mesh filename="package://assets/ankle_bearing_house.stl" />
      </geometry>
      <material name="ankle_bearing_house_material">
        <color rgba="0.615686 0.811765 0.929412 1" />
      </material>
    </visual>
    <collision>
      <origin xyz="0.0191783 -0.054 -0.428357" rpy="0 0 -1.5708" />
      <geometry>
        <mesh filename="package://assets/ankle_bearing_house.stl" />
      </geometry>
    </collision>
    <visual>
      <origin xyz="0.0759985 -0.066 -0.415" rpy="-1.5708 0 -1.5708" />
      <geometry>
        <mesh filename="package://assets/m6_threaded_eye.stl" />
      </geometry>
      <material name="m6_threaded_eye_2_material">
        <color rgba="0.615686 0.811765 0.929412 1" />
      </material>
    </visual>
    <collision>
      <origin xyz="0.0759985 -0.066 -0.415" rpy="-1.5708 0 -1.5708" />
      <geometry>
        <mesh filename="package://assets/m6_threaded_eye.stl" />
      </geometry>
    </collision>
    <visual>
      <origin xyz="0.0759985 -0.066 -0.415" rpy="-1.50971 0.0269221 0.191443" />
      <geometry>
        <mesh filename="package://assets/12_7mm_ball_with_6mm_hole.stl" />
      </geometry>
      <material name="12_7mm_ball_with_6mm_hole_2_material">
        <color rgba="0.647059 0.647059 0.647059 1" />
      </material>
    </visual>
    <collision>
      <origin xyz="0.0759985 -0.066 -0.415" rpy="-1.50971 0.0269221 0.191443" />
      <geometry>
        <mesh filename="package://assets/12_7mm_ball_with_6mm_hole.stl" />
      </geometry>
    </collision>
    <visual>
      <origin xyz="-0.0165016 -0.054 -0.423" rpy="-3.14159 0 1.5708" />
      <geometry>
        <mesh filename="package://assets/rulment_d22_x_d8_x_t7.stl" />
      </geometry>
      <material name="rulment_d22_x_d8_x_t7_2_material">
        <color rgba="0.901961 0.901961 0.901961 1" />
      </material>
    </visual>
    <collision>
      <origin xyz="-0.0165016 -0.054 -0.423" rpy="-3.14159 0 1.5708" />
      <geometry>
        <mesh filename="package://assets/rulment_d22_x_d8_x_t7.stl" />
      </geometry>
    </collision>
    <visual>
      <origin xyz="-0.0191815 -0.054 -0.428357" rpy="0 0 1.5708" />
      <geometry>
        <mesh filename="package://assets/ankle_bearing_house.stl" />
      </geometry>
      <material name="ankle_bearing_house_2_material">
        <color rgba="0.615686 0.811765 0.929412 1" />
      </material>
    </visual>
    <collision>
      <origin xyz="-0.0191815 -0.054 -0.428357" rpy="0 0 1.5708" />
      <geometry>
        <mesh filename="package://assets/ankle_bearing_house.stl" />
      </geometry>
    </collision>
    <visual>
      <origin xyz="-1.45092e-06 -0.0445 -0.395" rpy="0 0 3.14159" />
      <geometry>
        <mesh filename="package://assets/rulment_d22_x_d8_x_t7.stl" />
      </geometry>
      <material name="rulment_d22_x_d8_x_t7_3_material">
        <color rgba="0.901961 0.901961 0.901961 1" />
      </material>
    </visual>
    <collision>
      <origin xyz="-1.45092e-06 -0.0445 -0.395" rpy="0 0 3.14159" />
      <geometry>
        <mesh filename="package://assets/rulment_d22_x_d8_x_t7.stl" />
      </geometry>
    </collision>
    <visual>
      <origin xyz="-1.43124e-06 -0.0418201 -0.389643" rpy="3.14159 0 3.14159" />
      <geometry>
        <mesh filename="package://assets/ankle_bearing_house.stl" />
      </geometry>
      <material name="ankle_bearing_house_3_material">
        <color rgba="0.615686 0.811765 0.929412 1" />
      </material>
    </visual>
    <collision>
      <origin xyz="-1.43124e-06 -0.0418201 -0.389643" rpy="3.14159 0 3.14159" />
      <geometry>
        <mesh filename="package://assets/ankle_bearing_house.stl" />
      </geometry>
    </collision>
    <visual>
      <origin xyz="-0.0180006 -0.055 -0.16" rpy="-1.5708 0 -1.5708" />
      <geometry>
        <mesh filename="package://assets/rotor_x4_p36_36.stl" />
      </geometry>
      <material name="rotor_x4_p36_36_material">
        <color rgba="0.380392 0.0470588 0.435294 1" />
      </material>
    </visual>
    <collision>
      <origin xyz="-0.0180006 -0.055 -0.16" rpy="-1.5708 0 -1.5708" />
      <geometry>
        <mesh filename="package://assets/rotor_x4_p36_36.stl" />
      </geometry>
    </collision>
    <visual>
      <origin xyz="-0.0180006 -0.055 -0.16" rpy="-1.5708 0 -1.5708" />
      <geometry>
        <mesh filename="package://assets/stator_x4_p36_36.stl" />
      </geometry>
      <material name="stator_x4_p36_36_material">
        <color rgba="0.764706 0.545098 0.803922 1" />
      </material>
    </visual>
    <collision>
      <origin xyz="-0.0180006 -0.055 -0.16" rpy="-1.5708 0 -1.5708" />
      <geometry>
        <mesh filename="package://assets/stator_x4_p36_36.stl" />
      </geometry>
    </collision>
    <visual>
      <origin xyz="-0.0180009 -0.055 -0.235" rpy="1.5708 0 1.5708" />
      <geometry>
        <mesh filename="package://assets/rotor_x4_p36_36.stl" />
      </geometry>
      <material name="rotor_x4_p36_36_2_material">
        <color rgba="0.380392 0.0470588 0.435294 1" />
      </material>
    </visual>
    <collision>
      <origin xyz="-0.0180009 -0.055 -0.235" rpy="1.5708 0 1.5708" />
      <geometry>
        <mesh filename="package://assets/rotor_x4_p36_36.stl" />
      </geometry>
    </collision>
    <visual>
      <origin xyz="-0.0180009 -0.055 -0.235" rpy="1.5708 0 1.5708" />
      <geometry>
        <mesh filename="package://assets/stator_x4_p36_36.stl" />
      </geometry>
      <material name="stator_x4_p36_36_2_material">
        <color rgba="0.764706 0.545098 0.803922 1" />
      </material>
    </visual>
    <collision>
      <origin xyz="-0.0180009 -0.055 -0.235" rpy="1.5708 0 1.5708" />
      <geometry>
        <mesh filename="package://assets/stator_x4_p36_36.stl" />
      </geometry>
    </collision>
    <visual>
      <origin xyz="-1.45092e-06 -0.0655 -0.395" rpy="0 0 0" />
      <geometry>
        <mesh filename="package://assets/rulment_d22_x_d8_x_t7.stl" />
      </geometry>
      <material name="rulment_d22_x_d8_x_t7_4_material">
        <color rgba="0.901961 0.901961 0.901961 1" />
      </material>
    </visual>
    <collision>
      <origin xyz="-1.45092e-06 -0.0655 -0.395" rpy="0 0 0" />
      <geometry>
        <mesh filename="package://assets/rulment_d22_x_d8_x_t7.stl" />
      </geometry>
    </collision>
    <visual>
      <origin xyz="-1.43124e-06 -0.0681799 -0.389643" rpy="-3.14159 0 0" />
      <geometry>
        <mesh filename="package://assets/ankle_bearing_house.stl" />
      </geometry>
      <material name="ankle_bearing_house_4_material">
        <color rgba="0.615686 0.811765 0.929412 1" />
      </material>
    </visual>
    <collision>
      <origin xyz="-1.43124e-06 -0.0681799 -0.389643" rpy="-3.14159 0 0" />
      <geometry>
        <mesh filename="package://assets/ankle_bearing_house.stl" />
      </geometry>
    </collision>
    <visual>
      <origin xyz="0.0659991 -0.0496487 -0.235073" rpy="3.14159 -0.0136963 -1.5708" />
      <geometry>
        <mesh filename="package://assets/lever_ankle.stl" />
      </geometry>
      <material name="lever_ankle_material">
        <color rgba="0.615686 0.811765 0.929412 1" />
      </material>
    </visual>
    <collision>
      <origin xyz="0.0659991 -0.0496487 -0.235073" rpy="3.14159 -0.0136963 -1.5708" />
      <geometry>
        <mesh filename="package://assets/lever_ankle.stl" />
      </geometry>
    </collision>
    <visual>
      <origin xyz="0.0700991 -0.0300023 -0.235342" rpy="-1.57079 -0.0136963 -1.5708" />
      <geometry>
        <mesh filename="package://assets/hex_nut_grade_a___b_m6x1__7468f1fe59412d2a2604ecf8e993c3bf.stl" />
      </geometry>
      <material name="hex_nut_grade_a___b_m6x1__7468f1fe59412d2a2604ecf8e993c3bf_material">
        <color rgba="0.603922 0.647059 0.686275 1" />
      </material>
    </visual>
    <collision>
      <origin xyz="0.0700991 -0.0300023 -0.235342" rpy="-1.57079 -0.0136963 -1.5708" />
      <geometry>
        <mesh filename="package://assets/hex_nut_grade_a___b_m6x1__7468f1fe59412d2a2604ecf8e993c3bf.stl" />
      </geometry>
    </collision>
    <visual>
      <origin xyz="0.0537491 -0.055 -0.235" rpy="3.14159 -0.0136963 -1.5708" />
      <geometry>
        <mesh filename="package://assets/spacer_lever_ankle.stl" />
      </geometry>
      <material name="spacer_lever_ankle_material">
        <color rgba="0.615686 0.811765 0.929412 1" />
      </material>
    </visual>
    <collision>
      <origin xyz="0.0537491 -0.055 -0.235" rpy="3.14159 -0.0136963 -1.5708" />
      <geometry>
        <mesh filename="package://assets/spacer_lever_ankle.stl" />
      </geometry>
    </collision>
    <visual>
      <origin xyz="0.0659994 -0.0603516 -0.160053" rpy="0 -0.00999633 1.5708" />
      <geometry>
        <mesh filename="package://assets/lever_ankle.stl" />
      </geometry>
      <material name="lever_ankle_2_material">
        <color rgba="0.615686 0.811765 0.929412 1" />
      </material>
    </visual>
    <collision>
      <origin xyz="0.0659994 -0.0603516 -0.160053" rpy="0 -0.00999633 1.5708" />
      <geometry>
        <mesh filename="package://assets/lever_ankle.stl" />
      </geometry>
    </collision>
    <visual>
      <origin xyz="0.0700994 -0.0799988 -0.16025" rpy="1.5708 -0.00999633 1.5708" />
      <geometry>
        <mesh filename="package://assets/hex_nut_grade_a___b_m6x1__7468f1fe59412d2a2604ecf8e993c3bf.stl" />
      </geometry>
      <material name="hex_nut_grade_a___b_m6x1__7468f1fe59412d2a2604ecf8e993c3bf_2_material">
        <color rgba="0.603922 0.647059 0.686275 1" />
      </material>
    </visual>
    <collision>
      <origin xyz="0.0700994 -0.0799988 -0.16025" rpy="1.5708 -0.00999633 1.5708" />
      <geometry>
        <mesh filename="package://assets/hex_nut_grade_a___b_m6x1__7468f1fe59412d2a2604ecf8e993c3bf.stl" />
      </geometry>
    </collision>
    <visual>
      <origin xyz="0.0537494 -0.055 -0.16" rpy="0 -0.00999633 1.5708" />
      <geometry>
        <mesh filename="package://assets/spacer_lever_ankle.stl" />
      </geometry>
      <material name="spacer_lever_ankle_2_material">
        <color rgba="0.615686 0.811765 0.929412 1" />
      </material>
    </visual>
    <collision>
      <origin xyz="0.0537494 -0.055 -0.16" rpy="0 -0.00999633 1.5708" />
      <geometry>
        <mesh filename="package://assets/spacer_lever_ankle.stl" />
      </geometry>
    </collision>
    <visual>
      <origin xyz="0.0856991 -0.0300023 -0.235342" rpy="-1.57079 -0.0136963 -1.5708" />
      <geometry>
        <mesh filename="package://assets/m6_threaded_eye.stl" />
      </geometry>
      <material name="m6_threaded_eye_3_material">
        <color rgba="0.615686 0.811765 0.929412 1" />
      </material>
    </visual>
    <collision>
      <origin xyz="0.0856991 -0.0300023 -0.235342" rpy="-1.57079 -0.0136963 -1.5708" />
      <geometry>
        <mesh filename="package://assets/m6_threaded_eye.stl" />
      </geometry>
    </collision>
    <visual>
      <origin xyz="0.0856991 -0.0300023 -0.235342" rpy="-1.51418 -0.0643278 -2.97336" />
      <geometry>
        <mesh filename="package://assets/12_7mm_ball_with_6mm_hole.stl" />
      </geometry>
      <material name="12_7mm_ball_with_6mm_hole_3_material">
        <color rgba="0.647059 0.647059 0.647059 1" />
      </material>
    </visual>
    <collision>
      <origin xyz="0.0856991 -0.0300023 -0.235342" rpy="-1.51418 -0.0643278 -2.97336" />
      <geometry>
        <mesh filename="package://assets/12_7mm_ball_with_6mm_hole.stl" />
      </geometry>
    </collision>
    <visual>
      <origin xyz="0.0856994 -0.0799988 -0.16025" rpy="1.5708 -0.00999633 1.5708" />
      <geometry>
        <mesh filename="package://assets/m6_threaded_eye.stl" />
      </geometry>
      <material name="m6_threaded_eye_4_material">
        <color rgba="0.615686 0.811765 0.929412 1" />
      </material>
    </visual>
    <collision>
      <origin xyz="0.0856994 -0.0799988 -0.16025" rpy="1.5708 -0.00999633 1.5708" />
      <geometry>
        <mesh filename="package://assets/m6_threaded_eye.stl" />
      </geometry>
    </collision>
    <visual>
      <origin xyz="0.0856994 -0.0799988 -0.16025" rpy="1.50971 -0.0269255 -2.95015" />
      <geometry>
        <mesh filename="package://assets/12_7mm_ball_with_6mm_hole.stl" />
      </geometry>
      <material name="12_7mm_ball_with_6mm_hole_4_material">
        <color rgba="0.647059 0.647059 0.647059 1" />
      </material>
    </visual>
    <collision>
      <origin xyz="0.0856994 -0.0799988 -0.16025" rpy="1.50971 -0.0269255 -2.95015" />
      <geometry>
        <mesh filename="package://assets/12_7mm_ball_with_6mm_hole.stl" />
      </geometry>
    </collision>
  </link>
  <link name="ankle_assembly">
    <inertial>
      <origin xyz="-4.60793e-08 -0.024 -0.0125447" rpy="0 0 0" />
      <mass value="0.0816337" />
      <inertia ixx="1.68911e-05" ixy="-3.1834e-27" ixz="-1.62341e-11" iyy="2.14344e-05" iyz="6.07251e-27" izz="1.24715e-05" />
    </inertial>
    <visual>
      <origin xyz="0 -0.024 0" rpy="0 0 -1.5708" />
      <geometry>
        <mesh filename="package://assets/upper_ankle_shaft.stl" />
      </geometry>
      <material name="upper_ankle_shaft_material">
        <color rgba="0.615686 0.811765 0.929412 1" />
      </material>
    </visual>
    <collision>
      <origin xyz="0 -0.024 0" rpy="0 0 -1.5708" />
      <geometry>
        <mesh filename="package://assets/upper_ankle_shaft.stl" />
      </geometry>
    </collision>
    <visual>
      <origin xyz="-3.36917e-08 -0.024 -0.00917229" rpy="0 0 -1.5708" />
      <geometry>
        <mesh filename="package://assets/ankle_ear.stl" />
      </geometry>
      <material name="ankle_ear_material">
        <color rgba="0.615686 0.811765 0.929412 1" />
      </material>
    </visual>
    <collision>
      <origin xyz="-3.36917e-08 -0.024 -0.00917229" rpy="0 0 -1.5708" />
      <geometry>
        <mesh filename="package://assets/ankle_ear.stl" />
      </geometry>
    </collision>
    <visual>
      <origin xyz="-1.0285e-07 -0.024 -0.028" rpy="0 0 -1.5708" />
      <geometry>
        <mesh filename="package://assets/ankle_shaft.stl" />
      </geometry>
      <material name="ankle_shaft_material">
        <color rgba="0.615686 0.811765 0.929412 1" />
      </material>
    </visual>
    <collision>
      <origin xyz="-1.0285e-07 -0.024 -0.028" rpy="0 0 -1.5708" />
      <geometry>
        <mesh filename="package://assets/ankle_shaft.stl" />
      </geometry>
    </collision>
  </link>
  <joint name="left_ankle_pitch_joint" type="revolute">
    <origin xyz="-1.45092e-06 -0.03 -0.395" rpy="0 0 0" />
    <parent link="urdf_l_tibia_assembly" />
    <child link="ankle_assembly" />
    <axis xyz="0 1 0" />
    <limit effort="10" velocity="10" lower="-0.785398" upper="0.785398" />
  </joint>
  <link name="ankle_assembly_2">
    <inertial>
      <origin xyz="-4.60795e-08 -0.024 -0.0125448" rpy="0 0 0" />
      <mass value="0.0816337" />
      <inertia ixx="1.68911e-05" ixy="8.7363e-17" ixz="-1.62341e-11" iyy="2.14344e-05" iyz="2.37839e-11" izz="1.24715e-05" />
    </inertial>
    <visual>
      <origin xyz="0 -0.024 -6.36862e-08" rpy="0 0 -1.5708" />
      <geometry>
        <mesh filename="package://assets/upper_ankle_shaft.stl" />
      </geometry>
      <material name="upper_ankle_shaft_2_material">
        <color rgba="0.615686 0.811765 0.929412 1" />
      </material>
    </visual>
    <collision>
      <origin xyz="0 -0.024 -6.36862e-08" rpy="0 0 -1.5708" />
      <geometry>
        <mesh filename="package://assets/upper_ankle_shaft.stl" />
      </geometry>
    </collision>
    <visual>
      <origin xyz="-3.36919e-08 -0.024 -0.00917235" rpy="0 0 -1.5708" />
      <geometry>
        <mesh filename="package://assets/ankle_ear.stl" />
      </geometry>
      <material name="ankle_ear_2_material">
        <color rgba="0.615686 0.811765 0.929412 1" />
      </material>
    </visual>
    <collision>
      <origin xyz="-3.36919e-08 -0.024 -0.00917235" rpy="0 0 -1.5708" />
      <geometry>
        <mesh filename="package://assets/ankle_ear.stl" />
      </geometry>
    </collision>
    <visual>
      <origin xyz="-1.0285e-07 -0.0239999 -0.0280001" rpy="0 0 -1.5708" />
      <geometry>
        <mesh filename="package://assets/ankle_shaft.stl" />
      </geometry>
      <material name="ankle_shaft_2_material">
        <color rgba="0.615686 0.811765 0.929412 1" />
      </material>
    </visual>
    <collision>
      <origin xyz="-1.0285e-07 -0.0239999 -0.0280001" rpy="0 0 -1.5708" />
      <geometry>
        <mesh filename="package://assets/ankle_shaft.stl" />
      </geometry>
    </collision>
  </link>
  <joint name="left_ankle_pitch_joint_2" type="fixed">
    <origin xyz="-1.45092e-06 -0.03 -0.395" rpy="0 0 0" />
    <parent link="urdf_l_tibia_assembly" />
    <child link="ankle_assembly_2" />
  </joint>
  <joint name="left_knee_joint" type="revolute">
    <origin xyz="0 0.055 -0.113" rpy="0 0 0" />
    <parent link="urdf_lower_femur_assembly" />
    <child link="urdf_l_tibia_assembly" />
    <axis xyz="0 1 0" />
    <limit effort="10" velocity="10" lower="-1.5708" upper="-0" />
  </joint>
  <joint name="left_hip_yaw_joint" type="revolute">
    <origin xyz="-0.053 7.97086e-07 -0.217" rpy="0 0 0" />
    <parent link="urdf_l_upper_femur_assembly" />
    <child link="urdf_lower_femur_assembly" />
    <axis xyz="0 0 1" />
    <limit effort="10" velocity="10" lower="-1.5708" upper="1.5708" />
  </joint>
  <joint name="left_hip_roll_joint" type="revolute">
    <origin xyz="0.055 0.073 0" rpy="0 0 0" />
    <parent link="urdf_hip_assembly" />
    <child link="urdf_l_upper_femur_assembly" />
    <axis xyz="1 0 0" />
    <limit effort="10" velocity="10" lower="-0.349066" upper="3.14159" />
  </joint>
  <joint name="left_hip_pitch_joint" type="revolute">
    <origin xyz="0.0333787 0.111301 -0.467748" rpy="0 0 0" />
    <parent link="urdf_base" />
    <child link="urdf_hip_assembly" />
    <axis xyz="0 1 0" />
    <limit effort="10" velocity="10" lower="-2.53073" upper="1.5708" />
  </joint>
  <link name="urdf_hip_assembly_2">
    <inertial>
      <origin xyz="-0.00420719 -0.0739982 -6.05312e-05" rpy="0 0 0" />
      <mass value="1.73" />
      <inertia ixx="0.00302291" ixy="-2.30694e-05" ixz="6.10556e-06" iyy="0.00228746" iyz="-1.21542e-06" izz="0.00263542" />
    </inertial>
    <visual>
      <origin xyz="0.00253569 -0.0570203 7.30113e-05" rpy="3.12572 0 1.5708" />
      <geometry>
        <mesh filename="package://assets/hip.stl" />
      </geometry>
      <material name="hip_2_material">
        <color rgba="0.0627451 0.266667 0.490196 1" />
      </material>
    </visual>
    <collision>
      <origin xyz="0.00253569 -0.0570203 7.30113e-05" rpy="3.12572 0 1.5708" />
      <geometry>
        <mesh filename="package://assets/hip.stl" />
      </geometry>
    </collision>
    <visual>
      <origin xyz="-0.0429946 -0.078 -0.000682358" rpy="-1.55493 0 -1.5708" />
      <geometry>
        <mesh filename="package://assets/stator_x8_p20_120_unified.stl" />
      </geometry>
      <material name="stator_x8_p20_120_unified_6_material">
        <color rgba="0.882353 0.572549 0.478431 1" />
      </material>
    </visual>
    <collision>
      <origin xyz="-0.0429946 -0.078 -0.000682358" rpy="-1.55493 0 -1.5708" />
      <geometry>
        <mesh filename="package://assets/stator_x8_p20_120_unified.stl" />
      </geometry>
    </collision>
  </link>
  <link name="urdf_r_upper_femur_assemby">
    <inertial>
      <origin xyz="-0.0457092 -0.000635047 -0.147962" rpy="0 0 0" />
      <mass value="1.912" />
      <inertia ixx="0.00513139" ixy="-2.69178e-06" ixz="-0.000930576" iyy="0.00557438" iyz="4.84028e-05" izz="0.0033672" />
    </inertial>
    <visual>
      <origin xyz="-0.0257733 -0.00168828 -0.111759" rpy="0 -0.00155 -1.5708" />
      <geometry>
        <mesh filename="package://assets/r_upper_femur.stl" />
      </geometry>
      <material name="r_upper_femur_material">
        <color rgba="0.941176 0.87451 0.678431 1" />
      </material>
    </visual>
    <collision>
      <origin xyz="-0.0257733 -0.00168828 -0.111759" rpy="0 -0.00155 -1.5708" />
      <geometry>
        <mesh filename="package://assets/r_upper_femur.stl" />
      </geometry>
    </collision>
    <visual>
      <origin xyz="-0.053 -0.0001922 -0.124" rpy="-3.14159 -0.00155 -1.5708" />
      <geometry>
        <mesh filename="package://assets/stator_x8_p20_120_unified.stl" />
      </geometry>
      <material name="stator_x8_p20_120_unified_7_material">
        <color rgba="0.882353 0.572549 0.478431 1" />
      </material>
    </visual>
    <collision>
      <origin xyz="-0.053 -0.0001922 -0.124" rpy="-3.14159 -0.00155 -1.5708" />
      <geometry>
        <mesh filename="package://assets/stator_x8_p20_120_unified.stl" />
      </geometry>
    </collision>
  </link>
  <link name="urdf_lower_femur_assembly_2">
    <inertial>
      <origin xyz="-4.09789e-09 0.00357383 -0.103307" rpy="0 0 0" />
      <mass value="1.817" />
      <inertia ixx="0.00383469" ixy="-1.57905e-09" ixz="2.04921e-08" iyy="0.00421827" iyz="0.00019709" izz="0.00258541" />
    </inertial>
    <visual>
      <origin xyz="1.00211e-08 -0.00389134 -0.070766" rpy="0 0 1.5708" />
      <geometry>
        <mesh filename="package://assets/lower_femur.stl" />
      </geometry>
      <material name="lower_femur_2_material">
        <color rgba="0.380392 0.0470588 0.435294 1" />
      </material>
    </visual>
    <collision>
      <origin xyz="1.00211e-08 -0.00389134 -0.070766" rpy="0 0 1.5708" />
      <geometry>
        <mesh filename="package://assets/lower_femur.stl" />
      </geometry>
    </collision>
    <visual>
      <origin xyz="-1.74296e-07 0.043 -0.113" rpy="0 -1.57079 1.57078" />
      <geometry>
        <mesh filename="package://assets/stator_x8_p20_120_unified.stl" />
      </geometry>
      <material name="stator_x8_p20_120_unified_8_material">
        <color rgba="0.882353 0.572549 0.478431 1" />
      </material>
    </visual>
    <collision>
      <origin xyz="-1.74296e-07 0.043 -0.113" rpy="0 -1.57079 1.57078" />
      <geometry>
        <mesh filename="package://assets/stator_x8_p20_120_unified.stl" />
      </geometry>
    </collision>
  </link>
  <link name="urdf_r_tibia_assembly">
    <inertial>
      <origin xyz="0.0163357 0.0511723 -0.277209" rpy="0 0 0" />
      <mass value="3.4106" />
      <inertia ixx="0.0617379" ixy="-0.000264838" ixz="0.00268123" iyy="0.0648035" iyz="0.00321885" izz="0.00849991" />
    </inertial>
    <visual>
      <origin xyz="0.0803622 0.0370024 -0.325364" rpy="0.0787708 0.0539328 0.0197929" />
      <geometry>
        <mesh filename="package://assets/m6_threaded_bar_225mm.stl" />
      </geometry>
      <material name="m6_threaded_bar_225mm_2_material">
        <color rgba="0.27451 0.0117647 0.317647 1" />
      </material>
    </visual>
    <collision>
      <origin xyz="0.0803622 0.0370024 -0.325364" rpy="0.0787708 0.0539328 0.0197929" />
      <geometry>
        <mesh filename="package://assets/m6_threaded_bar_225mm.stl" />
      </geometry>
    </collision>
    <visual>
      <origin xyz="0.0804187 0.0739998 -0.287695" rpy="0.01746 0.0588936 1.16039" />
      <geometry>
        <mesh filename="package://assets/m6_threaded_bar_300mm.stl" />
      </geometry>
      <material name="m6_threaded_bar_300mm_2_material">
        <color rgba="0.141176 0.0352941 0.396078 1" />
      </material>
    </visual>
    <collision>
      <origin xyz="0.0804187 0.0739998 -0.287695" rpy="0.01746 0.0588936 1.16039" />
      <geometry>
        <mesh filename="package://assets/m6_threaded_bar_300mm.stl" />
      </geometry>
    </collision>
    <visual>
      <origin xyz="0.000417719 0.0429159 -0.182555" rpy="-0.00149587 0 -1.5708" />
      <geometry>
        <mesh filename="package://assets/r_tibia.stl" />
      </geometry>
      <material name="r_tibia_material">
        <color rgba="0.654902 0.823529 0.576471 1" />
      </material>
    </visual>
    <collision>
      <origin xyz="0.000417719 0.0429159 -0.182555" rpy="-0.00149587 0 -1.5708" />
      <geometry>
        <mesh filename="package://assets/r_tibia.stl" />
      </geometry>
    </collision>
    <visual>
      <origin xyz="-0.0182399 0.055 -0.159973" rpy="-1.5723 0 -1.5708" />
      <geometry>
        <mesh filename="package://assets/stator_x4_p36_36_unified.stl" />
      </geometry>
      <material name="stator_x4_p36_36_unified_7_material">
        <color rgba="0.764706 0.545098 0.803922 1" />
      </material>
    </visual>
    <collision>
      <origin xyz="-0.0182399 0.055 -0.159973" rpy="-1.5723 0 -1.5708" />
      <geometry>
        <mesh filename="package://assets/stator_x4_p36_36_unified.stl" />
      </geometry>
    </collision>
    <visual>
      <origin xyz="-0.000563079 0.055 -0.3755" rpy="-0.00149587 0 -1.5708" />
      <geometry>
        <mesh filename="package://assets/spacer_bottom_tibia.stl" />
      </geometry>
      <material name="spacer_bottom_tibia_2_material">
        <color rgba="0.615686 0.811765 0.929412 1" />
      </material>
    </visual>
    <collision>
      <origin xyz="-0.000563079 0.055 -0.3755" rpy="-0.00149587 0 -1.5708" />
      <geometry>
        <mesh filename="package://assets/spacer_bottom_tibia.stl" />
      </geometry>
    </collision>
    <visual>
      <origin xyz="-0.0183524 0.055 -0.234973" rpy="1.57229 0 1.5708" />
      <geometry>
        <mesh filename="package://assets/stator_x4_p36_36_unified.stl" />
      </geometry>
      <material name="stator_x4_p36_36_unified_8_material">
        <color rgba="0.764706 0.545098 0.803922 1" />
      </material>
    </visual>
    <collision>
      <origin xyz="-0.0183524 0.055 -0.234973" rpy="1.57229 0 1.5708" />
      <geometry>
        <mesh filename="package://assets/stator_x4_p36_36_unified.stl" />
      </geometry>
    </collision>
    <visual>
      <origin xyz="0.0296503 0.056 -0.449476" rpy="-0.00149587 0 -1.5708" />
      <geometry>
        <mesh filename="package://assets/shoe.stl" />
      </geometry>
      <material name="shoe_2_material">
        <color rgba="0.0862745 0.321569 0.580392 1" />
      </material>
    </visual>
    <collision>
      <origin xyz="0.0296503 0.056 -0.449476" rpy="-0.00149587 0 -1.5708" />
      <geometry>
        <mesh filename="package://assets/shoe.stl" />
      </geometry>
    </collision>
    <visual>
      <origin xyz="0.0558635 0.056 -0.424532" rpy="-0.00149587 0 -1.5708" />
      <geometry>
        <mesh filename="package://assets/lower_fixation_leg_lontrol.stl" />
      </geometry>
      <material name="lower_fixation_leg_lontrol_2_material">
        <color rgba="0.615686 0.811765 0.929412 1" />
      </material>
    </visual>
    <collision>
      <origin xyz="0.0558635 0.056 -0.424532" rpy="-0.00149587 0 -1.5708" />
      <geometry>
        <mesh filename="package://assets/lower_fixation_leg_lontrol.stl" />
      </geometry>
    </collision>
    <visual>
      <origin xyz="0.0294707 0.056 -0.445027" rpy="-0.00149587 0 -1.5708" />
      <geometry>
        <mesh filename="package://assets/foot.stl" />
      </geometry>
      <material name="foot_2_material">
        <color rgba="0.615686 0.811765 0.929412 1" />
      </material>
    </visual>
    <collision>
      <origin xyz="0.0294707 0.056 -0.445027" rpy="-0.00149587 0 -1.5708" />
      <geometry>
        <mesh filename="package://assets/foot.stl" />
      </geometry>
    </collision>
    <visual>
      <origin xyz="0.0656474 0.0496492 -0.235203" rpy="0.0014935 -0.0194763 1.57077" />
      <geometry>
        <mesh filename="package://assets/lever_ankle.stl" />
      </geometry>
      <material name="lever_ankle_3_material">
        <color rgba="0.615686 0.811765 0.929412 1" />
      </material>
    </visual>
    <collision>
      <origin xyz="0.0656474 0.0496492 -0.235203" rpy="0.0014935 -0.0194763 1.57077" />
      <geometry>
        <mesh filename="package://assets/lever_ankle.stl" />
      </geometry>
    </collision>
    <visual>
      <origin xyz="0.0697468 0.0300047 -0.235592" rpy="1.57229 -0.0194763 1.57077" />
      <geometry>
        <mesh filename="package://assets/hex_nut_grade_a___b_m6x1__7468f1fe59412d2a2604ecf8e993c3bf.stl" />
      </geometry>
      <material name="hex_nut_grade_a___b_m6x1__7468f1fe59412d2a2604ecf8e993c3bf_3_material">
        <color rgba="0.603922 0.647059 0.686275 1" />
      </material>
    </visual>
    <collision>
      <origin xyz="0.0697468 0.0300047 -0.235592" rpy="1.57229 -0.0194763 1.57077" />
      <geometry>
        <mesh filename="package://assets/hex_nut_grade_a___b_m6x1__7468f1fe59412d2a2604ecf8e993c3bf.stl" />
      </geometry>
    </collision>
    <visual>
      <origin xyz="0.0533975 0.055 -0.23508" rpy="0.0014935 -0.0194763 1.57077" />
      <geometry>
        <mesh filename="package://assets/spacer_lever_ankle.stl" />
      </geometry>
      <material name="spacer_lever_ankle_3_material">
        <color rgba="0.615686 0.811765 0.929412 1" />
      </material>
    </visual>
    <collision>
      <origin xyz="0.0533975 0.055 -0.23508" rpy="0.0014935 -0.0194763 1.57077" />
      <geometry>
        <mesh filename="package://assets/spacer_lever_ankle.stl" />
      </geometry>
    </collision>
    <visual>
      <origin xyz="-0.00059232 0.0655 -0.395" rpy="0 -0.00149689 -3.14159" />
      <geometry>
        <mesh filename="package://assets/rulment_d22_x_d8_x_t7.stl" />
      </geometry>
      <material name="rulment_d22_x_d8_x_t7_5_material">
        <color rgba="0.901961 0.901961 0.901961 1" />
      </material>
    </visual>
    <collision>
      <origin xyz="-0.00059232 0.0655 -0.395" rpy="0 -0.00149689 -3.14159" />
      <geometry>
        <mesh filename="package://assets/rulment_d22_x_d8_x_t7.stl" />
      </geometry>
    </collision>
    <visual>
      <origin xyz="-0.000584287 0.0681799 -0.389643" rpy="-3.14159 -0.0015022 -3.14159" />
      <geometry>
        <mesh filename="package://assets/ankle_bearing_house.stl" />
      </geometry>
      <material name="ankle_bearing_house_5_material">
        <color rgba="0.615686 0.811765 0.929412 1" />
      </material>
    </visual>
    <collision>
      <origin xyz="-0.000584287 0.0681799 -0.389643" rpy="-3.14159 -0.0015022 -3.14159" />
      <geometry>
        <mesh filename="package://assets/ankle_bearing_house.stl" />
      </geometry>
    </collision>
    <visual>
      <origin xyz="0.06576 0.0603518 -0.160131" rpy="3.14009 -0.00591632 -1.57079" />
      <geometry>
        <mesh filename="package://assets/lever_ankle.stl" />
      </geometry>
      <material name="lever_ankle_4_material">
        <color rgba="0.615686 0.811765 0.929412 1" />
      </material>
    </visual>
    <collision>
      <origin xyz="0.06576 0.0603518 -0.160131" rpy="3.14009 -0.00591632 -1.57079" />
      <geometry>
        <mesh filename="package://assets/lever_ankle.stl" />
      </geometry>
    </collision>
    <visual>
      <origin xyz="0.0698598 0.0799996 -0.160253" rpy="-1.5723 -0.00591632 -1.57079" />
      <geometry>
        <mesh filename="package://assets/hex_nut_grade_a___b_m6x1__7468f1fe59412d2a2604ecf8e993c3bf.stl" />
      </geometry>
      <material name="hex_nut_grade_a___b_m6x1__7468f1fe59412d2a2604ecf8e993c3bf_4_material">
        <color rgba="0.603922 0.647059 0.686275 1" />
      </material>
    </visual>
    <collision>
      <origin xyz="0.0698598 0.0799996 -0.160253" rpy="-1.5723 -0.00591632 -1.57079" />
      <geometry>
        <mesh filename="package://assets/hex_nut_grade_a___b_m6x1__7468f1fe59412d2a2604ecf8e993c3bf.stl" />
      </geometry>
    </collision>
    <visual>
      <origin xyz="0.05351 0.055 -0.16008" rpy="3.1401 -0.00591632 -1.57079" />
      <geometry>
        <mesh filename="package://assets/spacer_lever_ankle.stl" />
      </geometry>
      <material name="spacer_lever_ankle_4_material">
        <color rgba="0.615686 0.811765 0.929412 1" />
      </material>
    </visual>
    <collision>
      <origin xyz="0.05351 0.055 -0.16008" rpy="3.1401 -0.00591632 -1.57079" />
      <geometry>
        <mesh filename="package://assets/spacer_lever_ankle.stl" />
      </geometry>
    </collision>
    <visual>
      <origin xyz="-0.00059232 0.0445 -0.395" rpy="0 0.00149954 0" />
      <geometry>
        <mesh filename="package://assets/rulment_d22_x_d8_x_t7.stl" />
      </geometry>
      <material name="rulment_d22_x_d8_x_t7_6_material">
        <color rgba="0.901961 0.901961 0.901961 1" />
      </material>
    </visual>
    <collision>
      <origin xyz="-0.00059232 0.0445 -0.395" rpy="0 0.00149954 0" />
      <geometry>
        <mesh filename="package://assets/rulment_d22_x_d8_x_t7.stl" />
      </geometry>
    </collision>
    <visual>
      <origin xyz="-0.000584287 0.0418201 -0.389643" rpy="3.14159 0.00149954 0" />
      <geometry>
        <mesh filename="package://assets/ankle_bearing_house.stl" />
      </geometry>
      <material name="ankle_bearing_house_6_material">
        <color rgba="0.615686 0.811765 0.929412 1" />
      </material>
    </visual>
    <collision>
      <origin xyz="-0.000584287 0.0418201 -0.389643" rpy="3.14159 0.00149954 0" />
      <geometry>
        <mesh filename="package://assets/ankle_bearing_house.stl" />
      </geometry>
    </collision>
    <visual>
      <origin xyz="0.0753776 0.068 -0.415113" rpy="-1.5723 0 -1.5708" />
      <geometry>
        <mesh filename="package://assets/m6_threaded_eye.stl" />
      </geometry>
      <material name="m6_threaded_eye_5_material">
        <color rgba="0.615686 0.811765 0.929412 1" />
      </material>
    </visual>
    <collision>
      <origin xyz="0.0753776 0.068 -0.415113" rpy="-1.5723 0 -1.5708" />
      <geometry>
        <mesh filename="package://assets/m6_threaded_eye.stl" />
      </geometry>
    </collision>
    <visual>
      <origin xyz="0.0753776 0.068 -0.415113" rpy="-1.51189 -0.0174259 2.73015" />
      <geometry>
        <mesh filename="package://assets/12_7mm_ball_with_6mm_hole.stl" />
      </geometry>
      <material name="12_7mm_ball_with_6mm_hole_5_material">
        <color rgba="0.647059 0.647059 0.647059 1" />
      </material>
    </visual>
    <collision>
      <origin xyz="0.0753776 0.068 -0.415113" rpy="-1.51189 -0.0174259 2.73015" />
      <geometry>
        <mesh filename="package://assets/12_7mm_ball_with_6mm_hole.stl" />
      </geometry>
    </collision>
    <visual>
      <origin xyz="0.0158657 0.056 -0.423024" rpy="3.14009 0 -1.5708" />
      <geometry>
        <mesh filename="package://assets/rulment_d22_x_d8_x_t7.stl" />
      </geometry>
      <material name="rulment_d22_x_d8_x_t7_7_material">
        <color rgba="0.901961 0.901961 0.901961 1" />
      </material>
    </visual>
    <collision>
      <origin xyz="0.0158657 0.056 -0.423024" rpy="3.14009 0 -1.5708" />
      <geometry>
        <mesh filename="package://assets/rulment_d22_x_d8_x_t7.stl" />
      </geometry>
    </collision>
    <visual>
      <origin xyz="0.0185375 0.056 -0.428385" rpy="-0.00149587 0 -1.5708" />
      <geometry>
        <mesh filename="package://assets/ankle_bearing_house.stl" />
      </geometry>
      <material name="ankle_bearing_house_7_material">
        <color rgba="0.615686 0.811765 0.929412 1" />
      </material>
    </visual>
    <collision>
      <origin xyz="0.0185375 0.056 -0.428385" rpy="-0.00149587 0 -1.5708" />
      <geometry>
        <mesh filename="package://assets/ankle_bearing_house.stl" />
      </geometry>
    </collision>
    <visual>
      <origin xyz="0.0753776 0.044 -0.415113" rpy="-1.5723 0 -1.5708" />
      <geometry>
        <mesh filename="package://assets/m6_threaded_eye.stl" />
      </geometry>
      <material name="m6_threaded_eye_6_material">
        <color rgba="0.615686 0.811765 0.929412 1" />
      </material>
    </visual>
    <collision>
      <origin xyz="0.0753776 0.044 -0.415113" rpy="-1.5723 0 -1.5708" />
      <geometry>
        <mesh filename="package://assets/m6_threaded_eye.stl" />
      </geometry>
    </collision>
    <visual>
      <origin xyz="0.0753776 0.044 -0.415113" rpy="-1.5167 -0.0786595 1.58633" />
      <geometry>
        <mesh filename="package://assets/12_7mm_ball_with_6mm_hole.stl" />
      </geometry>
      <material name="12_7mm_ball_with_6mm_hole_6_material">
        <color rgba="0.647059 0.647059 0.647059 1" />
      </material>
    </visual>
    <collision>
      <origin xyz="0.0753776 0.044 -0.415113" rpy="-1.5167 -0.0786595 1.58633" />
      <geometry>
        <mesh filename="package://assets/12_7mm_ball_with_6mm_hole.stl" />
      </geometry>
    </collision>
    <visual>
      <origin xyz="-0.0171343 0.056 -0.422975" rpy="-3.1401 0 1.5708" />
      <geometry>
        <mesh filename="package://assets/rulment_d22_x_d8_x_t7.stl" />
      </geometry>
      <material name="rulment_d22_x_d8_x_t7_8_material">
        <color rgba="0.901961 0.901961 0.901961 1" />
      </material>
    </visual>
    <collision>
      <origin xyz="-0.0171343 0.056 -0.422975" rpy="-3.1401 0 1.5708" />
      <geometry>
        <mesh filename="package://assets/rulment_d22_x_d8_x_t7.stl" />
      </geometry>
    </collision>
    <visual>
      <origin xyz="-0.0198222 0.056 -0.428328" rpy="0.00150322 0 1.5708" />
      <geometry>
        <mesh filename="package://assets/ankle_bearing_house.stl" />
      </geometry>
      <material name="ankle_bearing_house_8_material">
        <color rgba="0.615686 0.811765 0.929412 1" />
      </material>
    </visual>
    <collision>
      <origin xyz="-0.0198222 0.056 -0.428328" rpy="0.00150322 0 1.5708" />
      <geometry>
        <mesh filename="package://assets/ankle_bearing_house.stl" />
      </geometry>
    </collision>
    <visual>
      <origin xyz="0.0853468 0.0300047 -0.235615" rpy="1.57229 -0.0194763 1.57077" />
      <geometry>
        <mesh filename="package://assets/m6_threaded_eye.stl" />
      </geometry>
      <material name="m6_threaded_eye_7_material">
        <color rgba="0.615686 0.811765 0.929412 1" />
      </material>
    </visual>
    <collision>
      <origin xyz="0.0853468 0.0300047 -0.235615" rpy="1.57229 -0.0194763 1.57077" />
      <geometry>
        <mesh filename="package://assets/m6_threaded_eye.stl" />
      </geometry>
    </collision>
    <visual>
      <origin xyz="0.0853468 0.0300047 -0.235615" rpy="1.62489 -0.0786595 1.58633" />
      <geometry>
        <mesh filename="package://assets/12_7mm_ball_with_6mm_hole.stl" />
      </geometry>
      <material name="12_7mm_ball_with_6mm_hole_7_material">
        <color rgba="0.647059 0.647059 0.647059 1" />
      </material>
    </visual>
    <collision>
      <origin xyz="0.0853468 0.0300047 -0.235615" rpy="1.62489 -0.0786595 1.58633" />
      <geometry>
        <mesh filename="package://assets/12_7mm_ball_with_6mm_hole.stl" />
      </geometry>
    </collision>
    <visual>
      <origin xyz="0.0854598 0.0799996 -0.160276" rpy="-1.5723 -0.00591632 -1.57079" />
      <geometry>
        <mesh filename="package://assets/m6_threaded_eye.stl" />
      </geometry>
      <material name="m6_threaded_eye_8_material">
        <color rgba="0.615686 0.811765 0.929412 1" />
      </material>
    </visual>
    <collision>
      <origin xyz="0.0854598 0.0799996 -0.160276" rpy="-1.5723 -0.00591632 -1.57079" />
      <geometry>
        <mesh filename="package://assets/m6_threaded_eye.stl" />
      </geometry>
    </collision>
    <visual>
      <origin xyz="0.0854598 0.0799996 -0.160276" rpy="-1.58825 -0.0588955 -1.98121" />
      <geometry>
        <mesh filename="package://assets/12_7mm_ball_with_6mm_hole.stl" />
      </geometry>
      <material name="12_7mm_ball_with_6mm_hole_8_material">
        <color rgba="0.647059 0.647059 0.647059 1" />
      </material>
    </visual>
    <collision>
      <origin xyz="0.0854598 0.0799996 -0.160276" rpy="-1.58825 -0.0588955 -1.98121" />
      <geometry>
        <mesh filename="package://assets/12_7mm_ball_with_6mm_hole.stl" />
      </geometry>
    </collision>
  </link>
  <link name="ankle_assembly_3">
    <inertial>
      <origin xyz="-0.025 2.40154e-05 0.0154553" rpy="0 0 0" />
      <mass value="0.0816337" />
      <inertia ixx="1.68911e-05" ixy="2.23442e-25" ixz="5.76744e-23" iyy="2.14344e-05" iyz="-1.39271e-08" izz="1.24715e-05" />
    </inertial>
    <visual>
      <origin xyz="-0.025 4.35081e-05 0.028" rpy="0 -0.00155386 -1.5708" />
      <geometry>
        <mesh filename="package://assets/upper_ankle_shaft.stl" />
      </geometry>
      <material name="upper_ankle_shaft_3_material">
        <color rgba="0.615686 0.811765 0.929412 1" />
      </material>
    </visual>
    <collision>
      <origin xyz="-0.025 4.35081e-05 0.028" rpy="0 -0.00155386 -1.5708" />
      <geometry>
        <mesh filename="package://assets/upper_ankle_shaft.stl" />
      </geometry>
    </collision>
    <visual>
      <origin xyz="-0.025 2.92556e-05 0.0188277" rpy="0 -0.00155386 -1.5708" />
      <geometry>
        <mesh filename="package://assets/ankle_ear.stl" />
      </geometry>
      <material name="ankle_ear_3_material">
        <color rgba="0.615686 0.811765 0.929412 1" />
      </material>
    </visual>
    <collision>
      <origin xyz="-0.025 2.92556e-05 0.0188277" rpy="0 -0.00155386 -1.5708" />
      <geometry>
        <mesh filename="package://assets/ankle_ear.stl" />
      </geometry>
    </collision>
    <visual>
      <origin xyz="-0.025 0 0" rpy="0 -0.00155386 -1.5708" />
      <geometry>
        <mesh filename="package://assets/ankle_shaft.stl" />
      </geometry>
      <material name="ankle_shaft_3_material">
        <color rgba="0.615686 0.811765 0.929412 1" />
      </material>
    </visual>
    <collision>
      <origin xyz="-0.025 0 0" rpy="0 -0.00155386 -1.5708" />
      <geometry>
        <mesh filename="package://assets/ankle_shaft.stl" />
      </geometry>
    </collision>
  </link>
  <joint name="right_ankle_pitch_joint" type="revolute">
    <origin xyz="0.0243657 0.056 -0.423037" rpy="0.00155386 0.00149689 0" />
    <parent link="urdf_r_tibia_assembly" />
    <child link="ankle_assembly_3" />
    <axis xyz="1 0 0" />
    <limit effort="10" velocity="10" lower="-0.785398" upper="0.785398" />
  </joint>
  <link name="ankle_assembly_4">
    <inertial>
      <origin xyz="-0.0249768 9.18303e-08 0.0154927" rpy="0 0 0" />
      <mass value="0.0816337" />
      <inertia ixx="1.68911e-05" ixy="1.66885e-11" ixz="-6.61565e-09" iyy="2.14344e-05" iyz="-2.50682e-14" izz="1.24715e-05" />
    </inertial>
    <visual>
      <origin xyz="-0.0249581 9.18304e-08 0.0280374" rpy="-0.00150056 0 -1.5708" />
      <geometry>
        <mesh filename="package://assets/upper_ankle_shaft.stl" />
      </geometry>
      <material name="upper_ankle_shaft_4_material">
        <color rgba="0.615686 0.811765 0.929412 1" />
      </material>
    </visual>
    <collision>
      <origin xyz="-0.0249581 9.18304e-08 0.0280374" rpy="-0.00150056 0 -1.5708" />
      <geometry>
        <mesh filename="package://assets/upper_ankle_shaft.stl" />
      </geometry>
    </collision>
    <visual>
      <origin xyz="-0.0249718 9.18303e-08 0.0188651" rpy="-0.00150056 0 -1.5708" />
      <geometry>
        <mesh filename="package://assets/ankle_ear.stl" />
      </geometry>
      <material name="ankle_ear_4_material">
        <color rgba="0.615686 0.811765 0.929412 1" />
      </material>
    </visual>
    <collision>
      <origin xyz="-0.0249718 9.18303e-08 0.0188651" rpy="-0.00150056 0 -1.5708" />
      <geometry>
        <mesh filename="package://assets/ankle_ear.stl" />
      </geometry>
    </collision>
    <visual>
      <origin xyz="-0.025 9.18301e-08 3.74223e-05" rpy="-0.00150056 0 -1.5708" />
      <geometry>
        <mesh filename="package://assets/ankle_shaft.stl" />
      </geometry>
      <material name="ankle_shaft_4_material">
        <color rgba="0.615686 0.811765 0.929412 1" />
      </material>
    </visual>
    <collision>
      <origin xyz="-0.025 9.18301e-08 3.74223e-05" rpy="-0.00150056 0 -1.5708" />
      <geometry>
        <mesh filename="package://assets/ankle_shaft.stl" />
      </geometry>
    </collision>
  </link>
  <joint name="right_ankle_pitch_joint_2" type="fixed">
    <origin xyz="0.0243657 0.056 -0.423037" rpy="0 0 0" />
    <parent link="urdf_r_tibia_assembly" />
    <child link="ankle_assembly_4" />
  </joint>
  <joint name="right_knee_joint" type="revolute">
    <origin xyz="2.22935e-07 -0.055 -0.113" rpy="0 0.0158737 0" />
    <parent link="urdf_lower_femur_assembly_2" />
    <child link="urdf_r_tibia_assembly" />
    <axis xyz="0 1 0" />
    <limit effort="10" velocity="10" lower="-0.191906" upper="2.33882" />
  </joint>
  <joint name="right_hip_yaw_joint" type="revolute">
    <origin xyz="-0.053 -0.00033635 -0.217" rpy="-0.00155 0 0" />
    <parent link="urdf_r_upper_femur_assemby" />
    <child link="urdf_lower_femur_assembly_2" />
    <axis xyz="0 0 1" />
    <limit effort="10" velocity="10" lower="-1.57082" upper="1.57077" />
  </joint>
  <joint name="right_hip_roll_joint" type="revolute">
    <origin xyz="0.0549931 -0.078 0.000872784" rpy="0 -0.0158773 0" />
    <parent link="urdf_hip_assembly_2" />
    <child link="urdf_r_upper_femur_assemby" />
    <axis xyz="1 0 0" />
    <limit effort="10" velocity="10" lower="-3.14005" upper="0.35061" />
  </joint>
  <joint name="right_hip_pitch_joint" type="revolute">
    <origin xyz="0.0333787 -0.107699 -0.467748" rpy="0 0 0" />
    <parent link="urdf_base" />
    <child link="urdf_hip_assembly_2" />
    <axis xyz="0 1 0" />
    <limit effort="10" velocity="10" lower="-2.51486" upper="1.58667" />
  </joint>
</robot>
