<?xml version="1.0" ?>
<!-- Generated using onshape-to-robot -->
<!-- Onshape document_id: 44eccb8c34362883e6cd3fd1 -->
<robot name="robot_harambe">
  <!-- Link urdf_base -->
  <link name="urdf_base">
    <inertial>
      <origin xyz="0.000699269 0.0334604 -0.431702" rpy="0 0 0"/>
      <mass value="5.132"/>
      <inertia ixx="0.0213139" ixy="-2.35276e-07" ixz="6.5838e-06" iyy="0.0288848" iyz="-2.88595e-05" izz="0.0155352"/>
    </inertial>
    <!-- Part stator_x8_p20_120_unified -->
    <visual>
      <origin xyz="-0.0103011 0.0333787 -0.467748" rpy="-1.5708 0.785398 1.5708"/>
      <geometry>
        <mesh filename="package://assets/stator_x8_p20_120_unified.stl"/>
      </geometry>
      <material name="stator_x8_p20_120_unified_material">
        <color rgba="0.882353 0.572549 0.478431 1"/>
      </material>
    </visual>
    <collision>
      <origin xyz="-0.0103011 0.0333787 -0.467748" rpy="-1.5708 0.785398 1.5708"/>
      <geometry>
        <mesh filename="package://assets/stator_x8_p20_120_unified.stl"/>
      </geometry>
    </collision>
    <!-- Part b_base -->
    <visual>
      <origin xyz="0.000697952 -0.00271429 -0.432504" rpy="0 -0 0"/>
      <geometry>
        <mesh filename="package://assets/b_base.stl"/>
      </geometry>
      <material name="b_base_material">
        <color rgba="0.368627 0.25098 0.643137 1"/>
      </material>
    </visual>
    <collision>
      <origin xyz="0.000697952 -0.00271429 -0.432504" rpy="0 -0 0"/>
      <geometry>
        <mesh filename="package://assets/b_base.stl"/>
      </geometry>
    </collision>
    <!-- Part stator_x8_p20_120_unified_2 -->
    <visual>
      <origin xyz="0.0116989 0.0333787 -0.467748" rpy="1.5708 -0.785398 1.5708"/>
      <geometry>
        <mesh filename="package://assets/stator_x8_p20_120_unified.stl"/>
      </geometry>
      <material name="stator_x8_p20_120_unified_2_material">
        <color rgba="0.882353 0.572549 0.478431 1"/>
      </material>
    </visual>
    <collision>
      <origin xyz="0.0116989 0.0333787 -0.467748" rpy="1.5708 -0.785398 1.5708"/>
      <geometry>
        <mesh filename="package://assets/stator_x8_p20_120_unified.stl"/>
      </geometry>
    </collision>
    <!-- Part stator_x8_p20_120_unified_3 -->
    <visual>
      <origin xyz="0.000698852 0.0333787 -0.396748" rpy="0 -0 0"/>
      <geometry>
        <mesh filename="package://assets/stator_x8_p20_120_unified.stl"/>
      </geometry>
      <material name="stator_x8_p20_120_unified_3_material">
        <color rgba="0.882353 0.572549 0.478431 1"/>
      </material>
    </visual>
    <collision>
      <origin xyz="0.000698852 0.0333787 -0.396748" rpy="0 -0 0"/>
      <geometry>
        <mesh filename="package://assets/stator_x8_p20_120_unified.stl"/>
      </geometry>
    </collision>
    <!-- Part f_base -->
    <visual>
      <origin xyz="0.000705351 0.070373 -0.431099" rpy="0 -0 0"/>
      <geometry>
        <mesh filename="package://assets/f_base.stl"/>
      </geometry>
      <material name="f_base_material">
        <color rgba="0.909804 0.572549 0.164706 1"/>
      </material>
    </visual>
    <collision>
      <origin xyz="0.000705351 0.070373 -0.431099" rpy="0 -0 0"/>
      <geometry>
        <mesh filename="package://assets/f_base.stl"/>
      </geometry>
    </collision>
  </link>
  <!-- Link urdf_simplified_torso -->
  <link name="urdf_simplified_torso">
    <inertial>
      <origin xyz="3.65935e-05 0.00131439 0.32693" rpy="0 0 0"/>
      <mass value="5.9"/>
      <inertia ixx="0.291383" ixy="1.29291e-06" ixz="-8.5891e-05" iyy="0.318357" iyz="-0.00277833" izz="0.0767614"/>
    </inertial>
    <!-- Part urdf_simplified_torso -->
    <visual>
      <origin xyz="0 5.1e-11 0.26095" rpy="-0 -0 -0"/>
      <geometry>
        <mesh filename="package://assets/urdf_simplified_torso.stl"/>
      </geometry>
      <material name="urdf_simplified_torso_material">
        <color rgba="0.647059 0.647059 0.647059 1"/>
      </material>
    </visual>
    <collision>
      <origin xyz="0 5.1e-11 0.26095" rpy="-0 -0 -0"/>
      <geometry>
        <mesh filename="package://assets/urdf_simplified_torso.stl"/>
      </geometry>
    </collision>
    <!-- Part head -->
    <visual>
      <origin xyz="0.000358088 3.7822e-05 0.67095" rpy="0 0 0"/>
      <geometry>
        <mesh filename="package://assets/head.stl"/>
      </geometry>
      <material name="head_material">
        <color rgba="0.737255 0.937255 0.917647 1"/>
      </material>
    </visual>
    <collision>
      <origin xyz="0.000358088 3.7822e-05 0.67095" rpy="0 0 0"/>
      <geometry>
        <mesh filename="package://assets/head.stl"/>
      </geometry>
    </collision>
    <!-- Part back_access -->
    <visual>
      <origin xyz="0.000358088 3.7822e-05 0.672878" rpy="0 0 0"/>
      <geometry>
        <mesh filename="package://assets/back_access.stl"/>
      </geometry>
      <material name="back_access_material">
        <color rgba="0.231373 0.380392 0.705882 1"/>
      </material>
    </visual>
    <collision>
      <origin xyz="0.000358088 3.7822e-05 0.672878" rpy="0 0 0"/>
      <geometry>
        <mesh filename="package://assets/back_access.stl"/>
      </geometry>
    </collision>
  </link>
  <!-- Link urdf_l_shoulder_assembly -->
  <link name="urdf_l_shoulder_assembly">
    <inertial>
      <origin xyz="-0.00413417 4.09728e-05 0.0631966" rpy="0 0 0"/>
      <mass value="1.246"/>
      <inertia ixx="0.00206364" ixy="1.488e-06" ixz="-3.5558e-05" iyy="0.00171114" iyz="3.32975e-06" izz="0.00152408"/>
    </inertial>
    <!-- Part l_shoulder -->
    <visual>
      <origin xyz="-0.00130076 6.96521e-06 0.0502746" rpy="1.5708 1.5708 0"/>
      <geometry>
        <mesh filename="package://assets/l_shoulder.stl"/>
      </geometry>
      <material name="l_shoulder_material">
        <color rgba="0.615686 0.811765 0.929412 1"/>
      </material>
    </visual>
    <collision>
      <origin xyz="-0.00130076 6.96521e-06 0.0502746" rpy="1.5708 1.5708 0"/>
      <geometry>
        <mesh filename="package://assets/l_shoulder.stl"/>
      </geometry>
    </collision>
    <!-- Part stator_x6_p20_60_unified -->
    <visual>
      <origin xyz="-0.0385 0 0.07" rpy="0 1.5708 0"/>
      <geometry>
        <mesh filename="package://assets/stator_x6_p20_60_unified.stl"/>
      </geometry>
      <material name="stator_x6_p20_60_unified_material">
        <color rgba="0.960784 0.835294 0.470588 1"/>
      </material>
    </visual>
    <collision>
      <origin xyz="-0.0385 0 0.07" rpy="0 1.5708 0"/>
      <geometry>
        <mesh filename="package://assets/stator_x6_p20_60_unified.stl"/>
      </geometry>
    </collision>
  </link>
  <!-- Link urdf_l_upper_arm_assembly -->
  <link name="urdf_l_upper_arm_assembly">
    <inertial>
      <origin xyz="0.000631443 0.105506 -0.0354438" rpy="0 0 0"/>
      <mass value="0.802"/>
      <inertia ixx="0.00206427" ixy="-2.68695e-05" ixz="1.03041e-05" iyy="0.00104318" iyz="0.000475779" izz="0.00190836"/>
    </inertial>
    <!-- Part urdf_l_upper_arm_simplified -->
    <visual>
      <origin xyz="0.00120028 0.0932559 -0.0268697" rpy="1.5708 -0.785398 0"/>
      <geometry>
        <mesh filename="package://assets/urdf_l_upper_arm_simplified.stl"/>
      </geometry>
      <material name="urdf_l_upper_arm_simplified_material">
        <color rgba="0.917647 0.917647 0.917647 1"/>
      </material>
    </visual>
    <collision>
      <origin xyz="0.00120028 0.0932559 -0.0268697" rpy="1.5708 -0.785398 0"/>
      <geometry>
        <mesh filename="package://assets/urdf_l_upper_arm_simplified.stl"/>
      </geometry>
    </collision>
    <!-- Part stator_x4_p36_36_unified -->
    <visual>
      <origin xyz="0 0.091 -0.046" rpy="-1.5708 0.785398 0"/>
      <geometry>
        <mesh filename="package://assets/stator_x4_p36_36_unified.stl"/>
      </geometry>
      <material name="stator_x4_p36_36_unified_material">
        <color rgba="0.764706 0.545098 0.803922 1"/>
      </material>
    </visual>
    <collision>
      <origin xyz="0 0.091 -0.046" rpy="-1.5708 0.785398 0"/>
      <geometry>
        <mesh filename="package://assets/stator_x4_p36_36_unified.stl"/>
      </geometry>
    </collision>
  </link>
  <!-- Link urdf_l_elbow_assembly -->
  <link name="urdf_l_elbow_assembly">
    <inertial>
      <origin xyz="0.000297133 0.00777593 -0.0710681" rpy="0 0 0"/>
      <mass value="1.109"/>
      <inertia ixx="0.00140529" ixy="1.03356e-05" ixz="-1.68171e-05" iyy="0.00151899" iyz="7.83699e-05" izz="0.00113761"/>
    </inertial>
    <!-- Part stator_x6_p20_60_unified_2 -->
    <visual>
      <origin xyz="-0 0.044 -0.075" rpy="1.5708 1.5708 0"/>
      <geometry>
        <mesh filename="package://assets/stator_x6_p20_60_unified.stl"/>
      </geometry>
      <material name="stator_x6_p20_60_unified_2_material">
        <color rgba="0.960784 0.835294 0.470588 1"/>
      </material>
    </visual>
    <collision>
      <origin xyz="-0 0.044 -0.075" rpy="1.5708 1.5708 0"/>
      <geometry>
        <mesh filename="package://assets/stator_x6_p20_60_unified.stl"/>
      </geometry>
    </collision>
    <!-- Part urdf_l_elbow_simplified -->
    <visual>
      <origin xyz="-0 0.01225 -0.075" rpy="-1.5708 1.5708 0"/>
      <geometry>
        <mesh filename="package://assets/urdf_l_elbow_simplified.stl"/>
      </geometry>
      <material name="urdf_l_elbow_simplified_material">
        <color rgba="0.231373 0.380392 0.705882 1"/>
      </material>
    </visual>
    <collision>
      <origin xyz="-0 0.01225 -0.075" rpy="-1.5708 1.5708 0"/>
      <geometry>
        <mesh filename="package://assets/urdf_l_elbow_simplified.stl"/>
      </geometry>
    </collision>
  </link>
  <!-- Link urdf_l_upper_forearm_assembly -->
  <link name="urdf_l_upper_forearm_assembly">
    <inertial>
      <origin xyz="0.10341 0.00191699 0.0286559" rpy="0 0 0"/>
      <mass value="0.707"/>
      <inertia ixx="0.000720041" ixy="-2.79231e-06" ixz="-0.000365631" iyy="0.00168211" iyz="-5.21195e-06" izz="0.00146156"/>
    </inertial>
    <!-- Part urdf_l_upper_forearm_simplified -->
    <visual>
      <origin xyz="0.119 0 0.035" rpy="0 -1.5708 0"/>
      <geometry>
        <mesh filename="package://assets/urdf_l_upper_forearm_simplified.stl"/>
      </geometry>
      <material name="urdf_l_upper_forearm_simplified_material">
        <color rgba="0.498039 0.498039 0.498039 1"/>
      </material>
    </visual>
    <collision>
      <origin xyz="0.119 0 0.035" rpy="0 -1.5708 0"/>
      <geometry>
        <mesh filename="package://assets/urdf_l_upper_forearm_simplified.stl"/>
      </geometry>
    </collision>
    <!-- Part stator_x4_p36_36_unified_2 -->
    <visual>
      <origin xyz="0.09 0 0.035" rpy="-3.14159 -1.5708 0"/>
      <geometry>
        <mesh filename="package://assets/stator_x4_p36_36_unified.stl"/>
      </geometry>
      <material name="stator_x4_p36_36_unified_2_material">
        <color rgba="0.764706 0.545098 0.803922 1"/>
      </material>
    </visual>
    <collision>
      <origin xyz="0.09 0 0.035" rpy="-3.14159 -1.5708 0"/>
      <geometry>
        <mesh filename="package://assets/stator_x4_p36_36_unified.stl"/>
      </geometry>
    </collision>
  </link>
  <!-- Link urdf_l_lower_forearm_assembly -->
  <link name="urdf_l_lower_forearm_assembly">
    <inertial>
      <origin xyz="-0.000687732 -0.00432126 -0.0515634" rpy="0 0 0"/>
      <mass value="0.618"/>
      <inertia ixx="0.000619445" ixy="-4.69813e-06" ixz="1.66447e-05" iyy="0.000626234" iyz="-2.276e-05" izz="0.000448744"/>
    </inertial>
    <!-- Part urdf_l_lower_forearm_simplified -->
    <visual>
      <origin xyz="0 -0.009 -0.0615" rpy="-1.5708 0 3.14159"/>
      <geometry>
        <mesh filename="package://assets/urdf_l_lower_forearm_simplified.stl"/>
      </geometry>
      <material name="urdf_l_lower_forearm_simplified_material">
        <color rgba="0.980392 0.713725 0.00392157 1"/>
      </material>
    </visual>
    <collision>
      <origin xyz="0 -0.009 -0.0615" rpy="-1.5708 0 3.14159"/>
      <geometry>
        <mesh filename="package://assets/urdf_l_lower_forearm_simplified.stl"/>
      </geometry>
    </collision>
    <!-- Part stator_x4_p36_36_unified_3 -->
    <visual>
      <origin xyz="0 -0.0375 -0.0615" rpy="1.5708 0 -3.14159"/>
      <geometry>
        <mesh filename="package://assets/stator_x4_p36_36_unified.stl"/>
      </geometry>
      <material name="stator_x4_p36_36_unified_3_material">
        <color rgba="0.764706 0.545098 0.803922 1"/>
      </material>
    </visual>
    <collision>
      <origin xyz="0 -0.0375 -0.0615" rpy="1.5708 0 -3.14159"/>
      <geometry>
        <mesh filename="package://assets/stator_x4_p36_36_unified.stl"/>
      </geometry>
    </collision>
  </link>
  <!-- Link urdf_l_wrist_assembly -->
  <link name="urdf_l_wrist_assembly">
    <inertial>
      <origin xyz="-1.08315e-06 0.112614 -0.0282716" rpy="0 0 0"/>
      <mass value="0.398"/>
      <inertia ixx="0.00160501" ixy="-2.3164e-08" ixz="7.037e-09" iyy="0.000274862" iyz="5.58167e-05" izz="0.00146537"/>
    </inertial>
    <!-- Part l_wrist -->
    <visual>
      <origin xyz="-4.31502e-06 0.0434653 -0.0219314" rpy="1.5708 0 0"/>
      <geometry>
        <mesh filename="package://assets/l_wrist.stl"/>
      </geometry>
      <material name="l_wrist_material">
        <color rgba="0.8 0.74902 0.913725 1"/>
      </material>
    </visual>
    <collision>
      <origin xyz="-4.31502e-06 0.0434653 -0.0219314" rpy="1.5708 0 0"/>
      <geometry>
        <mesh filename="package://assets/l_wrist.stl"/>
      </geometry>
    </collision>
    <!-- Part l_hand -->
    <visual>
      <origin xyz="-2.67e-09 0.135203 -0.0303429" rpy="1.5708 -1.5708 0"/>
      <geometry>
        <mesh filename="package://assets/l_hand.stl"/>
      </geometry>
      <material name="l_hand_material">
        <color rgba="1 1 1 1"/>
      </material>
    </visual>
    <collision>
      <origin xyz="-2.67e-09 0.135203 -0.0303429" rpy="1.5708 -1.5708 0"/>
      <geometry>
        <mesh filename="package://assets/l_hand.stl"/>
      </geometry>
    </collision>
  </link>
  <!-- Joint from urdf_l_lower_forearm_assembly to urdf_l_wrist_assembly -->
  <joint name="left_wrist_roll_joint_X4" type="revolute">
    <origin xyz="0 0.027 -0.0615" rpy="-1.5708 -0 0"/>
    <parent link="urdf_l_lower_forearm_assembly"/>
    <child link="urdf_l_wrist_assembly"/>
    <axis xyz="0 0 1"/>
    <limit effort="10" velocity="10" lower="-1.5708" upper="1.5708"/>
  </joint>
  <!-- Joint from urdf_l_upper_forearm_assembly to urdf_l_lower_forearm_assembly -->
  <joint name="left_wrist_yaw_joint_X4" type="revolute">
    <origin xyz="0.163 0 0.035" rpy="0 -1.5708 0"/>
    <parent link="urdf_l_upper_forearm_assembly"/>
    <child link="urdf_l_lower_forearm_assembly"/>
    <axis xyz="0 0 1"/>
    <limit effort="10" velocity="10" lower="-2.35619" upper="2.35619"/>
  </joint>
  <!-- Joint from urdf_l_elbow_assembly to urdf_l_upper_forearm_assembly -->
  <joint name="left_elbow_pitch_joint_X6" type="revolute">
    <origin xyz="-0 -0.035 -0.075" rpy="-1.5708 1.5708 0"/>
    <parent link="urdf_l_elbow_assembly"/>
    <child link="urdf_l_upper_forearm_assembly"/>
    <axis xyz="0 0 1"/>
    <limit effort="10" velocity="10" lower="-1.5708" upper="1.5708"/>
  </joint>
  <!-- Joint from urdf_l_upper_arm_assembly to urdf_l_elbow_assembly -->
  <joint name="left_shoulder_yaw_joint_X4" type="revolute">
    <origin xyz="-0 0.165 -0.046" rpy="1.5708 1.5708 0"/>
    <parent link="urdf_l_upper_arm_assembly"/>
    <child link="urdf_l_elbow_assembly"/>
    <axis xyz="0 0 1"/>
    <limit effort="10" velocity="10" lower="-2.35619" upper="2.35619"/>
  </joint>
  <!-- Joint from urdf_l_shoulder_assembly to urdf_l_upper_arm_assembly -->
  <joint name="left_shoulder_roll_joint_X6" type="revolute">
    <origin xyz="0.046 -0 0.07" rpy="-0 1.5708 0"/>
    <parent link="urdf_l_shoulder_assembly"/>
    <child link="urdf_l_upper_arm_assembly"/>
    <axis xyz="0 0 1"/>
    <limit effort="10" velocity="10" lower="0" upper="3.14159"/>
  </joint>
  <!-- Joint from urdf_simplified_torso to urdf_l_shoulder_assembly -->
  <joint name="left_shoulder_pitch_joint_X6" type="revolute">
    <origin xyz="-0.1755 -5.1e-11 0.423977" rpy="-1.5708 0 1.5708"/>
    <parent link="urdf_simplified_torso"/>
    <child link="urdf_l_shoulder_assembly"/>
    <axis xyz="0 0 1"/>
    <limit effort="10" velocity="10" lower="-3.14159" upper="1.5708"/>
  </joint>
  <!-- Link urdf_r_shoulder_assembly -->
  <link name="urdf_r_shoulder_assembly">
    <inertial>
      <origin xyz="-0.00474022 2.53153e-05 -0.0660727" rpy="0 0 0"/>
      <mass value="1.02"/>
      <inertia ixx="0.00132827" ixy="7.40443e-07" ixz="1.40702e-05" iyy="0.00114323" iyz="-1.76147e-06" izz="0.00104972"/>
    </inertial>
    <!-- Part stator_x6_p20_60_unified_3 -->
    <visual>
      <origin xyz="-0.0385 -0 -0.07" rpy="-0 1.5708 0"/>
      <geometry>
        <mesh filename="package://assets/stator_x6_p20_60_unified.stl"/>
      </geometry>
      <material name="stator_x6_p20_60_unified_3_material">
        <color rgba="0.960784 0.835294 0.470588 1"/>
      </material>
    </visual>
    <collision>
      <origin xyz="-0.0385 -0 -0.07" rpy="-0 1.5708 0"/>
      <geometry>
        <mesh filename="package://assets/stator_x6_p20_60_unified.stl"/>
      </geometry>
    </collision>
    <!-- Part r_shoulder -->
    <visual>
      <origin xyz="-0.00129067 6.91178e-06 -0.0501448" rpy="1.5708 1.5708 0"/>
      <geometry>
        <mesh filename="package://assets/r_shoulder.stl"/>
      </geometry>
      <material name="r_shoulder_material">
        <color rgba="0.615686 0.811765 0.929412 1"/>
      </material>
    </visual>
    <collision>
      <origin xyz="-0.00129067 6.91178e-06 -0.0501448" rpy="1.5708 1.5708 0"/>
      <geometry>
        <mesh filename="package://assets/r_shoulder.stl"/>
      </geometry>
    </collision>
  </link>
  <!-- Link urdf_r_upper_arm_assembly -->
  <link name="urdf_r_upper_arm_assembly">
    <inertial>
      <origin xyz="-9.416e-09 -0.104084 0.0297331" rpy="0 0 0"/>
      <mass value="0.802"/>
      <inertia ixx="0.00204755" ixy="-6.95e-10" ixz="1.159e-09" iyy="0.0010158" iyz="0.000468447" izz="0.00188605"/>
    </inertial>
    <!-- Part stator_x4_p36_36_unified_4 -->
    <visual>
      <origin xyz="0 -0.091 0.041" rpy="1.5708 -0 0"/>
      <geometry>
        <mesh filename="package://assets/stator_x4_p36_36_unified.stl"/>
      </geometry>
      <material name="stator_x4_p36_36_unified_4_material">
        <color rgba="0.764706 0.545098 0.803922 1"/>
      </material>
    </visual>
    <collision>
      <origin xyz="0 -0.091 0.041" rpy="1.5708 -0 0"/>
      <geometry>
        <mesh filename="package://assets/stator_x4_p36_36_unified.stl"/>
      </geometry>
    </collision>
    <!-- Part r_upper_arm -->
    <visual>
      <origin xyz="-4.6857e-08 -0.0905315 0.020543" rpy="-1.5708 0 0"/>
      <geometry>
        <mesh filename="package://assets/r_upper_arm.stl"/>
      </geometry>
      <material name="r_upper_arm_material">
        <color rgba="0.231373 0.380392 0.705882 1"/>
      </material>
    </visual>
    <collision>
      <origin xyz="-4.6857e-08 -0.0905315 0.020543" rpy="-1.5708 0 0"/>
      <geometry>
        <mesh filename="package://assets/r_upper_arm.stl"/>
      </geometry>
    </collision>
  </link>
  <!-- Link urdf_r_elbow_assembly -->
  <link name="urdf_r_elbow_assembly">
    <inertial>
      <origin xyz="-0.0084574 3.15569e-05 -0.0612736" rpy="0 0 0"/>
      <mass value="1.109"/>
      <inertia ixx="0.00151237" ixy="-3.07412e-07" ixz="-6.05931e-05" iyy="0.00139043" iyz="-2.25603e-06" izz="0.00111817"/>
    </inertial>
    <!-- Part r_elbow -->
    <visual>
      <origin xyz="0.000331582 1.16025e-05 -0.0512953" rpy="0 -0 -0"/>
      <geometry>
        <mesh filename="package://assets/r_elbow.stl"/>
      </geometry>
      <material name="r_elbow_material">
        <color rgba="0.796078 0.905882 0.745098 1"/>
      </material>
    </visual>
    <collision>
      <origin xyz="0.000331582 1.16025e-05 -0.0512953" rpy="0 -0 -0"/>
      <geometry>
        <mesh filename="package://assets/r_elbow.stl"/>
      </geometry>
    </collision>
    <!-- Part stator_x6_p20_60_unified_4 -->
    <visual>
      <origin xyz="-0.0445 0 -0.065" rpy="3.14159 -1.5708 0"/>
      <geometry>
        <mesh filename="package://assets/stator_x6_p20_60_unified.stl"/>
      </geometry>
      <material name="stator_x6_p20_60_unified_4_material">
        <color rgba="0.960784 0.835294 0.470588 1"/>
      </material>
    </visual>
    <collision>
      <origin xyz="-0.0445 0 -0.065" rpy="3.14159 -1.5708 0"/>
      <geometry>
        <mesh filename="package://assets/stator_x6_p20_60_unified.stl"/>
      </geometry>
    </collision>
  </link>
  <!-- Link urdf_r_upper_forearm_assembly -->
  <link name="urdf_r_upper_forearm_assembly">
    <inertial>
      <origin xyz="0.00228064 0.101792 0.0327896" rpy="0 0 0"/>
      <mass value="0.707"/>
      <inertia ixx="0.00166903" ixy="-1.53798e-05" ixz="-1.15872e-05" iyy="0.000703651" iyz="-0.000352466" izz="0.0014499"/>
    </inertial>
    <!-- Part stator_x4_p36_36_unified_5 -->
    <visual>
      <origin xyz="0 0.09 0.04" rpy="-1.5708 1.5708 0"/>
      <geometry>
        <mesh filename="package://assets/stator_x4_p36_36_unified.stl"/>
      </geometry>
      <material name="stator_x4_p36_36_unified_5_material">
        <color rgba="0.764706 0.545098 0.803922 1"/>
      </material>
    </visual>
    <collision>
      <origin xyz="0 0.09 0.04" rpy="-1.5708 1.5708 0"/>
      <geometry>
        <mesh filename="package://assets/stator_x4_p36_36_unified.stl"/>
      </geometry>
    </collision>
    <!-- Part r_upper_forearm -->
    <visual>
      <origin xyz="0.00466986 0.0842107 0.0254856" rpy="1.5708 1.5708 0"/>
      <geometry>
        <mesh filename="package://assets/r_upper_forearm.stl"/>
      </geometry>
      <material name="r_upper_forearm_material">
        <color rgba="0.890196 0.698039 0.639216 1"/>
      </material>
    </visual>
    <collision>
      <origin xyz="0.00466986 0.0842107 0.0254856" rpy="1.5708 1.5708 0"/>
      <geometry>
        <mesh filename="package://assets/r_upper_forearm.stl"/>
      </geometry>
    </collision>
  </link>
  <!-- Link urdf_r_lower_forearm_assembly -->
  <link name="urdf_r_lower_forearm_assembly">
    <inertial>
      <origin xyz="-2.4334e-08 0.00399848 0.046852" rpy="0 0 0"/>
      <mass value="0.618"/>
      <inertia ixx="0.000618602" ixy="-1.76e-10" ixz="5.34e-10" iyy="0.000617307" iyz="-3.83228e-05" izz="0.000437775"/>
    </inertial>
    <!-- Part r_lower_forearm -->
    <visual>
      <origin xyz="4.2712e-08 -0.00205797 0.0333447" rpy="3.14159 -0 0"/>
      <geometry>
        <mesh filename="package://assets/r_lower_forearm.stl"/>
      </geometry>
      <material name="r_lower_forearm_material">
        <color rgba="0.941176 0.87451 0.678431 1"/>
      </material>
    </visual>
    <collision>
      <origin xyz="4.2712e-08 -0.00205797 0.0333447" rpy="3.14159 -0 0"/>
      <geometry>
        <mesh filename="package://assets/r_lower_forearm.stl"/>
      </geometry>
    </collision>
    <!-- Part stator_x4_p36_36_unified_6 -->
    <visual>
      <origin xyz="-0 0.038 0.0565" rpy="-1.5708 -0 -3.14159"/>
      <geometry>
        <mesh filename="package://assets/stator_x4_p36_36_unified.stl"/>
      </geometry>
      <material name="stator_x4_p36_36_unified_6_material">
        <color rgba="0.764706 0.545098 0.803922 1"/>
      </material>
    </visual>
    <collision>
      <origin xyz="-0 0.038 0.0565" rpy="-1.5708 -0 -3.14159"/>
      <geometry>
        <mesh filename="package://assets/stator_x4_p36_36_unified.stl"/>
      </geometry>
    </collision>
  </link>
  <!-- Link urdf_r_wrist_assembly -->
  <link name="urdf_r_wrist_assembly">
    <inertial>
      <origin xyz="1.54616e-06 0.104482 -0.0275327" rpy="0 0 0"/>
      <mass value="0.45"/>
      <inertia ixx="0.001889" ixy="3.2626e-08" ixz="-1.0208e-08" iyy="0.000327099" iyz="9.3721e-05" izz="0.0017356"/>
    </inertial>
    <!-- Part r_hand -->
    <visual>
      <origin xyz="2.67e-09 0.135003 -0.0303429" rpy="1.5708 1.5708 0"/>
      <geometry>
        <mesh filename="package://assets/r_hand.stl"/>
      </geometry>
      <material name="r_hand_material">
        <color rgba="1 1 1 1"/>
      </material>
    </visual>
    <collision>
      <origin xyz="2.67e-09 0.135003 -0.0303429" rpy="1.5708 1.5708 0"/>
      <geometry>
        <mesh filename="package://assets/r_hand.stl"/>
      </geometry>
    </collision>
    <!-- Part r_wrist -->
    <visual>
      <origin xyz="4.44584e-06 0.0434653 -0.0219316" rpy="1.5708 -0 0"/>
      <geometry>
        <mesh filename="package://assets/r_wrist.stl"/>
      </geometry>
      <material name="r_wrist_material">
        <color rgba="0.8 0.74902 0.913725 1"/>
      </material>
    </visual>
    <collision>
      <origin xyz="4.44584e-06 0.0434653 -0.0219316" rpy="1.5708 -0 0"/>
      <geometry>
        <mesh filename="package://assets/r_wrist.stl"/>
      </geometry>
    </collision>
  </link>
  <!-- Joint from urdf_r_lower_forearm_assembly to urdf_r_wrist_assembly -->
  <joint name="right_wrist_roll_joint_X4" type="revolute">
    <origin xyz="-0 -0.027 0.0565" rpy="1.5708 0 -0"/>
    <parent link="urdf_r_lower_forearm_assembly"/>
    <child link="urdf_r_wrist_assembly"/>
    <axis xyz="0 0 1"/>
    <limit effort="10" velocity="10" lower="-1.5708" upper="1.5708"/>
  </joint>
  <!-- Joint from urdf_r_upper_forearm_assembly to urdf_r_lower_forearm_assembly -->
  <joint name="right_wrist_yaw_joint_X4" type="revolute">
    <origin xyz="-0 0.168 0.04" rpy="-1.5708 1.5708 0"/>
    <parent link="urdf_r_upper_forearm_assembly"/>
    <child link="urdf_r_lower_forearm_assembly"/>
    <axis xyz="0 0 1"/>
    <limit effort="10" velocity="10" lower="-2.35619" upper="2.35619"/>
  </joint>
  <!-- Joint from urdf_r_elbow_assembly to urdf_r_upper_forearm_assembly -->
  <joint name="right_elbow_pitch_joint_X6" type="revolute">
    <origin xyz="0.04 0 -0.065" rpy="-1.5708 0 1.5708"/>
    <parent link="urdf_r_elbow_assembly"/>
    <child link="urdf_r_upper_forearm_assembly"/>
    <axis xyz="0 0 1"/>
    <limit effort="10" velocity="10" lower="-1.5708" upper="1.5708"/>
  </joint>
  <!-- Joint from urdf_r_upper_arm_assembly to urdf_r_elbow_assembly -->
  <joint name="right_shoulder_yaw_joint_X4" type="revolute">
    <origin xyz="0 -0.17 0.041" rpy="-1.5708 0 0"/>
    <parent link="urdf_r_upper_arm_assembly"/>
    <child link="urdf_r_elbow_assembly"/>
    <axis xyz="0 0 1"/>
    <limit effort="10" velocity="10" lower="-2.35619" upper="2.35619"/>
  </joint>
  <!-- Joint from urdf_r_shoulder_assembly to urdf_r_upper_arm_assembly -->
  <joint name="right_shoulder_roll_joint_X6" type="revolute">
    <origin xyz="0.041 0 -0.07" rpy="-3.14159 1.5708 0"/>
    <parent link="urdf_r_shoulder_assembly"/>
    <child link="urdf_r_upper_arm_assembly"/>
    <axis xyz="0 0 1"/>
    <limit effort="10" velocity="10" lower="-3.14159" upper="0"/>
  </joint>
  <!-- Joint from urdf_simplified_torso to urdf_r_shoulder_assembly -->
  <joint name="right_shoulder_pitch_joint_X6" type="revolute">
    <origin xyz="0.1755 -5.1e-11 0.423977" rpy="-1.5708 -0 1.5708"/>
    <parent link="urdf_simplified_torso"/>
    <child link="urdf_r_shoulder_assembly"/>
    <axis xyz="0 0 1"/>
    <limit effort="10" velocity="10" lower="-3.14159" upper="1.5708"/>
  </joint>
  <!-- Joint from urdf_base to urdf_simplified_torso -->
  <joint name="waist_yaw_joint" type="revolute">
    <origin xyz="0.000698852 0.0333787 -0.300748" rpy="0 -0 0"/>
    <parent link="urdf_base"/>
    <child link="urdf_simplified_torso"/>
    <axis xyz="0 0 1"/>
    <limit effort="10" velocity="10" lower="-1.5708" upper="1.5708"/>
  </joint>
  <!-- Link urdf_hip_assembly -->
  <link name="urdf_hip_assembly">
    <inertial>
      <origin xyz="-0.00420762 6.23946e-06 0.0689982" rpy="0 0 0"/>
      <mass value="1.73"/>
      <inertia ixx="0.00302301" ixy="-4.5747e-08" ixz="2.30858e-05" iyy="0.00263533" iyz="8.49179e-07" izz="0.00228746"/>
    </inertial>
    <!-- Part hip -->
    <visual>
      <origin xyz="0.00253653 3.27638e-05 0.0520203" rpy="1.5708 1.5708 0"/>
      <geometry>
        <mesh filename="package://assets/hip.stl"/>
      </geometry>
      <material name="hip_material">
        <color rgba="0.0627451 0.266667 0.490196 1"/>
      </material>
    </visual>
    <collision>
      <origin xyz="0.00253653 3.27638e-05 0.0520203" rpy="1.5708 1.5708 0"/>
      <geometry>
        <mesh filename="package://assets/hip.stl"/>
      </geometry>
    </collision>
    <!-- Part stator_x8_p20_120_unified_4 -->
    <visual>
      <origin xyz="-0.043 -0 0.073" rpy="-3.14159 -1.5708 0"/>
      <geometry>
        <mesh filename="package://assets/stator_x8_p20_120_unified.stl"/>
      </geometry>
      <material name="stator_x8_p20_120_unified_4_material">
        <color rgba="0.882353 0.572549 0.478431 1"/>
      </material>
    </visual>
    <collision>
      <origin xyz="-0.043 -0 0.073" rpy="-3.14159 -1.5708 0"/>
      <geometry>
        <mesh filename="package://assets/stator_x8_p20_120_unified.stl"/>
      </geometry>
    </collision>
  </link>
  <!-- Link urdf_l_upper_femur_assembly -->
  <link name="urdf_l_upper_femur_assembly">
    <inertial>
      <origin xyz="-0.000406021 0.147969 -0.0457109" rpy="0 0 0"/>
      <mass value="1.912"/>
      <inertia ixx="0.00557257" ixy="-5.1876e-05" ixz="-1.18834e-06" iyy="0.00336728" iyz="0.000930002" izz="0.00512969"/>
    </inertial>
    <!-- Part l_upper_femur -->
    <visual>
      <origin xyz="-0.00151622 0.111785 -0.0257799" rpy="1.5708 0 0"/>
      <geometry>
        <mesh filename="package://assets/l_upper_femur.stl"/>
      </geometry>
      <material name="l_upper_femur_material">
        <color rgba="0.141176 0.694118 0.65098 1"/>
      </material>
    </visual>
    <collision>
      <origin xyz="-0.00151622 0.111785 -0.0257799" rpy="1.5708 0 0"/>
      <geometry>
        <mesh filename="package://assets/l_upper_femur.stl"/>
      </geometry>
    </collision>
    <!-- Part stator_x8_p20_120_unified_5 -->
    <visual>
      <origin xyz="0 0.124 -0.053" rpy="-1.5708 0 0"/>
      <geometry>
        <mesh filename="package://assets/stator_x8_p20_120_unified.stl"/>
      </geometry>
      <material name="stator_x8_p20_120_unified_5_material">
        <color rgba="0.882353 0.572549 0.478431 1"/>
      </material>
    </visual>
    <collision>
      <origin xyz="0 0.124 -0.053" rpy="-1.5708 0 0"/>
      <geometry>
        <mesh filename="package://assets/stator_x8_p20_120_unified.stl"/>
      </geometry>
    </collision>
  </link>
  <!-- Link urdf_lower_femur_assembly -->
  <link name="urdf_lower_femur_assembly">
    <inertial>
      <origin xyz="0.00357383 1.0389e-08 0.103307" rpy="0 0 0"/>
      <mass value="1.817"/>
      <inertia ixx="0.00421827" ixy="-2.5e-11" ixz="-0.00019709" iyy="0.00383469" iyz="-2.1291e-08" izz="0.00258541"/>
    </inertial>
    <!-- Part lower_femur -->
    <visual>
      <origin xyz="-0.00389134 -5.752e-09 0.070766" rpy="-3.14159 0 0"/>
      <geometry>
        <mesh filename="package://assets/lower_femur.stl"/>
      </geometry>
      <material name="lower_femur_material">
        <color rgba="0.380392 0.0470588 0.435294 1"/>
      </material>
    </visual>
    <collision>
      <origin xyz="-0.00389134 -5.752e-09 0.070766" rpy="-3.14159 0 0"/>
      <geometry>
        <mesh filename="package://assets/lower_femur.stl"/>
      </geometry>
    </collision>
    <!-- Part stator_x8_p20_120_unified_6 -->
    <visual>
      <origin xyz="0.043 -0 0.113" rpy="3.14159 1.5708 0"/>
      <geometry>
        <mesh filename="package://assets/stator_x8_p20_120_unified.stl"/>
      </geometry>
      <material name="stator_x8_p20_120_unified_6_material">
        <color rgba="0.882353 0.572549 0.478431 1"/>
      </material>
    </visual>
    <collision>
      <origin xyz="0.043 -0 0.113" rpy="3.14159 1.5708 0"/>
      <geometry>
        <mesh filename="package://assets/stator_x8_p20_120_unified.stl"/>
      </geometry>
    </collision>
  </link>
  <!-- Link urdf_l_tibia_assembly -->
  <link name="urdf_l_tibia_assembly">
    <inertial>
      <origin xyz="0.00463967 0.190721 -0.0449177" rpy="0 0 0"/>
      <mass value="6.45981"/>
      <inertia ixx="0.0785879" ixy="-0.00174734" ixz="0.000322174" iyy="0.0153456" iyz="0.00887502" izz="0.0762229"/>
    </inertial>
    <!-- Part stator_x4_p36_36_unified_7 -->
    <visual>
      <origin xyz="-0.018 0.16 -0.055" rpy="-0 1.5708 0"/>
      <geometry>
        <mesh filename="package://assets/stator_x4_p36_36_unified.stl"/>
      </geometry>
      <material name="stator_x4_p36_36_unified_7_material">
        <color rgba="0.764706 0.545098 0.803922 1"/>
      </material>
    </visual>
    <collision>
      <origin xyz="-0.018 0.16 -0.055" rpy="-0 1.5708 0"/>
      <geometry>
        <mesh filename="package://assets/stator_x4_p36_36_unified.stl"/>
      </geometry>
    </collision>
    <!-- Part stator_x4_p36_36_unified_8 -->
    <visual>
      <origin xyz="-0.018 0.235 -0.055" rpy="3.14159 -1.5708 0"/>
      <geometry>
        <mesh filename="package://assets/stator_x4_p36_36_unified.stl"/>
      </geometry>
      <material name="stator_x4_p36_36_unified_8_material">
        <color rgba="0.764706 0.545098 0.803922 1"/>
      </material>
    </visual>
    <collision>
      <origin xyz="-0.018 0.235 -0.055" rpy="3.14159 -1.5708 0"/>
      <geometry>
        <mesh filename="package://assets/stator_x4_p36_36_unified.stl"/>
      </geometry>
    </collision>
    <!-- Part m6_threaded_bar_300mm -->
    <visual>
      <origin xyz="0.0845 0.288554 -0.0732971" rpy="-3.14159 1.51844 1.5708"/>
      <geometry>
        <mesh filename="package://assets/m6_threaded_bar_300mm.stl"/>
      </geometry>
      <material name="m6_threaded_bar_300mm_material">
        <color rgba="0.141176 0.0352941 0.396078 1"/>
      </material>
    </visual>
    <collision>
      <origin xyz="0.0845 0.288554 -0.0732971" rpy="-3.14159 1.51844 1.5708"/>
      <geometry>
        <mesh filename="package://assets/m6_threaded_bar_300mm.stl"/>
      </geometry>
    </collision>
    <!-- Part urdf_spacer_x4 -->
    <visual>
      <origin xyz="0.05375 0.235 -0.055" rpy="-3.14159 1.50098 -1.5708"/>
      <geometry>
        <mesh filename="package://assets/urdf_spacer_x4.stl"/>
      </geometry>
      <material name="urdf_spacer_x4_material">
        <color rgba="0.615686 0.811765 0.929412 1"/>
      </material>
    </visual>
    <collision>
      <origin xyz="0.05375 0.235 -0.055" rpy="-3.14159 1.50098 -1.5708"/>
      <geometry>
        <mesh filename="package://assets/urdf_spacer_x4.stl"/>
      </geometry>
    </collision>
    <!-- Part urdf_l_tibia_assembly -->
    <visual>
      <origin xyz="0.000678721 0.186264 -0.0431371" rpy="1.5708 1.5708 0"/>
      <geometry>
        <mesh filename="package://assets/urdf_l_tibia_assembly.stl"/>
      </geometry>
      <material name="urdf_l_tibia_assembly_material">
        <color rgba="0.615686 0.811765 0.929412 1"/>
      </material>
    </visual>
    <collision>
      <origin xyz="0.000678721 0.186264 -0.0431371" rpy="1.5708 1.5708 0"/>
      <geometry>
        <mesh filename="package://assets/urdf_l_tibia_assembly.stl"/>
      </geometry>
    </collision>
    <!-- Part m6_threaded_bar_225mm -->
    <visual>
      <origin xyz="0.0845 0.326445 -0.0363334" rpy="-0 1.50098 -1.5708"/>
      <geometry>
        <mesh filename="package://assets/m6_threaded_bar_225mm.stl"/>
      </geometry>
      <material name="m6_threaded_bar_225mm_material">
        <color rgba="0.27451 0.0117647 0.317647 1"/>
      </material>
    </visual>
    <collision>
      <origin xyz="0.0845 0.326445 -0.0363334" rpy="-0 1.50098 -1.5708"/>
      <geometry>
        <mesh filename="package://assets/m6_threaded_bar_225mm.stl"/>
      </geometry>
    </collision>
    <!-- Part urdf_spacer_x4_2 -->
    <visual>
      <origin xyz="0.05375 0.16 -0.055" rpy="3.14159 -1.51844 -1.5708"/>
      <geometry>
        <mesh filename="package://assets/urdf_spacer_x4.stl"/>
      </geometry>
      <material name="urdf_spacer_x4_2_material">
        <color rgba="0.615686 0.811765 0.929412 1"/>
      </material>
    </visual>
    <collision>
      <origin xyz="0.05375 0.16 -0.055" rpy="3.14159 -1.51844 -1.5708"/>
      <geometry>
        <mesh filename="package://assets/urdf_spacer_x4.stl"/>
      </geometry>
    </collision>
  </link>
  <!-- Link udrf_ankle_assembly -->
  <link name="udrf_ankle_assembly">
    <inertial>
      <origin xyz="-0 0.0125426 -0.004" rpy="0 0 0"/>
      <mass value="0.0818219"/>
      <inertia ixx="1.69449e-05" ixy="0" ixz="0" iyy="1.25404e-05" iyz="0" izz="2.15245e-05"/>
    </inertial>
    <!-- Part udrf_ankle_assembly -->
    <visual>
      <origin xyz="-0 0.0125426 -0.004" rpy="1.5708 1.5708 0"/>
      <geometry>
        <mesh filename="package://assets/udrf_ankle_assembly.stl"/>
      </geometry>
      <material name="udrf_ankle_assembly_material">
        <color rgba="0.615686 0.811765 0.929412 1"/>
      </material>
    </visual>
    <collision>
      <origin xyz="-0 0.0125426 -0.004" rpy="1.5708 1.5708 0"/>
      <geometry>
        <mesh filename="package://assets/udrf_ankle_assembly.stl"/>
      </geometry>
    </collision>
  </link>
  <!-- Link urdf_foot_assembly -->
  <link name="urdf_foot_assembly">
    <inertial>
      <origin xyz="-9.74e-10 0.0209668 0.0427639" rpy="0 0 0"/>
      <mass value="0.504"/>
      <inertia ixx="0.00202397" ixy="-1.6e-11" ixz="1.2e-11" iyy="0.00229243" iyz="5.90887e-06" izz="0.000361698"/>
    </inertial>
    <!-- Part urdf_foot_assembly -->
    <visual>
      <origin xyz="5.5e-11 0.0209668 0.0427639" rpy="1.5708 0 -0"/>
      <geometry>
        <mesh filename="package://assets/urdf_foot_assembly.stl"/>
      </geometry>
      <material name="urdf_foot_assembly_material">
        <color rgba="0.615686 0.811765 0.929412 1"/>
      </material>
    </visual>
    <collision>
      <origin xyz="5.5e-11 0.0209668 0.0427639" rpy="1.5708 0 -0"/>
      <geometry>
        <mesh filename="package://assets/urdf_foot_assembly.stl"/>
      </geometry>
    </collision>
  </link>
  <!-- Joint from udrf_ankle_assembly to urdf_foot_assembly -->
  <joint name="left_ankle_roll_joint" type="revolute">
    <origin xyz="-0.012 0.028 -0.004" rpy="0 1.5708 0"/>
    <parent link="udrf_ankle_assembly"/>
    <child link="urdf_foot_assembly"/>
    <axis xyz="0 0 1"/>
    <limit effort="10" velocity="10" lower="-0.785398" upper="0.785398"/>
  </joint>
  <!-- Joint from urdf_l_tibia_assembly to udrf_ankle_assembly -->
  <joint name="left_ankle_pitch_joint" type="revolute">
    <origin xyz="-0 0.395 -0.051" rpy="0 -0 0"/>
    <parent link="urdf_l_tibia_assembly"/>
    <child link="udrf_ankle_assembly"/>
    <axis xyz="0 0 1"/>
    <limit effort="10" velocity="10" lower="-0.785398" upper="0.785398"/>
  </joint>
  <!-- Joint from urdf_lower_femur_assembly to urdf_l_tibia_assembly -->
  <joint name="left_knee_joint" type="revolute">
    <origin xyz="-0.055 -0 0.113" rpy="1.5708 0 -1.5708"/>
    <parent link="urdf_lower_femur_assembly"/>
    <child link="urdf_l_tibia_assembly"/>
    <axis xyz="0 0 1"/>
    <limit effort="10" velocity="10" lower="-0.174533" upper="1.5708"/>
  </joint>
  <!-- Joint from urdf_l_upper_femur_assembly to urdf_lower_femur_assembly -->
  <joint name="left_hip_yaw_joint" type="revolute">
    <origin xyz="-0 0.217 -0.053" rpy="-1.5708 0 0"/>
    <parent link="urdf_l_upper_femur_assembly"/>
    <child link="urdf_lower_femur_assembly"/>
    <axis xyz="0 0 1"/>
    <limit effort="10" velocity="10" lower="-1.5708" upper="1.5708"/>
  </joint>
  <!-- Joint from urdf_hip_assembly to urdf_l_upper_femur_assembly -->
  <joint name="left_hip_roll_joint" type="revolute">
    <origin xyz="0.055 0 0.073" rpy="-0 1.5708 0"/>
    <parent link="urdf_hip_assembly"/>
    <child link="urdf_l_upper_femur_assembly"/>
    <axis xyz="0 0 1"/>
    <limit effort="10" velocity="10" lower="-0.349066" upper="3.14159"/>
  </joint>
  <!-- Joint from urdf_base to urdf_hip_assembly -->
  <joint name="left_hip_pitch_joint" type="revolute">
    <origin xyz="-0.111301 0.0333787 -0.467748" rpy="-1.5708 -0 1.5708"/>
    <parent link="urdf_base"/>
    <child link="urdf_hip_assembly"/>
    <axis xyz="0 0 1"/>
    <limit effort="10" velocity="10" lower="-2.53073" upper="1.5708"/>
  </joint>
  <!-- Link urdf_hip_assembly_2 -->
  <link name="urdf_hip_assembly_2">
    <inertial>
      <origin xyz="-0.00420762 6.23946e-06 0.0739982" rpy="0 0 0"/>
      <mass value="1.73"/>
      <inertia ixx="0.00302301" ixy="-4.5747e-08" ixz="2.30858e-05" iyy="0.00263533" iyz="8.49179e-07" izz="0.00228746"/>
    </inertial>
    <!-- Part hip_2 -->
    <visual>
      <origin xyz="0.00253653 3.27638e-05 0.0570203" rpy="1.5708 1.5708 0"/>
      <geometry>
        <mesh filename="package://assets/hip.stl"/>
      </geometry>
      <material name="hip_2_material">
        <color rgba="0.0627451 0.266667 0.490196 1"/>
      </material>
    </visual>
    <collision>
      <origin xyz="0.00253653 3.27638e-05 0.0570203" rpy="1.5708 1.5708 0"/>
      <geometry>
        <mesh filename="package://assets/hip.stl"/>
      </geometry>
    </collision>
    <!-- Part stator_x8_p20_120_unified_7 -->
    <visual>
      <origin xyz="-0.043 0 0.078" rpy="-3.14159 -1.5708 0"/>
      <geometry>
        <mesh filename="package://assets/stator_x8_p20_120_unified.stl"/>
      </geometry>
      <material name="stator_x8_p20_120_unified_7_material">
        <color rgba="0.882353 0.572549 0.478431 1"/>
      </material>
    </visual>
    <collision>
      <origin xyz="-0.043 0 0.078" rpy="-3.14159 -1.5708 0"/>
      <geometry>
        <mesh filename="package://assets/stator_x8_p20_120_unified.stl"/>
      </geometry>
    </collision>
  </link>
  <!-- Link urdf_r_upper_femur_assemby -->
  <link name="urdf_r_upper_femur_assemby">
    <inertial>
      <origin xyz="0.000405705 0.147963 -0.0457092" rpy="0 0 0"/>
      <mass value="1.912"/>
      <inertia ixx="0.00557422" ixy="5.18237e-05" ixz="1.24938e-06" iyy="0.00336736" iyz="0.000930579" izz="0.00513139"/>
    </inertial>
    <!-- Part r_upper_femur -->
    <visual>
      <origin xyz="0.00151505 0.111761 -0.0257733" rpy="1.5708 0 -0"/>
      <geometry>
        <mesh filename="package://assets/r_upper_femur.stl"/>
      </geometry>
      <material name="r_upper_femur_material">
        <color rgba="0.941176 0.87451 0.678431 1"/>
      </material>
    </visual>
    <collision>
      <origin xyz="0.00151505 0.111761 -0.0257733" rpy="1.5708 0 -0"/>
      <geometry>
        <mesh filename="package://assets/r_upper_femur.stl"/>
      </geometry>
    </collision>
    <!-- Part stator_x8_p20_120_unified_8 -->
    <visual>
      <origin xyz="-0 0.124 -0.053" rpy="-1.5708 -0 0"/>
      <geometry>
        <mesh filename="package://assets/stator_x8_p20_120_unified.stl"/>
      </geometry>
      <material name="stator_x8_p20_120_unified_8_material">
        <color rgba="0.882353 0.572549 0.478431 1"/>
      </material>
    </visual>
    <collision>
      <origin xyz="-0 0.124 -0.053" rpy="-1.5708 -0 0"/>
      <geometry>
        <mesh filename="package://assets/stator_x8_p20_120_unified.stl"/>
      </geometry>
    </collision>
  </link>
  <!-- Link urdf_lower_femur_assembly_2 -->
  <link name="urdf_lower_femur_assembly_2">
    <inertial>
      <origin xyz="-0.00357383 -1.0389e-08 0.103307" rpy="0 0 0"/>
      <mass value="1.817"/>
      <inertia ixx="0.00421827" ixy="-2.5e-11" ixz="0.00019709" iyy="0.00383469" iyz="2.1291e-08" izz="0.00258541"/>
    </inertial>
    <!-- Part lower_femur_2 -->
    <visual>
      <origin xyz="0.00389134 5.752e-09 0.070766" rpy="-3.14159 0 3.14159"/>
      <geometry>
        <mesh filename="package://assets/lower_femur.stl"/>
      </geometry>
      <material name="lower_femur_2_material">
        <color rgba="0.380392 0.0470588 0.435294 1"/>
      </material>
    </visual>
    <collision>
      <origin xyz="0.00389134 5.752e-09 0.070766" rpy="-3.14159 0 3.14159"/>
      <geometry>
        <mesh filename="package://assets/lower_femur.stl"/>
      </geometry>
    </collision>
    <!-- Part stator_x8_p20_120_unified_9 -->
    <visual>
      <origin xyz="-0.043 0 0.113" rpy="0 1.5708 0"/>
      <geometry>
        <mesh filename="package://assets/stator_x8_p20_120_unified.stl"/>
      </geometry>
      <material name="stator_x8_p20_120_unified_9_material">
        <color rgba="0.882353 0.572549 0.478431 1"/>
      </material>
    </visual>
    <collision>
      <origin xyz="-0.043 0 0.113" rpy="0 1.5708 0"/>
      <geometry>
        <mesh filename="package://assets/stator_x8_p20_120_unified.stl"/>
      </geometry>
    </collision>
  </link>
  <!-- Link urdf_r_tibia_assembly -->
  <link name="urdf_r_tibia_assembly">
    <inertial>
      <origin xyz="0.00463921 0.190727 0.0449175" rpy="0 0 0"/>
      <mass value="6.45984"/>
      <inertia ixx="0.0785959" ixy="-0.00175015" ixz="-0.000322094" iyy="0.0153456" iyz="-0.0088755" izz="0.0762312"/>
    </inertial>
    <!-- Part urdf_spacer_x4_3 -->
    <visual>
      <origin xyz="0.05375 0.16 0.055" rpy="-3.14159 1.51844 -1.5708"/>
      <geometry>
        <mesh filename="package://assets/urdf_spacer_x4.stl"/>
      </geometry>
      <material name="urdf_spacer_x4_3_material">
        <color rgba="0.615686 0.811765 0.929412 1"/>
      </material>
    </visual>
    <collision>
      <origin xyz="0.05375 0.16 0.055" rpy="-3.14159 1.51844 -1.5708"/>
      <geometry>
        <mesh filename="package://assets/urdf_spacer_x4.stl"/>
      </geometry>
    </collision>
    <!-- Part m6_threaded_bar_225mm_2 -->
    <visual>
      <origin xyz="0.0845 0.326658 0.0363483" rpy="3.14159 1.50098 1.5708"/>
      <geometry>
        <mesh filename="package://assets/m6_threaded_bar_225mm.stl"/>
      </geometry>
      <material name="m6_threaded_bar_225mm_2_material">
        <color rgba="0.27451 0.0117647 0.317647 1"/>
      </material>
    </visual>
    <collision>
      <origin xyz="0.0845 0.326658 0.0363483" rpy="3.14159 1.50098 1.5708"/>
      <geometry>
        <mesh filename="package://assets/m6_threaded_bar_225mm.stl"/>
      </geometry>
    </collision>
    <!-- Part urdf_spacer_x4_4 -->
    <visual>
      <origin xyz="0.05375 0.235 0.055" rpy="-3.14159 -1.50098 -1.5708"/>
      <geometry>
        <mesh filename="package://assets/urdf_spacer_x4.stl"/>
      </geometry>
      <material name="urdf_spacer_x4_4_material">
        <color rgba="0.615686 0.811765 0.929412 1"/>
      </material>
    </visual>
    <collision>
      <origin xyz="0.05375 0.235 0.055" rpy="-3.14159 -1.50098 -1.5708"/>
      <geometry>
        <mesh filename="package://assets/urdf_spacer_x4.stl"/>
      </geometry>
    </collision>
    <!-- Part urdf_r_tibia_assembly -->
    <visual>
      <origin xyz="0.000678806 0.186264 0.0431372" rpy="1.5708 1.5708 0"/>
      <geometry>
        <mesh filename="package://assets/urdf_r_tibia_assembly.stl"/>
      </geometry>
      <material name="urdf_r_tibia_assembly_material">
        <color rgba="0.615686 0.811765 0.929412 1"/>
      </material>
    </visual>
    <collision>
      <origin xyz="0.000678806 0.186264 0.0431372" rpy="1.5708 1.5708 0"/>
      <geometry>
        <mesh filename="package://assets/urdf_r_tibia_assembly.stl"/>
      </geometry>
    </collision>
    <!-- Part stator_x4_p36_36_unified_9 -->
    <visual>
      <origin xyz="-0.018 0.16 0.055" rpy="-0 1.5708 0"/>
      <geometry>
        <mesh filename="package://assets/stator_x4_p36_36_unified.stl"/>
      </geometry>
      <material name="stator_x4_p36_36_unified_9_material">
        <color rgba="0.764706 0.545098 0.803922 1"/>
      </material>
    </visual>
    <collision>
      <origin xyz="-0.018 0.16 0.055" rpy="-0 1.5708 0"/>
      <geometry>
        <mesh filename="package://assets/stator_x4_p36_36_unified.stl"/>
      </geometry>
    </collision>
    <!-- Part m6_threaded_bar_300mm_2 -->
    <visual>
      <origin xyz="0.0845 0.288767 0.0732859" rpy="0 1.51844 -1.5708"/>
      <geometry>
        <mesh filename="package://assets/m6_threaded_bar_300mm.stl"/>
      </geometry>
      <material name="m6_threaded_bar_300mm_2_material">
        <color rgba="0.141176 0.0352941 0.396078 1"/>
      </material>
    </visual>
    <collision>
      <origin xyz="0.0845 0.288767 0.0732859" rpy="0 1.51844 -1.5708"/>
      <geometry>
        <mesh filename="package://assets/m6_threaded_bar_300mm.stl"/>
      </geometry>
    </collision>
    <!-- Part stator_x4_p36_36_unified_10 -->
    <visual>
      <origin xyz="-0.018 0.235 0.055" rpy="-3.14159 -1.5708 0"/>
      <geometry>
        <mesh filename="package://assets/stator_x4_p36_36_unified.stl"/>
      </geometry>
      <material name="stator_x4_p36_36_unified_10_material">
        <color rgba="0.764706 0.545098 0.803922 1"/>
      </material>
    </visual>
    <collision>
      <origin xyz="-0.018 0.235 0.055" rpy="-3.14159 -1.5708 0"/>
      <geometry>
        <mesh filename="package://assets/stator_x4_p36_36_unified.stl"/>
      </geometry>
    </collision>
  </link>
  <!-- Link udrf_ankle_assembly_2 -->
  <link name="udrf_ankle_assembly_2">
    <inertial>
      <origin xyz="-0 0.0125426 -0.004" rpy="0 0 0"/>
      <mass value="0.0818219"/>
      <inertia ixx="1.69449e-05" ixy="0" ixz="0" iyy="1.25404e-05" iyz="0" izz="2.15245e-05"/>
    </inertial>
    <!-- Part udrf_ankle_assembly_2 -->
    <visual>
      <origin xyz="-0 0.0125426 -0.004" rpy="1.5708 1.5708 0"/>
      <geometry>
        <mesh filename="package://assets/udrf_ankle_assembly.stl"/>
      </geometry>
      <material name="udrf_ankle_assembly_2_material">
        <color rgba="0.615686 0.811765 0.929412 1"/>
      </material>
    </visual>
    <collision>
      <origin xyz="-0 0.0125426 -0.004" rpy="1.5708 1.5708 0"/>
      <geometry>
        <mesh filename="package://assets/udrf_ankle_assembly.stl"/>
      </geometry>
    </collision>
  </link>
  <!-- Link urdf_foot_assembly_2 -->
  <link name="urdf_foot_assembly_2">
    <inertial>
      <origin xyz="-9.74e-10 0.0209668 0.0427639" rpy="0 0 0"/>
      <mass value="0.504"/>
      <inertia ixx="0.00202397" ixy="-1.6e-11" ixz="1.2e-11" iyy="0.00229243" iyz="5.90887e-06" izz="0.000361698"/>
    </inertial>
    <!-- Part urdf_foot_assembly_2 -->
    <visual>
      <origin xyz="5.5e-11 0.0209668 0.0427639" rpy="1.5708 0 0"/>
      <geometry>
        <mesh filename="package://assets/urdf_foot_assembly.stl"/>
      </geometry>
      <material name="urdf_foot_assembly_2_material">
        <color rgba="0.615686 0.811765 0.929412 1"/>
      </material>
    </visual>
    <collision>
      <origin xyz="5.5e-11 0.0209668 0.0427639" rpy="1.5708 0 0"/>
      <geometry>
        <mesh filename="package://assets/urdf_foot_assembly.stl"/>
      </geometry>
    </collision>
  </link>
  <!-- Joint from udrf_ankle_assembly_2 to urdf_foot_assembly_2 -->
  <joint name="right_ankle_pitch_joint" type="revolute">
    <origin xyz="-0.012 0.028 -0.004" rpy="0 1.5708 0"/>
    <parent link="udrf_ankle_assembly_2"/>
    <child link="urdf_foot_assembly_2"/>
    <axis xyz="0 0 1"/>
    <limit effort="10" velocity="10" lower="-0.785398" upper="0.785398"/>
  </joint>
  <!-- Joint from urdf_r_tibia_assembly to udrf_ankle_assembly_2 -->
  <joint name="right_ankle_roll_joint" type="revolute">
    <origin xyz="0 0.395 0.059" rpy="0 -0 0"/>
    <parent link="urdf_r_tibia_assembly"/>
    <child link="udrf_ankle_assembly_2"/>
    <axis xyz="0 0 1"/>
    <limit effort="10" velocity="10" lower="-0.785398" upper="0.785398"/>
  </joint>
  <!-- Joint from urdf_lower_femur_assembly_2 to urdf_r_tibia_assembly -->
  <joint name="right_knee_joint" type="revolute">
    <origin xyz="0.055 -0 0.113" rpy="1.5708 0 -1.5708"/>
    <parent link="urdf_lower_femur_assembly_2"/>
    <child link="urdf_r_tibia_assembly"/>
    <axis xyz="0 0 1"/>
    <limit effort="10" velocity="10" lower="-0.174533" upper="1.5708"/>
  </joint>
  <!-- Joint from urdf_r_upper_femur_assemby to urdf_lower_femur_assembly_2 -->
  <joint name="right_hip_yaw_joint" type="revolute">
    <origin xyz="0 0.217 -0.053" rpy="-1.5708 0 -0"/>
    <parent link="urdf_r_upper_femur_assemby"/>
    <child link="urdf_lower_femur_assembly_2"/>
    <axis xyz="0 0 1"/>
    <limit effort="10" velocity="10" lower="-1.5708" upper="1.5708"/>
  </joint>
  <!-- Joint from urdf_hip_assembly_2 to urdf_r_upper_femur_assemby -->
  <joint name="right_hip_roll_joint" type="revolute">
    <origin xyz="0.055 0 0.078" rpy="-3.14159 -1.5708 0"/>
    <parent link="urdf_hip_assembly_2"/>
    <child link="urdf_r_upper_femur_assemby"/>
    <axis xyz="0 0 1"/>
    <limit effort="10" velocity="10" lower="-3.14159" upper="0.349066"/>
  </joint>
  <!-- Joint from urdf_base to urdf_hip_assembly_2 -->
  <joint name="right_hip_pitch_joint" type="revolute">
    <origin xyz="0.107699 0.0333787 -0.467748" rpy="1.5708 -0 1.5708"/>
    <parent link="urdf_base"/>
    <child link="urdf_hip_assembly_2"/>
    <axis xyz="0 0 1"/>
    <limit effort="10" velocity="10" lower="-2.53073" upper="1.5708"/>
  </joint>
</robot>
