<?xml version='1.0' encoding='us-ascii'?>
<mujoco model="robot_harambe">
  <compiler angle="radian" meshdir="assets/" />

  <asset>
    <mesh name="stator_x8_p20_120_unified" content_type="model/stl" file="stator_x8_p20_120_unified.stl" />
    <mesh name="b_base" content_type="model/stl" file="b_base.stl" />
    <mesh name="f_base" content_type="model/stl" file="f_base.stl" />
    <mesh name="urdf_r_plate_shoulder_with_limiter_pla" content_type="model/stl" file="urdf_r_plate_shoulder_with_limiter_pla.stl" />
    <mesh name="urdf_l_plate_shoulder_with_limiter_pla" content_type="model/stl" file="urdf_l_plate_shoulder_with_limiter_pla.stl" />
    <mesh name="stator_x6_p20_60_unified" content_type="model/stl" file="stator_x6_p20_60_unified.stl" />
    <mesh name="urdf_simplified_torso" content_type="model/stl" file="urdf_simplified_torso.stl" />
    <mesh name="urdf_torso_pelvis_plate_pla" content_type="model/stl" file="urdf_torso_pelvis_plate_pla.stl" />
    <mesh name="head" content_type="model/stl" file="head.stl" />
    <mesh name="back_access" content_type="model/stl" file="back_access.stl" />
    <mesh name="l_shoulder" content_type="model/stl" file="l_shoulder.stl" />
    <mesh name="arm_limiter" content_type="model/stl" file="arm_limiter.stl" />
    <mesh name="l_upper_arm" content_type="model/stl" file="l_upper_arm.stl" />
    <mesh name="stator_x4_p36_36_unified" content_type="model/stl" file="stator_x4_p36_36_unified.stl" />
    <mesh name="elbow_limiter" content_type="model/stl" file="elbow_limiter.stl" />
    <mesh name="l_elbow" content_type="model/stl" file="l_elbow.stl" />
    <mesh name="forearm_limiter" content_type="model/stl" file="forearm_limiter.stl" />
    <mesh name="l_upper_forearm" content_type="model/stl" file="l_upper_forearm.stl" />
    <mesh name="hand_limiter" content_type="model/stl" file="hand_limiter.stl" />
    <mesh name="l_lower_forearm" content_type="model/stl" file="l_lower_forearm.stl" />
    <mesh name="l_wrist" content_type="model/stl" file="l_wrist.stl" />
    <mesh name="l_hand" content_type="model/stl" file="l_hand.stl" />
    <mesh name="r_shoulder" content_type="model/stl" file="r_shoulder.stl" />
    <mesh name="r_upper_arm" content_type="model/stl" file="r_upper_arm.stl" />
    <mesh name="r_elbow" content_type="model/stl" file="r_elbow.stl" />
    <mesh name="r_upper_forearm" content_type="model/stl" file="r_upper_forearm.stl" />
    <mesh name="r_lower_forearm" content_type="model/stl" file="r_lower_forearm.stl" />
    <mesh name="r_hand" content_type="model/stl" file="r_hand.stl" />
    <mesh name="r_wrist" content_type="model/stl" file="r_wrist.stl" />
    <mesh name="hip" content_type="model/stl" file="hip.stl" />
    <mesh name="l_upper_femur" content_type="model/stl" file="l_upper_femur.stl" />
    <mesh name="rotor_x8_p20_120" content_type="model/stl" file="rotor_x8_p20_120.stl" />
    <mesh name="stator_x8_p20_120" content_type="model/stl" file="stator_x8_p20_120.stl" />
    <mesh name="lower_femur" content_type="model/stl" file="lower_femur.stl" />
    <mesh name="m6_threaded_bar_300mm" content_type="model/stl" file="m6_threaded_bar_300mm.stl" />
    <mesh name="m6_threaded_bar_225mm" content_type="model/stl" file="m6_threaded_bar_225mm.stl" />
    <mesh name="shoe" content_type="model/stl" file="shoe.stl" />
    <mesh name="lower_fixation_leg_lontrol" content_type="model/stl" file="lower_fixation_leg_lontrol.stl" />
    <mesh name="foot" content_type="model/stl" file="foot.stl" />
    <mesh name="spacer_bottom_tibia" content_type="model/stl" file="spacer_bottom_tibia.stl" />
    <mesh name="l_tibia" content_type="model/stl" file="l_tibia.stl" />
    <mesh name="m6_threaded_eye" content_type="model/stl" file="m6_threaded_eye.stl" />
    <mesh name="12_7mm_ball_with_6mm_hole" content_type="model/stl" file="12_7mm_ball_with_6mm_hole.stl" />
    <mesh name="rulment_d22_x_d8_x_t7" content_type="model/stl" file="rulment_d22_x_d8_x_t7.stl" />
    <mesh name="ankle_bearing_house" content_type="model/stl" file="ankle_bearing_house.stl" />
    <mesh name="rotor_x4_p36_36" content_type="model/stl" file="rotor_x4_p36_36.stl" />
    <mesh name="stator_x4_p36_36" content_type="model/stl" file="stator_x4_p36_36.stl" />
    <mesh name="lever_ankle" content_type="model/stl" file="lever_ankle.stl" />
    <mesh name="hex_nut_grade_a___b_m6x1__7468f1fe59412d2a2604ecf8e993c3bf" content_type="model/stl" file="hex_nut_grade_a___b_m6x1__7468f1fe59412d2a2604ecf8e993c3bf.stl" />
    <mesh name="spacer_lever_ankle" content_type="model/stl" file="spacer_lever_ankle.stl" />
    <mesh name="upper_ankle_shaft" content_type="model/stl" file="upper_ankle_shaft.stl" />
    <mesh name="ankle_ear" content_type="model/stl" file="ankle_ear.stl" />
    <mesh name="ankle_shaft" content_type="model/stl" file="ankle_shaft.stl" />
    <mesh name="r_upper_femur" content_type="model/stl" file="r_upper_femur.stl" />
    <mesh name="r_tibia" content_type="model/stl" file="r_tibia.stl" />
  </asset>

  <worldbody>
    <body name="urdf_base">
      <inertial pos="0.000699269 0.0334604 -0.431702" quat="0.707094 -0.00116708 0.000361561 0.707118" mass="5.132" diaginertia="0.0288849 0.0213139 0.0155351" />
      <joint name="floating_base" type="free" />
      <geom pos="-0.0103011 0.0333787 -0.467748" quat="0.270596 -0.653281 -0.270601 0.653281" type="mesh" rgba="0.882353 0.572549 0.478431 1" mesh="stator_x8_p20_120_unified" />
      <geom pos="0.000697952 -0.00271429 -0.432504" quat="1 0 0 0" type="mesh" rgba="0.368627 0.25098 0.643137 1" mesh="b_base" />
      <geom pos="0.0116989 0.0333787 -0.467748" quat="0.270596 0.653281 0.270601 0.653281" type="mesh" rgba="0.882353 0.572549 0.478431 1" mesh="stator_x8_p20_120_unified" />
      <geom pos="0.000698852 0.0333787 -0.396748" quat="1 0 0 0" type="mesh" rgba="0.882353 0.572549 0.478431 1" mesh="stator_x8_p20_120_unified" />
      <geom pos="0.000705351 0.070373 -0.431099" quat="1 0 0 0" type="mesh" rgba="0.909804 0.572549 0.164706 1" mesh="f_base" />
      <body name="urdf_simplified_torso_sub_assembly" pos="0.000698852 0.0333787 -0.300748" quat="1.32679e-06 1 0 0">
        <inertial pos="0.00587549 -0.00084485 -0.417851" quat="0.707102 -0.003486 0.00443143 0.707089" mass="9.22071" diaginertia="0.324474 0.220452 0.138142" />
        <joint name="waist_yaw_joint" pos="0 0 0" axis="0 0 1" range="-1.5708 1.5708" actuatorfrcrange="-10 10" />
        <geom pos="0.168755 -4.00834e-06 -0.427883" quat="1.32679e-06 -1 0 0" type="mesh" rgba="0.647059 0.647059 0.647059 1" mesh="urdf_r_plate_shoulder_with_limiter_pla" />
        <geom pos="-0.156752 -4.00839e-06 -0.427883" quat="1.32679e-06 1 0 0" type="mesh" rgba="0.615686 0.811765 0.929412 1" mesh="urdf_l_plate_shoulder_with_limiter_pla" />
        <geom pos="0.0990017 -4.00839e-06 -0.427" quat="9.38184e-07 -0.707105 -9.38187e-07 -0.707108" type="mesh" rgba="0.960784 0.835294 0.470588 1" mesh="stator_x6_p20_60_unified" />
        <geom pos="-0.0869983 -4.00839e-06 -0.427" quat="0.707105 0 -0.707108 0" type="mesh" rgba="0.960784 0.835294 0.470588 1" mesh="stator_x6_p20_60_unified" />
        <geom pos="0.00600172 -4.00844e-06 -0.2625" quat="1.32679e-06 -1 0 0" type="mesh" rgba="0.647059 0.647059 0.647059 1" mesh="urdf_simplified_torso" />
        <geom pos="0 0 -0.005" quat="1.32679e-06 1 0 0" type="mesh" rgba="0.231373 0.380392 0.705882 1" mesh="urdf_torso_pelvis_plate_pla" />
        <geom pos="0.00635981 -4.18304e-05 -0.6725" quat="1.32679e-06 -1 0 0" type="mesh" rgba="0.737255 0.937255 0.917647 1" mesh="head" />
        <geom pos="0.00635981 -4.18304e-05 -0.674429" quat="1.32679e-06 -1 0 0" type="mesh" rgba="0.231373 0.380392 0.705882 1" mesh="back_access" />
        <body name="urdf_l_shoulder_assembly" pos="-0.169498 -4.00839e-06 -0.427" quat="0.499998 -0.5 0.500002 -0.5">
          <inertial pos="-0.00497539 -1.6622e-05 -0.06724" quat="0.999715 0.00810981 -0.0224209 -0.00137743" mass="3.07135" diaginertia="0.00354298 0.00313082 0.0029081" />
          <joint name="left_shoulder_pitch_joint_X6" pos="0 0 0" axis="0 0 1" range="-1.5708 3.14159" actuatorfrcrange="-10 10" />
          <geom pos="-0.00130076 -6.96521e-06 -0.0502746" quat="0.499998 -0.5 -0.5 -0.500002" type="mesh" rgba="0.615686 0.811765 0.929412 1" mesh="l_shoulder" />
          <geom pos="-0.0385 0 -0.07" quat="9.38184e-07 0.707105 -9.38187e-07 0.707108" type="mesh" rgba="0.960784 0.835294 0.470588 1" mesh="stator_x6_p20_60_unified" />
          <body name="urdf_l_upper_arm_assembly" pos="0.036 0 -0.07" quat="9.38184e-07 -0.707105 -9.38187e-07 -0.707108">
            <inertial pos="0.00100127 0.105781 -0.0355919" quat="0.588053 0.365527 -0.402904 0.598541" mass="0.822" diaginertia="0.00221504 0.002152 0.000872758" />
            <joint name="left_shoulder_roll_joint_X6" pos="0 0 0" axis="0 0 1" range="0 3.14159" actuatorfrcrange="-10 10" />
            <geom pos="0.0411507 0.158216 -0.0675144" quat="0.707105 0.707108 0 0" type="mesh" rgba="1 0.756863 0.054902 1" mesh="arm_limiter" />
            <geom pos="6.2547e-08 0.0912885 -0.0256703" quat="0.707105 0.707108 0 0" type="mesh" rgba="0.231373 0.380392 0.705882 1" mesh="l_upper_arm" />
            <geom pos="0 0.091 -0.046" quat="0.707105 -0.707108 0 0" type="mesh" rgba="0.764706 0.545098 0.803922 1" mesh="stator_x4_p36_36_unified" />
            <body name="urdf_l_elbow_assembly" pos="0 0.17 -0.046" quat="0.707105 0.707108 0 0">
              <inertial pos="0.00994774 -0.000233513 -0.0631484" quat="0.991046 0.0604271 -0.115292 -0.0297511" mass="2.98735" diaginertia="0.00317971 0.00298622 0.00261738" />
              <joint name="left_shoulder_yaw_joint_X4" pos="0 0 0" axis="0 0 1" range="-2.35619 2.35619" actuatorfrcrange="-10 10" />
              <geom pos="-0.0364319 -0.0350673 -0.00907087" quat="1 0 0 0" type="mesh" rgba="1 0.756863 0.054902 1" mesh="elbow_limiter" />
              <geom pos="0.0445 0 -0.065" quat="9.38184e-07 0.707105 9.38187e-07 -0.707108" type="mesh" rgba="0.960784 0.835294 0.470588 1" mesh="stator_x6_p20_60_unified" />
              <geom pos="-0.000331628 1.15447e-05 -0.0512953" type="mesh" rgba="0.796078 0.905882 0.745098 1" mesh="l_elbow" />
              <body name="urdf_l_upper_forearm_assembly" pos="-0.04 0 -0.065" quat="0.499998 0.5 0.500002 0.5">
                <inertial pos="0.00170771 -0.103744 0.0340287" quat="0.833026 0.552631 0.0125098 -0.0226004" mass="0.727" diaginertia="0.00176949 0.0017013 0.000599374" />
                <joint name="left_elbow_pitch_joint_X6" pos="0 0 0" axis="0 0 1" range="-1.5708 1.5708" actuatorfrcrange="-10 10" />
                <geom pos="-0.0189092 -0.156122 0.0747704" quat="0.499981 -0.500017 -0.499982 -0.500019" type="mesh" rgba="1 0.756863 0.054902 1" mesh="forearm_limiter" />
                <geom pos="0.0046701 -0.0842108 0.0254855" quat="0.499998 -0.5 -0.5 -0.500002" type="mesh" rgba="0.890196 0.698039 0.639216 1" mesh="l_upper_forearm" />
                <geom pos="0 -0.09 0.04" quat="0.499998 0.5 -0.5 0.500002" type="mesh" rgba="0.764706 0.545098 0.803922 1" mesh="stator_x4_p36_36_unified" />
                <body name="urdf_l_lower_forearm_assembly" pos="0 -0.168 0.04" quat="0.499998 -0.5 -0.5 -0.500002">
                  <inertial pos="-0.00114678 -0.00570813 -0.0477193" quat="0.950749 -0.0131424 -0.0972779 -0.294009" mass="0.553" diaginertia="0.000534676 0.000516804 0.000385711" />
                  <joint name="left_wrist_yaw_joint_X4" pos="0 0 0" axis="0 0 1" range="-2.35619 2.35619" actuatorfrcrange="-10 10" />
                  <geom pos="-0.0317086 -0.0248862 -0.00779106" quat="1 -3.71337e-05 -1.4695e-08 0" type="mesh" rgba="1 0.756863 0.054902 1" mesh="hand_limiter" />
                  <geom pos="-3.7846e-08 0.00198299 -0.0340631" quat="1 0 0 0" type="mesh" rgba="0.941176 0.87451 0.678431 1" mesh="l_lower_forearm" />
                  <geom pos="0 -0.038 -0.0565" quat="9.38184e-07 9.38187e-07 0.707108 0.707105" type="mesh" rgba="0.764706 0.545098 0.803922 1" mesh="stator_x4_p36_36_unified" />
                  <body name="urdf_l_wrist_assembly" pos="0 0.033 -0.0565" quat="0.707105 0.707108 0 0">
                    <inertial pos="-1.08315e-06 -0.112614 0.0282716" quat="0.72344 0.690387 2.13501e-05 -9.61983e-06" mass="0.398" diaginertia="0.00160501 0.00146798 0.000272251" />
                    <joint name="left_wrist_roll_joint_X4" pos="0 0 0" axis="0 0 1" range="-1.5708 1.5708" actuatorfrcrange="-10 10" />
                    <geom pos="-4.31502e-06 -0.0434653 0.0219314" quat="0.707105 -0.707108 0 0" type="mesh" rgba="0.8 0.74902 0.913725 1" mesh="l_wrist" />
                    <geom pos="-2.67e-09 -0.135203 0.0303429" quat="0.499998 -0.5 0.5 0.500002" type="mesh" rgba="1 1 1 1" mesh="l_hand" />
                  </body>
                </body>
              </body>
            </body>
          </body>
        </body>
        <body name="urdf_r_shoulder_assembly" pos="0.181502 -4.00839e-06 -0.427" quat="0.499998 0.5 -0.500002 -0.5">
          <inertial pos="-0.00525946 9.07501e-06 -0.0685921" quat="0.999812 -0.00891254 -0.0171965 0.00120203" mass="2.84535" diaginertia="0.00278256 0.00253765 0.00243356" />
          <joint name="right_shoulder_pitch_joint_X6" pos="0 0 0" axis="0 0 1" range="-3.14159 1.5708" actuatorfrcrange="-10 10" />
          <geom pos="-0.0385 0 -0.07" quat="0.707105 0 0.707108 0" type="mesh" rgba="0.960784 0.835294 0.470588 1" mesh="stator_x6_p20_60_unified" />
          <geom pos="-0.00129067 6.91178e-06 -0.0501448" quat="0.499998 0.5 0.5 -0.500002" type="mesh" rgba="0.615686 0.811765 0.929412 1" mesh="r_shoulder" />
          <body name="urdf_r_upper_arm_assembly" pos="0.041 0 -0.07" quat="9.38184e-07 -0.707105 9.38187e-07 0.707108">
            <inertial pos="-9.416e-09 -0.104084 0.0297331" quat="0.591533 0.387413 -0.387413 0.591533" mass="0.802" diaginertia="0.00209028 0.00204755 0.000811569" />
            <joint name="right_shoulder_roll_joint_X6" pos="0 0 0" axis="0 0 1" range="0 3.14159" actuatorfrcrange="-10 10" />
            <geom pos="0 -0.091 0.041" quat="0.707105 0.707108 0 0" type="mesh" rgba="0.764706 0.545098 0.803922 1" mesh="stator_x4_p36_36_unified" />
            <geom pos="-4.6857e-08 -0.0905315 0.020543" quat="0.707105 -0.707108 0 0" type="mesh" rgba="0.231373 0.380392 0.705882 1" mesh="r_upper_arm" />
            <body name="urdf_r_elbow_assembly" pos="0 -0.17 0.041" quat="0.707105 -0.707108 0 0">
              <inertial pos="-0.010381 1.19265e-05 -0.0635916" quat="0.99734 -0.00404936 0.0727762 0.000210321" mass="2.93435" diaginertia="0.0029758 0.00279049 0.00249856" />
              <joint name="right_shoulder_yaw_joint_X4" pos="0 0 0" axis="0 0 1" range="-2.35619 2.35619" actuatorfrcrange="-10 10" />
              <geom pos="0.000331582 1.16025e-05 -0.0512953" type="mesh" rgba="0.796078 0.905882 0.745098 1" mesh="r_elbow" />
              <geom pos="-0.0445 0 -0.065" quat="9.38184e-07 -0.707105 -9.38187e-07 -0.707108" type="mesh" rgba="0.960784 0.835294 0.470588 1" mesh="stator_x6_p20_60_unified" />
              <body name="urdf_r_upper_forearm_assembly" pos="0.04 0 -0.065" quat="0.499998 -0.5 -0.500002 0.5">
                <inertial pos="0.00228064 0.101792 0.0327896" quat="0.560912 0.827219 0.0216668 -0.024842" mass="0.707" diaginertia="0.00166967 0.00158973 0.000563186" />
                <joint name="right_elbow_pitch_joint_X6" pos="0 0 0" axis="0 0 1" range="-1.5708 1.5708" actuatorfrcrange="-10 10" />
                <geom pos="0 0.09 0.04" quat="0.499998 -0.5 0.5 0.500002" type="mesh" rgba="0.764706 0.545098 0.803922 1" mesh="stator_x4_p36_36_unified" />
                <geom pos="0.00466986 0.0842107 0.0254856" quat="0.499998 0.5 0.5 -0.500002" type="mesh" rgba="0.890196 0.698039 0.639216 1" mesh="r_upper_forearm" />
                <body name="urdf_r_lower_forearm_assembly" pos="0 0.168 0.04" quat="0.499998 0.5 0.5 -0.500002">
                  <inertial pos="-2.4334e-08 -0.00399848 -0.046852" quat="0.703527 -0.0712082 0.071207 0.703497" mass="0.618" diaginertia="0.000625145 0.000618602 0.000429937" />
                  <joint name="right_wrist_yaw_joint_X4" pos="0 0 0" axis="0 0 1" range="-2.35619 2.35619" actuatorfrcrange="-10 10" />
                  <geom pos="4.2712e-08 0.00205797 -0.0333447" quat="1 0 0 0" type="mesh" rgba="0.941176 0.87451 0.678431 1" mesh="r_lower_forearm" />
                  <geom pos="0 -0.038 -0.0565" quat="9.38184e-07 9.38187e-07 0.707108 0.707105" type="mesh" rgba="0.764706 0.545098 0.803922 1" mesh="stator_x4_p36_36_unified" />
                  <body name="urdf_r_wrist_assembly" pos="0 0.033 -0.0565" quat="0.707105 0.707108 0 0">
                    <inertial pos="1.54616e-06 -0.104482 0.0275327" quat="0.730104 0.683336 -2.63731e-05 1.26727e-05" mass="0.45" diaginertia="0.001889 0.00174181 0.00032089" />
                    <joint name="right_wrist_roll_joint_X4" pos="0 0 0" axis="0 0 1" range="-1.5708 1.5708" actuatorfrcrange="-10 10" />
                    <geom pos="2.67e-09 -0.135003 0.0303429" quat="0.499998 -0.5 -0.5 -0.500002" type="mesh" rgba="1 1 1 1" mesh="r_hand" />
                    <geom pos="4.44584e-06 -0.0434653 0.0219316" quat="0.707105 -0.707108 0 0" type="mesh" rgba="0.8 0.74902 0.913725 1" mesh="r_wrist" />
                  </body>
                </body>
              </body>
            </body>
          </body>
        </body>
      </body>
      <body name="urdf_hip_assembly" pos="-0.111301 0.0333787 -0.467748" quat="0.499998 0.5 0.500002 0.5">
        <inertial pos="-0.00420762 -6.23945e-06 -0.0689982" quat="0.999876 0.00121969 0.0156716 5.48896e-06" mass="1.73" diaginertia="0.00302373 0.00263533 0.00228673" />
        <joint name="left_hip_pitch_joint" pos="0 0 0" axis="0 0 1" range="-1.5708 2.53073" actuatorfrcrange="-10 10" />
        <geom pos="0.00253653 -3.27638e-05 -0.0520203" quat="0.499998 -0.5 -0.5 -0.500002" type="mesh" rgba="0.0627451 0.266667 0.490196 1" mesh="hip" />
        <geom pos="-0.043 0 -0.073" quat="0.707105 0 0.707108 0" type="mesh" rgba="0.882353 0.572549 0.478431 1" mesh="stator_x8_p20_120_unified" />
        <body name="urdf_l_upper_femur_assembly" pos="0.055 0 -0.073" quat="0.707105 0 -0.707108 0">
          <inertial pos="-0.000406021 -0.148741 0.0457109" quat="0.805124 0.537059 -0.131809 0.214403" mass="1.912" diaginertia="0.00563412 0.00558368 0.00296734" />
          <joint name="left_hip_roll_joint" pos="0 0 0" axis="0 0 1" range="-3.14159 0.349066" actuatorfrcrange="-10 10" />
          <geom pos="-0.00151622 -0.111785 0.0257799" quat="0.707105 -0.707108 0 0" type="mesh" rgba="0.141176 0.694118 0.65098 1" mesh="l_upper_femur" />
          <geom pos="0 -0.124 0.053" quat="-0.147602 -0.147603 0.691531 -0.691529" type="mesh" rgba="0.596078 0.176471 0.0509804 1" mesh="rotor_x8_p20_120" />
          <geom pos="0 -0.124 0.053" quat="0.707105 0.707108 0 0" type="mesh" rgba="0.882353 0.572549 0.478431 1" mesh="stator_x8_p20_120" />
          <body name="urdf_lower_femur_assembly" pos="0 -0.217 0.053" quat="0.707105 -0.707108 0 0">
            <inertial pos="0.00357383 -1.0389e-08 -0.103307" quat="0.998247 -8.1112e-06 -0.0591836 -3.54611e-06" mass="1.817" diaginertia="0.00424172 0.00383469 0.00256196" />
            <joint name="left_hip_yaw_joint" pos="0 0 0" axis="0 0 1" range="-1.5708 1.5708" actuatorfrcrange="-10 10" />
            <geom pos="-0.00389134 5.752e-09 -0.070766" type="mesh" rgba="0.380392 0.0470588 0.435294 1" mesh="lower_femur" />
            <geom pos="0.043 0 -0.113" quat="0.707105 0 -0.707108 0" type="mesh" rgba="0.882353 0.572549 0.478431 1" mesh="stator_x8_p20_120_unified" />
            <body name="urdf_l_tibia_assembly" pos="-0.055 0 -0.113" quat="0.499998 0.5 0.500002 0.5">
              <inertial pos="0.0213653 -0.249179 0.0506862" quat="0.562887 0.496588 -0.472961 0.461375" mass="4.97481" diaginertia="0.0907335 0.0759647 0.0207684" />
              <joint name="left_knee_joint" pos="0 0 0" axis="0 0 1" range="0 1.5708" actuatorfrcrange="-10 10" />
              <geom pos="0.08085 -0.287625 0.0729994" quat="0.724092 -0.682919 0.0787879 0.0557224" type="mesh" rgba="0.141176 0.0352941 0.396078 1" mesh="m6_threaded_bar_300mm" />
              <geom pos="0.08085 -0.325171 0.0360012" quat="-0.0390271 0.080963 0.725749 0.682063" type="mesh" rgba="0.27451 0.0117647 0.317647 1" mesh="m6_threaded_bar_225mm" />
              <geom pos="0.0303243 -0.449431 0.054" quat="0.499998 -0.5 -0.5 -0.500002" type="mesh" rgba="0.0862745 0.321569 0.580392 1" mesh="shoe" />
              <geom pos="0.0565 -0.424448 0.054" quat="0.499998 -0.5 -0.5 -0.500002" type="mesh" rgba="0.615686 0.811765 0.929412 1" mesh="lower_fixation_leg_lontrol" />
              <geom pos="0.030138 -0.444982 0.054" quat="0.499998 -0.5 -0.5 -0.500002" type="mesh" rgba="0.615686 0.811765 0.929412 1" mesh="foot" />
              <geom pos="0 -0.3755 0.055" quat="0.499998 -0.5 -0.5 -0.500002" type="mesh" rgba="0.615686 0.811765 0.929412 1" mesh="spacer_bottom_tibia" />
              <geom pos="0.000691668 -0.182574 0.0429128" quat="0.499998 -0.5 -0.5 -0.500002" type="mesh" rgba="0.513725 0.415686 0.733333 1" mesh="l_tibia" />
              <geom pos="0.076 -0.415 0.042" quat="9.38184e-07 -0.707105 -9.38187e-07 -0.707108" type="mesh" rgba="0.615686 0.811765 0.929412 1" mesh="m6_threaded_eye" />
              <geom pos="0.076 -0.415 0.042" quat="0.0428106 0.763901 0.000877305 0.643911" type="mesh" rgba="0.647059 0.647059 0.647059 1" mesh="12_7mm_ball_with_6mm_hole" />
              <geom pos="0.0165 -0.423 0.054" quat="0.499998 0.5 -0.5 0.500002" type="mesh" rgba="0.901961 0.901961 0.901961 1" mesh="rulment_d22_x_d8_x_t7" />
              <geom pos="0.0191799 -0.428357 0.054" quat="0.499998 -0.5 -0.5 -0.500002" type="mesh" rgba="0.615686 0.811765 0.929412 1" mesh="ankle_bearing_house" />
              <geom pos="0.076 -0.415 0.066" quat="9.38184e-07 -0.707105 -9.38187e-07 -0.707108" type="mesh" rgba="0.615686 0.811765 0.929412 1" mesh="m6_threaded_eye" />
              <geom pos="0.076 -0.415 0.066" quat="0.0291116 -0.994907 0.0163096 0.0951131" type="mesh" rgba="0.647059 0.647059 0.647059 1" mesh="12_7mm_ball_with_6mm_hole" />
              <geom pos="-0.0165 -0.423 0.054" quat="0.499998 0.5 0.5 -0.500002" type="mesh" rgba="0.901961 0.901961 0.901961 1" mesh="rulment_d22_x_d8_x_t7" />
              <geom pos="-0.0191799 -0.428357 0.054" quat="0.499998 -0.5 0.5 0.500002" type="mesh" rgba="0.615686 0.811765 0.929412 1" mesh="ankle_bearing_house" />
              <geom pos="0 -0.395 0.0445" quat="9.38184e-07 9.38187e-07 -0.707108 -0.707105" type="mesh" rgba="0.901961 0.901961 0.901961 1" mesh="rulment_d22_x_d8_x_t7" />
              <geom pos="0 -0.389643 0.0418201" quat="9.38184e-07 -9.38187e-07 0.707108 -0.707105" type="mesh" rgba="0.615686 0.811765 0.929412 1" mesh="ankle_bearing_house" />
              <geom pos="-0.018 -0.16 0.055" quat="9.38184e-07 0.707105 -9.38187e-07 0.707108" type="mesh" rgba="0.380392 0.0470588 0.435294 1" mesh="rotor_x4_p36_36" />
              <geom pos="-0.018 -0.16 0.055" quat="9.38184e-07 0.707105 -9.38187e-07 0.707108" type="mesh" rgba="0.764706 0.545098 0.803922 1" mesh="stator_x4_p36_36" />
              <geom pos="-0.018 -0.235 0.055" quat="0.707105 0 0.707108 0" type="mesh" rgba="0.380392 0.0470588 0.435294 1" mesh="rotor_x4_p36_36" />
              <geom pos="-0.018 -0.235 0.055" quat="0.707105 0 0.707108 0" type="mesh" rgba="0.764706 0.545098 0.803922 1" mesh="stator_x4_p36_36" />
              <geom pos="0 -0.395 0.0655" quat="0.707105 -0.707108 0 0" type="mesh" rgba="0.901961 0.901961 0.901961 1" mesh="rulment_d22_x_d8_x_t7" />
              <geom pos="0 -0.389643 0.0681799" quat="0.707105 0.707108 0 0" type="mesh" rgba="0.615686 0.811765 0.929412 1" mesh="ankle_bearing_house" />
              <geom pos="0.066 -0.235073 0.0496487" quat="0.503411 0.496565 -0.496563 0.503413" type="mesh" rgba="0.615686 0.811765 0.929412 1" mesh="lever_ankle" />
              <geom pos="0.0701 -0.235342 0.0300023" quat="0.00483975 0.70709 0.00484494 0.70709" type="mesh" rgba="0.603922 0.647059 0.686275 1" mesh="hex_nut_grade_a___b_m6x1__7468f1fe59412d2a2604ecf8e993c3bf" />
              <geom pos="0.05375 -0.235 0.055" quat="0.503411 0.496565 -0.496563 0.503413" type="mesh" rgba="0.615686 0.811765 0.929412 1" mesh="spacer_lever_ankle" />
              <geom pos="0.066 -0.160053 0.0603516" quat="0.502492 -0.497496 0.497494 0.502494" type="mesh" rgba="0.615686 0.811765 0.929412 1" mesh="lever_ankle" />
              <geom pos="0.0701 -0.16025 0.0799988" quat="0.707098 0.00353422 0.707098 0.00353422" type="mesh" rgba="0.603922 0.647059 0.686275 1" mesh="hex_nut_grade_a___b_m6x1__7468f1fe59412d2a2604ecf8e993c3bf" />
              <geom pos="0.05375 -0.16 0.055" quat="0.502492 -0.497496 0.497494 0.502494" type="mesh" rgba="0.615686 0.811765 0.929412 1" mesh="spacer_lever_ankle" />
              <geom pos="0.0857 -0.235342 0.0300023" quat="0.00483975 0.70709 0.00484494 0.70709" type="mesh" rgba="0.615686 0.811765 0.929412 1" mesh="m6_threaded_eye" />
              <geom pos="0.0857 -0.235342 0.0300023" quat="0.0296531 0.0848459 0.0308918 0.995474" type="mesh" rgba="0.647059 0.647059 0.647059 1" mesh="12_7mm_ball_with_6mm_hole" />
              <geom pos="0.0857 -0.16025 0.0799988" quat="0.707098 0.00353422 0.707098 0.00353422" type="mesh" rgba="0.615686 0.811765 0.929412 1" mesh="m6_threaded_eye" />
              <geom pos="0.0857 -0.16025 0.0799988" quat="-0.0951131 0.0163113 0.994907 0.0291117" type="mesh" rgba="0.647059 0.647059 0.647059 1" mesh="12_7mm_ball_with_6mm_hole" />
              <geom pos="0 -0.395 0.054" quat="0.500001 -0.499997 -0.500001 -0.500001" type="mesh" rgba="0.615686 0.811765 0.929412 1" mesh="upper_ankle_shaft" />
              <geom pos="0 -0.404172 0.054" quat="0.500001 -0.499997 -0.500001 -0.500001" type="mesh" rgba="0.615686 0.811765 0.929412 1" mesh="ankle_ear" />
              <geom pos="0 -0.423 0.0539999" quat="0.500001 -0.499997 -0.500001 -0.500001" type="mesh" rgba="0.615686 0.811765 0.929412 1" mesh="ankle_shaft" />
              <body name="ankle_assembly" pos="0 -0.395 0.03" quat="1.32679e-06 -1 0 0">
                <inertial pos="0 0.0125447 -0.024" quat="0.5 0.5 -0.5 0.5" mass="0.0816337" diaginertia="2.14344e-05 1.68911e-05 1.24715e-05" />
                <joint name="left_ankle_pitch_joint" pos="0 0 0" axis="0 0 1" range="-0.785398 0.785398" actuatorfrcrange="-10 10" />
                <geom pos="0 0 -0.024" quat="0.499998 0.5 0.5 -0.500002" type="mesh" rgba="0.615686 0.811765 0.929412 1" mesh="upper_ankle_shaft" />
                <geom pos="0 0.00917229 -0.024" quat="0.499998 0.5 0.5 -0.500002" type="mesh" rgba="0.615686 0.811765 0.929412 1" mesh="ankle_ear" />
                <geom pos="0 0.028 -0.024" quat="0.499998 0.5 0.5 -0.500002" type="mesh" rgba="0.615686 0.811765 0.929412 1" mesh="ankle_shaft" />
              </body>
            </body>
          </body>
        </body>
      </body>
      <body name="urdf_hip_assembly_2" pos="0.107699 0.0333787 -0.467748" quat="0.499998 -0.5 -0.500002 0.5">
        <inertial pos="-0.00420719 6.05312e-05 -0.0739982" quat="0.999845 0.00134403 0.0156616 -0.00792813" mass="1.73" diaginertia="0.00302373 0.00263533 0.00228673" />
        <joint name="right_hip_pitch_joint" pos="0 0 0" axis="0 0 1" range="-2.51486 1.58667" actuatorfrcrange="-10 10" />
        <geom pos="0.00253569 -7.30113e-05 -0.0570203" quat="0.496015 -0.503952 -0.496017 -0.503954" type="mesh" rgba="0.0627451 0.266667 0.490196 1" mesh="hip" />
        <geom pos="-0.0429946 0.000682358 -0.078" quat="0.707083 0.00561065 0.707086 -0.00561067" type="mesh" rgba="0.882353 0.572549 0.478431 1" mesh="stator_x8_p20_120_unified" />
        <body name="urdf_r_upper_femur_assemby" pos="0.0549931 -0.000872784 -0.078" quat="-0.00506674 0.70708 -0.00616012 -0.707089">
          <inertial pos="0.000405705 -0.147963 0.0457092" quat="0.818228 0.541022 0.0994274 -0.167067" mass="1.912" diaginertia="0.00558398 0.00552262 0.00296637" />
          <joint name="right_hip_roll_joint" pos="0 0 0" axis="0 0 1" range="-0.35061 3.14005" actuatorfrcrange="-10 10" />
          <geom pos="0.00151505 -0.111761 0.0257733" quat="0.707105 -0.707108 0 0" type="mesh" rgba="0.941176 0.87451 0.678431 1" mesh="r_upper_femur" />
          <geom pos="0 -0.124 0.053" quat="0.707105 0.707108 0 0" type="mesh" rgba="0.882353 0.572549 0.478431 1" mesh="stator_x8_p20_120_unified" />
          <body name="urdf_lower_femur_assembly_2" pos="0 -0.217 0.053" quat="0.707105 -0.707108 0 0">
            <inertial pos="-0.00357383 -7.8699e-08 -0.103307" quat="0.998247 7.37345e-06 0.0591836 8.89496e-06" mass="1.817" diaginertia="0.00424172 0.00383469 0.00256196" />
            <joint name="right_hip_yaw_joint" pos="0 0 0" axis="0 0 1" range="-1.57082 1.57077" actuatorfrcrange="-10 10" />
            <geom pos="0.00389134 9.125e-08 -0.070766" quat="1.13268e-05 0 0 -1" type="mesh" rgba="0.380392 0.0470588 0.435294 1" mesh="lower_femur" />
            <geom pos="-0.043 -1.07189e-06 -0.113" quat="8.00924e-06 -0.707105 -8.00927e-06 -0.707108" type="mesh" rgba="0.882353 0.572549 0.478431 1" mesh="stator_x8_p20_120_unified" />
            <body name="urdf_r_tibia_assembly" pos="0.055 1.37102e-06 -0.113" quat="0.495631 -0.504319 -0.495645 0.504329">
              <inertial pos="0.0169442 0.269757 0.0604485" quat="0.749342 0.660111 0.017171 -0.0494367" mass="3.49223" diaginertia="0.0825346 0.0736776 0.0200966" />
              <joint name="right_knee_joint" pos="0 0 0" axis="0 0 1" range="-0.191906 2.33882" actuatorfrcrange="-10 10" />
              <geom pos="0.08085 0.325243 0.0370024" quat="0.678651 0.733926 0.0125362 0.0250558" type="mesh" rgba="0.27451 0.0117647 0.317647 1" mesh="m6_threaded_bar_225mm" />
              <geom pos="0.08085 0.287574 0.0739998" quat="0.597772 0.584688 -0.366935 0.407637" type="mesh" rgba="0.141176 0.0352941 0.396078 1" mesh="m6_threaded_bar_300mm" />
              <geom pos="0.000691468 0.182554 0.0429159" quat="0.499998 0.5 0.5 -0.500002" type="mesh" rgba="0.654902 0.823529 0.576471 1" mesh="r_tibia" />
              <geom pos="-0.018 0.16 0.055" quat="0.707105 0 0.707108 0" type="mesh" rgba="0.764706 0.545098 0.803922 1" mesh="stator_x4_p36_36_unified" />
              <geom pos="0 0.3755 0.055" quat="0.499998 0.5 0.5 -0.500002" type="mesh" rgba="0.615686 0.811765 0.929412 1" mesh="spacer_bottom_tibia" />
              <geom pos="-0.018 0.235 0.055" quat="9.38184e-07 0.707105 -9.38187e-07 0.707108" type="mesh" rgba="0.764706 0.545098 0.803922 1" mesh="stator_x4_p36_36_unified" />
              <geom pos="0.0303243 0.449431 0.056" quat="0.499998 0.5 0.5 -0.500002" type="mesh" rgba="0.0862745 0.321569 0.580392 1" mesh="shoe" />
              <geom pos="0.0565 0.424448 0.056" quat="0.499998 0.5 0.5 -0.500002" type="mesh" rgba="0.615686 0.811765 0.929412 1" mesh="lower_fixation_leg_lontrol" />
              <geom pos="0.030138 0.444982 0.056" quat="0.499998 0.5 0.5 -0.500002" type="mesh" rgba="0.615686 0.811765 0.929412 1" mesh="foot" />
              <geom pos="0.066 0.235104 0.0496492" quat="0.495109 0.504844 -0.504847 0.495106" type="mesh" rgba="0.615686 0.811765 0.929412 1" mesh="lever_ankle" />
              <geom pos="0.0701 0.235487 0.0300047" quat="0.00688322 -0.707073 0.00688841 -0.707073" type="mesh" rgba="0.603922 0.647059 0.686275 1" mesh="hex_nut_grade_a___b_m6x1__7468f1fe59412d2a2604ecf8e993c3bf" />
              <geom pos="0.05375 0.235 0.055" quat="0.495109 0.504844 -0.504847 0.495106" type="mesh" rgba="0.615686 0.811765 0.929412 1" mesh="spacer_lever_ankle" />
              <geom pos="0 0.395 0.0655" quat="9.38184e-07 -9.38187e-07 -0.707108 0.707105" type="mesh" rgba="0.901961 0.901961 0.901961 1" mesh="rulment_d22_x_d8_x_t7" />
              <geom pos="0 0.389643 0.0681799" quat="9.38184e-07 9.38187e-07 -0.707108 -0.707105" type="mesh" rgba="0.615686 0.811765 0.929412 1" mesh="ankle_bearing_house" />
              <geom pos="0.066 0.160032 0.0603518" quat="-0.498519 0.501477 -0.501477 -0.498518" type="mesh" rgba="0.615686 0.811765 0.929412 1" mesh="lever_ankle" />
              <geom pos="0.0701 0.160148 0.0799996" quat="0.707104 -0.00209173 0.707104 -0.00209173" type="mesh" rgba="0.603922 0.647059 0.686275 1" mesh="hex_nut_grade_a___b_m6x1__7468f1fe59412d2a2604ecf8e993c3bf" />
              <geom pos="0.05375 0.16 0.055" quat="0.49852 -0.501475 0.501478 0.498517" type="mesh" rgba="0.615686 0.811765 0.929412 1" mesh="spacer_lever_ankle" />
              <geom pos="0 0.395 0.0445" quat="0.707105 0.707108 0 0" type="mesh" rgba="0.901961 0.901961 0.901961 1" mesh="rulment_d22_x_d8_x_t7" />
              <geom pos="0 0.389643 0.0418201" quat="0.707105 -0.707108 0 0" type="mesh" rgba="0.615686 0.811765 0.929412 1" mesh="ankle_bearing_house" />
              <geom pos="0.076 0.415 0.068" quat="0.707105 0 0.707108 0" type="mesh" rgba="0.615686 0.811765 0.929412 1" mesh="m6_threaded_eye" />
              <geom pos="0.076 0.415 0.068" quat="-0.203944 -0.0138071 0.978516 -0.0268947" type="mesh" rgba="0.647059 0.647059 0.647059 1" mesh="12_7mm_ball_with_6mm_hole" />
              <geom pos="0.0165 0.423 0.056" quat="0.499998 -0.5 0.5 0.500002" type="mesh" rgba="0.901961 0.901961 0.901961 1" mesh="rulment_d22_x_d8_x_t7" />
              <geom pos="0.0191799 0.428357 0.056" quat="0.499998 0.5 0.5 -0.500002" type="mesh" rgba="0.615686 0.811765 0.929412 1" mesh="ankle_bearing_house" />
              <geom pos="0.076 0.415 0.044" quat="0.707105 0 0.707108 0" type="mesh" rgba="0.615686 0.811765 0.929412 1" mesh="m6_threaded_eye" />
              <geom pos="0.076 0.415 0.044" quat="0.700029 0.0464342 -0.712548 -0.00884376" type="mesh" rgba="0.647059 0.647059 0.647059 1" mesh="12_7mm_ball_with_6mm_hole" />
              <geom pos="-0.0165 0.423 0.056" quat="0.499998 -0.5 -0.5 -0.500002" type="mesh" rgba="0.901961 0.901961 0.901961 1" mesh="rulment_d22_x_d8_x_t7" />
              <geom pos="-0.0191799 0.428357 0.056" quat="0.499998 0.5 -0.5 0.500002" type="mesh" rgba="0.615686 0.811765 0.929412 1" mesh="ankle_bearing_house" />
              <geom pos="0.0857 0.235487 0.0300047" quat="0.00688322 -0.707073 0.00688841 -0.707073" type="mesh" rgba="0.615686 0.811765 0.929412 1" mesh="m6_threaded_eye" />
              <geom pos="0.0857 0.235487 0.0300047" quat="0.0464317 -0.700029 0.00884637 -0.712548" type="mesh" rgba="0.647059 0.647059 0.647059 1" mesh="12_7mm_ball_with_6mm_hole" />
              <geom pos="0.0857 0.160148 0.0799996" quat="0.707104 -0.00209173 0.707104 -0.00209173" type="mesh" rgba="0.615686 0.811765 0.929412 1" mesh="m6_threaded_eye" />
              <geom pos="0.0857 0.160148 0.0799996" quat="0.547705 -0.0287804 0.836125 -0.00925325" type="mesh" rgba="0.647059 0.647059 0.647059 1" mesh="12_7mm_ball_with_6mm_hole" />
              <geom pos="-7.43003e-08 0.395 0.0560001" quat="-0.499999 -0.499999 -0.500001 0.500001" type="mesh" rgba="0.615686 0.811765 0.929412 1" mesh="upper_ankle_shaft" />
              <geom pos="-4.99607e-08 0.404172 0.0560001" quat="-0.499999 -0.499999 -0.500001 0.500001" type="mesh" rgba="0.615686 0.811765 0.929412 1" mesh="ankle_ear" />
              <geom pos="0 0.423 0.0560001" quat="-0.499999 -0.499999 -0.500001 0.500001" type="mesh" rgba="0.615686 0.811765 0.929412 1" mesh="ankle_shaft" />
              <body name="ankle_assembly_3" pos="0.025 0.423 0.056" quat="9.38184e-07 -0.707105 9.38187e-07 0.707108">
                <inertial pos="0 0.0154553 0.025" quat="0.707107 0.707107 0 0" mass="0.0816337" diaginertia="2.14344e-05 1.68911e-05 1.24715e-05" />
                <joint name="right_ankle_pitch_joint" pos="0 0 0" axis="0 0 1" range="-0.785398 0.785398" actuatorfrcrange="-10 10" />
                <geom pos="0 0.028 0.025" quat="0.707105 -0.707108 0 0" type="mesh" rgba="0.615686 0.811765 0.929412 1" mesh="upper_ankle_shaft" />
                <geom pos="0 0.0188277 0.025" quat="0.707105 -0.707108 0 0" type="mesh" rgba="0.615686 0.811765 0.929412 1" mesh="ankle_ear" />
                <geom pos="0 0 0.025" quat="0.707105 -0.707108 0 0" type="mesh" rgba="0.615686 0.811765 0.929412 1" mesh="ankle_shaft" />
              </body>
            </body>
          </body>
        </body>
      </body>
    </body>
  <geom name="floor" type="plane" size="5 5 0.1" rgba="0.8 0.8 0.8 1" /></worldbody>
</mujoco>